[2023-04-25T22:39:08.552+0100] {processor.py:153} INFO - Started process (PID=402840) to work on /home/cavemhan/Documents/python/test_scripts/cyder-test/dags/base_dag.py
[2023-04-25T22:39:08.559+0100] {processor.py:743} INFO - Processing file /home/cavemhan/Documents/python/test_scripts/cyder-test/dags/base_dag.py for tasks to queue
[2023-04-25T22:39:08.562+0100] {logging_mixin.py:137} INFO - [2023-04-25T22:39:08.561+0100] {dagbag.py:532} INFO - Filling up the DagBag from /home/cavemhan/Documents/python/test_scripts/cyder-test/dags/base_dag.py
[2023-04-25T22:39:21.774+0100] {logging_mixin.py:137} INFO - [2023-04-25T22:39:21.764+0100] {dagbag.py:341} ERROR - Failed to import: /home/cavemhan/Documents/python/test_scripts/cyder-test/dags/base_dag.py
Traceback (most recent call last):
  File "/home/cavemhan/.local/share/virtualenvs/cyder-test-QPBcvLjc/lib/python3.10/site-packages/airflow/models/dagbag.py", line 337, in parse
    loader.exec_module(new_module)
  File "<frozen importlib._bootstrap_external>", line 883, in exec_module
  File "<frozen importlib._bootstrap>", line 241, in _call_with_frames_removed
  File "/home/cavemhan/Documents/python/test_scripts/cyder-test/dags/base_dag.py", line 7, in <module>
    from processing_dag import processing_dag
  File "/home/cavemhan/Documents/python/test_scripts/cyder-test/dags/processing_dag.py", line 29, in <module>
    download_spacy_models_task = PythonOperator(
  File "/home/cavemhan/.local/share/virtualenvs/cyder-test-QPBcvLjc/lib/python3.10/site-packages/airflow/models/baseoperator.py", line 394, in apply_defaults
    result = func(self, **kwargs, default_args=default_args)
  File "/home/cavemhan/.local/share/virtualenvs/cyder-test-QPBcvLjc/lib/python3.10/site-packages/airflow/operators/python.py", line 160, in __init__
    super().__init__(**kwargs)
  File "/home/cavemhan/.local/share/virtualenvs/cyder-test-QPBcvLjc/lib/python3.10/site-packages/airflow/models/baseoperator.py", line 394, in apply_defaults
    result = func(self, **kwargs, default_args=default_args)
  File "/home/cavemhan/.local/share/virtualenvs/cyder-test-QPBcvLjc/lib/python3.10/site-packages/airflow/models/baseoperator.py", line 742, in __init__
    raise AirflowException(
airflow.exceptions.AirflowException: Invalid arguments were passed to PythonOperator (task_id: download_spacy_modls). Invalid arguments were:
**kwargs: {'bash_command': 'echo "download_spacy_models_task is Running"'}
[2023-04-25T22:39:21.775+0100] {processor.py:755} WARNING - No viable dags retrieved from /home/cavemhan/Documents/python/test_scripts/cyder-test/dags/base_dag.py
[2023-04-25T22:39:21.963+0100] {processor.py:175} INFO - Processing /home/cavemhan/Documents/python/test_scripts/cyder-test/dags/base_dag.py took 13.422 seconds
[2023-04-25T22:40:25.084+0100] {processor.py:153} INFO - Started process (PID=404734) to work on /home/cavemhan/Documents/python/test_scripts/cyder-test/dags/base_dag.py
[2023-04-25T22:40:25.086+0100] {processor.py:743} INFO - Processing file /home/cavemhan/Documents/python/test_scripts/cyder-test/dags/base_dag.py for tasks to queue
[2023-04-25T22:40:25.087+0100] {logging_mixin.py:137} INFO - [2023-04-25T22:40:25.086+0100] {dagbag.py:532} INFO - Filling up the DagBag from /home/cavemhan/Documents/python/test_scripts/cyder-test/dags/base_dag.py
[2023-04-25T22:40:29.415+0100] {logging_mixin.py:137} INFO - [2023-04-25T22:40:29.406+0100] {dagbag.py:341} ERROR - Failed to import: /home/cavemhan/Documents/python/test_scripts/cyder-test/dags/base_dag.py
Traceback (most recent call last):
  File "/home/cavemhan/.local/share/virtualenvs/cyder-test-QPBcvLjc/lib/python3.10/site-packages/airflow/models/dagbag.py", line 337, in parse
    loader.exec_module(new_module)
  File "<frozen importlib._bootstrap_external>", line 883, in exec_module
  File "<frozen importlib._bootstrap>", line 241, in _call_with_frames_removed
  File "/home/cavemhan/Documents/python/test_scripts/cyder-test/dags/base_dag.py", line 7, in <module>
    from processing_dag import processing_dag
  File "/home/cavemhan/Documents/python/test_scripts/cyder-test/dags/processing_dag.py", line 29, in <module>
    download_spacy_models_task = PythonOperator(
  File "/home/cavemhan/.local/share/virtualenvs/cyder-test-QPBcvLjc/lib/python3.10/site-packages/airflow/models/baseoperator.py", line 394, in apply_defaults
    result = func(self, **kwargs, default_args=default_args)
  File "/home/cavemhan/.local/share/virtualenvs/cyder-test-QPBcvLjc/lib/python3.10/site-packages/airflow/operators/python.py", line 160, in __init__
    super().__init__(**kwargs)
  File "/home/cavemhan/.local/share/virtualenvs/cyder-test-QPBcvLjc/lib/python3.10/site-packages/airflow/models/baseoperator.py", line 394, in apply_defaults
    result = func(self, **kwargs, default_args=default_args)
  File "/home/cavemhan/.local/share/virtualenvs/cyder-test-QPBcvLjc/lib/python3.10/site-packages/airflow/models/baseoperator.py", line 742, in __init__
    raise AirflowException(
airflow.exceptions.AirflowException: Invalid arguments were passed to PythonOperator (task_id: download_spacy_modls). Invalid arguments were:
**kwargs: {'bash_command': 'echo "download_spacy_models_task is Running"'}
[2023-04-25T22:40:29.420+0100] {processor.py:755} WARNING - No viable dags retrieved from /home/cavemhan/Documents/python/test_scripts/cyder-test/dags/base_dag.py
[2023-04-25T22:40:29.495+0100] {processor.py:175} INFO - Processing /home/cavemhan/Documents/python/test_scripts/cyder-test/dags/base_dag.py took 4.414 seconds
[2023-04-25T22:41:02.604+0100] {processor.py:153} INFO - Started process (PID=405628) to work on /home/cavemhan/Documents/python/test_scripts/cyder-test/dags/base_dag.py
[2023-04-25T22:41:02.605+0100] {processor.py:743} INFO - Processing file /home/cavemhan/Documents/python/test_scripts/cyder-test/dags/base_dag.py for tasks to queue
[2023-04-25T22:41:02.606+0100] {logging_mixin.py:137} INFO - [2023-04-25T22:41:02.606+0100] {dagbag.py:532} INFO - Filling up the DagBag from /home/cavemhan/Documents/python/test_scripts/cyder-test/dags/base_dag.py
[2023-04-25T22:41:07.932+0100] {logging_mixin.py:137} INFO - [2023-04-25T22:41:07.919+0100] {dagbag.py:341} ERROR - Failed to import: /home/cavemhan/Documents/python/test_scripts/cyder-test/dags/base_dag.py
Traceback (most recent call last):
  File "/home/cavemhan/.local/share/virtualenvs/cyder-test-QPBcvLjc/lib/python3.10/site-packages/airflow/models/dagbag.py", line 337, in parse
    loader.exec_module(new_module)
  File "<frozen importlib._bootstrap_external>", line 883, in exec_module
  File "<frozen importlib._bootstrap>", line 241, in _call_with_frames_removed
  File "/home/cavemhan/Documents/python/test_scripts/cyder-test/dags/base_dag.py", line 7, in <module>
    from processing_dag import processing_dag
  File "/home/cavemhan/Documents/python/test_scripts/cyder-test/dags/processing_dag.py", line 29, in <module>
    download_spacy_models_task = PythonOperator(
  File "/home/cavemhan/.local/share/virtualenvs/cyder-test-QPBcvLjc/lib/python3.10/site-packages/airflow/models/baseoperator.py", line 394, in apply_defaults
    result = func(self, **kwargs, default_args=default_args)
  File "/home/cavemhan/.local/share/virtualenvs/cyder-test-QPBcvLjc/lib/python3.10/site-packages/airflow/operators/python.py", line 160, in __init__
    super().__init__(**kwargs)
  File "/home/cavemhan/.local/share/virtualenvs/cyder-test-QPBcvLjc/lib/python3.10/site-packages/airflow/models/baseoperator.py", line 394, in apply_defaults
    result = func(self, **kwargs, default_args=default_args)
  File "/home/cavemhan/.local/share/virtualenvs/cyder-test-QPBcvLjc/lib/python3.10/site-packages/airflow/models/baseoperator.py", line 742, in __init__
    raise AirflowException(
airflow.exceptions.AirflowException: Invalid arguments were passed to PythonOperator (task_id: download_spacy_modls). Invalid arguments were:
**kwargs: {'bash_command': 'echo "download_spacy_models_task is Running"'}
[2023-04-25T22:41:07.936+0100] {processor.py:755} WARNING - No viable dags retrieved from /home/cavemhan/Documents/python/test_scripts/cyder-test/dags/base_dag.py
[2023-04-25T22:41:07.978+0100] {processor.py:175} INFO - Processing /home/cavemhan/Documents/python/test_scripts/cyder-test/dags/base_dag.py took 5.378 seconds
[2023-04-25T22:42:11.646+0100] {processor.py:153} INFO - Started process (PID=407386) to work on /home/cavemhan/Documents/python/test_scripts/cyder-test/dags/base_dag.py
[2023-04-25T22:42:11.647+0100] {processor.py:743} INFO - Processing file /home/cavemhan/Documents/python/test_scripts/cyder-test/dags/base_dag.py for tasks to queue
[2023-04-25T22:42:11.648+0100] {logging_mixin.py:137} INFO - [2023-04-25T22:42:11.648+0100] {dagbag.py:532} INFO - Filling up the DagBag from /home/cavemhan/Documents/python/test_scripts/cyder-test/dags/base_dag.py
[2023-04-25T22:42:14.990+0100] {logging_mixin.py:137} INFO - [2023-04-25T22:42:14.984+0100] {dagbag.py:341} ERROR - Failed to import: /home/cavemhan/Documents/python/test_scripts/cyder-test/dags/base_dag.py
Traceback (most recent call last):
  File "/home/cavemhan/.local/share/virtualenvs/cyder-test-QPBcvLjc/lib/python3.10/site-packages/airflow/models/dagbag.py", line 337, in parse
    loader.exec_module(new_module)
  File "<frozen importlib._bootstrap_external>", line 883, in exec_module
  File "<frozen importlib._bootstrap>", line 241, in _call_with_frames_removed
  File "/home/cavemhan/Documents/python/test_scripts/cyder-test/dags/base_dag.py", line 7, in <module>
    from processing_dag import processing_dag
  File "/home/cavemhan/Documents/python/test_scripts/cyder-test/dags/processing_dag.py", line 29, in <module>
    download_spacy_models_task = PythonOperator(
  File "/home/cavemhan/.local/share/virtualenvs/cyder-test-QPBcvLjc/lib/python3.10/site-packages/airflow/models/baseoperator.py", line 394, in apply_defaults
    result = func(self, **kwargs, default_args=default_args)
  File "/home/cavemhan/.local/share/virtualenvs/cyder-test-QPBcvLjc/lib/python3.10/site-packages/airflow/operators/python.py", line 160, in __init__
    super().__init__(**kwargs)
  File "/home/cavemhan/.local/share/virtualenvs/cyder-test-QPBcvLjc/lib/python3.10/site-packages/airflow/models/baseoperator.py", line 394, in apply_defaults
    result = func(self, **kwargs, default_args=default_args)
  File "/home/cavemhan/.local/share/virtualenvs/cyder-test-QPBcvLjc/lib/python3.10/site-packages/airflow/models/baseoperator.py", line 742, in __init__
    raise AirflowException(
airflow.exceptions.AirflowException: Invalid arguments were passed to PythonOperator (task_id: load_or_download_models_task). Invalid arguments were:
**kwargs: {'bash_command': 'echo "download_spacy_models_task is Running"'}
[2023-04-25T22:42:14.991+0100] {processor.py:755} WARNING - No viable dags retrieved from /home/cavemhan/Documents/python/test_scripts/cyder-test/dags/base_dag.py
[2023-04-25T22:42:15.024+0100] {processor.py:175} INFO - Processing /home/cavemhan/Documents/python/test_scripts/cyder-test/dags/base_dag.py took 3.381 seconds
[2023-04-25T22:43:22.121+0100] {processor.py:153} INFO - Started process (PID=409200) to work on /home/cavemhan/Documents/python/test_scripts/cyder-test/dags/base_dag.py
[2023-04-25T22:43:22.123+0100] {processor.py:743} INFO - Processing file /home/cavemhan/Documents/python/test_scripts/cyder-test/dags/base_dag.py for tasks to queue
[2023-04-25T22:43:22.123+0100] {logging_mixin.py:137} INFO - [2023-04-25T22:43:22.123+0100] {dagbag.py:532} INFO - Filling up the DagBag from /home/cavemhan/Documents/python/test_scripts/cyder-test/dags/base_dag.py
[2023-04-25T22:43:23.720+0100] {logging_mixin.py:137} INFO - [2023-04-25T22:43:23.719+0100] {dagbag.py:341} ERROR - Failed to import: /home/cavemhan/Documents/python/test_scripts/cyder-test/dags/base_dag.py
Traceback (most recent call last):
  File "/home/cavemhan/.local/share/virtualenvs/cyder-test-QPBcvLjc/lib/python3.10/site-packages/airflow/models/dagbag.py", line 337, in parse
    loader.exec_module(new_module)
  File "<frozen importlib._bootstrap_external>", line 883, in exec_module
  File "<frozen importlib._bootstrap>", line 241, in _call_with_frames_removed
  File "/home/cavemhan/Documents/python/test_scripts/cyder-test/dags/base_dag.py", line 7, in <module>
    from processing_dag import processing_dag
  File "/home/cavemhan/Documents/python/test_scripts/cyder-test/dags/processing_dag.py", line 29, in <module>
    download_spacy_models_task = PythonOperator(
  File "/home/cavemhan/.local/share/virtualenvs/cyder-test-QPBcvLjc/lib/python3.10/site-packages/airflow/models/baseoperator.py", line 394, in apply_defaults
    result = func(self, **kwargs, default_args=default_args)
  File "/home/cavemhan/.local/share/virtualenvs/cyder-test-QPBcvLjc/lib/python3.10/site-packages/airflow/operators/python.py", line 160, in __init__
    super().__init__(**kwargs)
  File "/home/cavemhan/.local/share/virtualenvs/cyder-test-QPBcvLjc/lib/python3.10/site-packages/airflow/models/baseoperator.py", line 394, in apply_defaults
    result = func(self, **kwargs, default_args=default_args)
  File "/home/cavemhan/.local/share/virtualenvs/cyder-test-QPBcvLjc/lib/python3.10/site-packages/airflow/models/baseoperator.py", line 742, in __init__
    raise AirflowException(
airflow.exceptions.AirflowException: Invalid arguments were passed to PythonOperator (task_id: download_spacy_models_task). Invalid arguments were:
**kwargs: {'bash_command': 'echo "download_spacy_models_task is Running"'}
[2023-04-25T22:43:23.720+0100] {processor.py:755} WARNING - No viable dags retrieved from /home/cavemhan/Documents/python/test_scripts/cyder-test/dags/base_dag.py
[2023-04-25T22:43:23.740+0100] {processor.py:175} INFO - Processing /home/cavemhan/Documents/python/test_scripts/cyder-test/dags/base_dag.py took 1.622 seconds
[2023-04-25T22:44:19.816+0100] {processor.py:153} INFO - Started process (PID=410736) to work on /home/cavemhan/Documents/python/test_scripts/cyder-test/dags/base_dag.py
[2023-04-25T22:44:19.817+0100] {processor.py:743} INFO - Processing file /home/cavemhan/Documents/python/test_scripts/cyder-test/dags/base_dag.py for tasks to queue
[2023-04-25T22:44:19.818+0100] {logging_mixin.py:137} INFO - [2023-04-25T22:44:19.818+0100] {dagbag.py:532} INFO - Filling up the DagBag from /home/cavemhan/Documents/python/test_scripts/cyder-test/dags/base_dag.py
[2023-04-25T22:44:23.816+0100] {logging_mixin.py:137} INFO - [2023-04-25T22:44:23.801+0100] {dagbag.py:341} ERROR - Failed to import: /home/cavemhan/Documents/python/test_scripts/cyder-test/dags/base_dag.py
Traceback (most recent call last):
  File "/home/cavemhan/.local/share/virtualenvs/cyder-test-QPBcvLjc/lib/python3.10/site-packages/airflow/models/dagbag.py", line 337, in parse
    loader.exec_module(new_module)
  File "<frozen importlib._bootstrap_external>", line 883, in exec_module
  File "<frozen importlib._bootstrap>", line 241, in _call_with_frames_removed
  File "/home/cavemhan/Documents/python/test_scripts/cyder-test/dags/base_dag.py", line 7, in <module>
    from processing_dag import processing_dag
  File "/home/cavemhan/Documents/python/test_scripts/cyder-test/dags/processing_dag.py", line 29, in <module>
    download_spacy_models_task = PythonOperator(
  File "/home/cavemhan/.local/share/virtualenvs/cyder-test-QPBcvLjc/lib/python3.10/site-packages/airflow/models/baseoperator.py", line 394, in apply_defaults
    result = func(self, **kwargs, default_args=default_args)
  File "/home/cavemhan/.local/share/virtualenvs/cyder-test-QPBcvLjc/lib/python3.10/site-packages/airflow/operators/python.py", line 160, in __init__
    super().__init__(**kwargs)
  File "/home/cavemhan/.local/share/virtualenvs/cyder-test-QPBcvLjc/lib/python3.10/site-packages/airflow/models/baseoperator.py", line 394, in apply_defaults
    result = func(self, **kwargs, default_args=default_args)
  File "/home/cavemhan/.local/share/virtualenvs/cyder-test-QPBcvLjc/lib/python3.10/site-packages/airflow/models/baseoperator.py", line 742, in __init__
    raise AirflowException(
airflow.exceptions.AirflowException: Invalid arguments were passed to PythonOperator (task_id: download_spacy_models_task). Invalid arguments were:
**kwargs: {'bash_command': 'echo "download_spacy_models_task is Running"'}
[2023-04-25T22:44:23.818+0100] {processor.py:755} WARNING - No viable dags retrieved from /home/cavemhan/Documents/python/test_scripts/cyder-test/dags/base_dag.py
[2023-04-25T22:44:23.876+0100] {processor.py:175} INFO - Processing /home/cavemhan/Documents/python/test_scripts/cyder-test/dags/base_dag.py took 4.064 seconds
[2023-04-25T22:45:29.355+0100] {processor.py:153} INFO - Started process (PID=412364) to work on /home/cavemhan/Documents/python/test_scripts/cyder-test/dags/base_dag.py
[2023-04-25T22:45:29.356+0100] {processor.py:743} INFO - Processing file /home/cavemhan/Documents/python/test_scripts/cyder-test/dags/base_dag.py for tasks to queue
[2023-04-25T22:45:29.357+0100] {logging_mixin.py:137} INFO - [2023-04-25T22:45:29.357+0100] {dagbag.py:532} INFO - Filling up the DagBag from /home/cavemhan/Documents/python/test_scripts/cyder-test/dags/base_dag.py
[2023-04-25T22:45:32.525+0100] {logging_mixin.py:137} INFO - [2023-04-25T22:45:32.518+0100] {dagbag.py:341} ERROR - Failed to import: /home/cavemhan/Documents/python/test_scripts/cyder-test/dags/base_dag.py
Traceback (most recent call last):
  File "/home/cavemhan/.local/share/virtualenvs/cyder-test-QPBcvLjc/lib/python3.10/site-packages/airflow/models/dagbag.py", line 337, in parse
    loader.exec_module(new_module)
  File "<frozen importlib._bootstrap_external>", line 883, in exec_module
  File "<frozen importlib._bootstrap>", line 241, in _call_with_frames_removed
  File "/home/cavemhan/Documents/python/test_scripts/cyder-test/dags/base_dag.py", line 7, in <module>
    from processing_dag import processing_dag
  File "/home/cavemhan/Documents/python/test_scripts/cyder-test/dags/processing_dag.py", line 29, in <module>
    download_spacy_models_task = PythonOperator(
  File "/home/cavemhan/.local/share/virtualenvs/cyder-test-QPBcvLjc/lib/python3.10/site-packages/airflow/models/baseoperator.py", line 394, in apply_defaults
    result = func(self, **kwargs, default_args=default_args)
  File "/home/cavemhan/.local/share/virtualenvs/cyder-test-QPBcvLjc/lib/python3.10/site-packages/airflow/operators/python.py", line 160, in __init__
    super().__init__(**kwargs)
  File "/home/cavemhan/.local/share/virtualenvs/cyder-test-QPBcvLjc/lib/python3.10/site-packages/airflow/models/baseoperator.py", line 394, in apply_defaults
    result = func(self, **kwargs, default_args=default_args)
  File "/home/cavemhan/.local/share/virtualenvs/cyder-test-QPBcvLjc/lib/python3.10/site-packages/airflow/models/baseoperator.py", line 742, in __init__
    raise AirflowException(
airflow.exceptions.AirflowException: Invalid arguments were passed to PythonOperator (task_id: load_or_download_models). Invalid arguments were:
**kwargs: {'bash_command': 'echo "download_spacy_models_task is Running"'}
[2023-04-25T22:45:32.526+0100] {processor.py:755} WARNING - No viable dags retrieved from /home/cavemhan/Documents/python/test_scripts/cyder-test/dags/base_dag.py
[2023-04-25T22:45:32.561+0100] {processor.py:175} INFO - Processing /home/cavemhan/Documents/python/test_scripts/cyder-test/dags/base_dag.py took 3.209 seconds
[2023-04-25T22:46:54.121+0100] {processor.py:153} INFO - Started process (PID=414765) to work on /home/cavemhan/Documents/python/test_scripts/cyder-test/dags/base_dag.py
[2023-04-25T22:46:54.123+0100] {processor.py:743} INFO - Processing file /home/cavemhan/Documents/python/test_scripts/cyder-test/dags/base_dag.py for tasks to queue
[2023-04-25T22:46:54.125+0100] {logging_mixin.py:137} INFO - [2023-04-25T22:46:54.125+0100] {dagbag.py:532} INFO - Filling up the DagBag from /home/cavemhan/Documents/python/test_scripts/cyder-test/dags/base_dag.py
[2023-04-25T22:46:58.959+0100] {logging_mixin.py:137} INFO - [2023-04-25T22:46:58.951+0100] {dagbag.py:341} ERROR - Failed to import: /home/cavemhan/Documents/python/test_scripts/cyder-test/dags/base_dag.py
Traceback (most recent call last):
  File "/home/cavemhan/.local/share/virtualenvs/cyder-test-QPBcvLjc/lib/python3.10/site-packages/airflow/models/dagbag.py", line 337, in parse
    loader.exec_module(new_module)
  File "<frozen importlib._bootstrap_external>", line 883, in exec_module
  File "<frozen importlib._bootstrap>", line 241, in _call_with_frames_removed
  File "/home/cavemhan/Documents/python/test_scripts/cyder-test/dags/base_dag.py", line 7, in <module>
    from processing_dag import processing_dag
  File "/home/cavemhan/Documents/python/test_scripts/cyder-test/dags/processing_dag.py", line 29, in <module>
    download_spacy_models_task = PythonOperator(
  File "/home/cavemhan/.local/share/virtualenvs/cyder-test-QPBcvLjc/lib/python3.10/site-packages/airflow/models/baseoperator.py", line 394, in apply_defaults
    result = func(self, **kwargs, default_args=default_args)
  File "/home/cavemhan/.local/share/virtualenvs/cyder-test-QPBcvLjc/lib/python3.10/site-packages/airflow/operators/python.py", line 160, in __init__
    super().__init__(**kwargs)
  File "/home/cavemhan/.local/share/virtualenvs/cyder-test-QPBcvLjc/lib/python3.10/site-packages/airflow/models/baseoperator.py", line 394, in apply_defaults
    result = func(self, **kwargs, default_args=default_args)
  File "/home/cavemhan/.local/share/virtualenvs/cyder-test-QPBcvLjc/lib/python3.10/site-packages/airflow/models/baseoperator.py", line 742, in __init__
    raise AirflowException(
airflow.exceptions.AirflowException: Invalid arguments were passed to PythonOperator (task_id: load_or_download_models). Invalid arguments were:
**kwargs: {'bash_command': 'echo "download_spacy_models_task is Running"'}
[2023-04-25T22:46:58.962+0100] {processor.py:755} WARNING - No viable dags retrieved from /home/cavemhan/Documents/python/test_scripts/cyder-test/dags/base_dag.py
[2023-04-25T22:46:58.994+0100] {processor.py:175} INFO - Processing /home/cavemhan/Documents/python/test_scripts/cyder-test/dags/base_dag.py took 4.876 seconds
[2023-04-25T22:47:56.098+0100] {processor.py:153} INFO - Started process (PID=416266) to work on /home/cavemhan/Documents/python/test_scripts/cyder-test/dags/base_dag.py
[2023-04-25T22:47:56.100+0100] {processor.py:743} INFO - Processing file /home/cavemhan/Documents/python/test_scripts/cyder-test/dags/base_dag.py for tasks to queue
[2023-04-25T22:47:56.102+0100] {logging_mixin.py:137} INFO - [2023-04-25T22:47:56.101+0100] {dagbag.py:532} INFO - Filling up the DagBag from /home/cavemhan/Documents/python/test_scripts/cyder-test/dags/base_dag.py
[2023-04-25T22:48:27.386+0100] {processor.py:153} INFO - Started process (PID=417441) to work on /home/cavemhan/Documents/python/test_scripts/cyder-test/dags/base_dag.py
[2023-04-25T22:48:27.387+0100] {processor.py:743} INFO - Processing file /home/cavemhan/Documents/python/test_scripts/cyder-test/dags/base_dag.py for tasks to queue
[2023-04-25T22:48:27.388+0100] {logging_mixin.py:137} INFO - [2023-04-25T22:48:27.388+0100] {dagbag.py:532} INFO - Filling up the DagBag from /home/cavemhan/Documents/python/test_scripts/cyder-test/dags/base_dag.py
[2023-04-25T22:48:34.022+0100] {logging_mixin.py:137} INFO - output_dir: outputs/data/
[2023-04-25T22:48:36.984+0100] {logging_mixin.py:137} INFO - [2023-04-25T22:48:36.969+0100] {dagbag.py:341} ERROR - Failed to import: /home/cavemhan/Documents/python/test_scripts/cyder-test/dags/base_dag.py
Traceback (most recent call last):
  File "/home/cavemhan/.local/share/virtualenvs/cyder-test-QPBcvLjc/lib/python3.10/site-packages/airflow/models/dagbag.py", line 337, in parse
    loader.exec_module(new_module)
  File "<frozen importlib._bootstrap_external>", line 883, in exec_module
  File "<frozen importlib._bootstrap>", line 241, in _call_with_frames_removed
  File "/home/cavemhan/Documents/python/test_scripts/cyder-test/dags/base_dag.py", line 8, in <module>
    from ml_dags import ml_dag
  File "/home/cavemhan/Documents/python/test_scripts/cyder-test/dags/ml_dags.py", line 33, in <module>
    data_processor_for_ml = DataProcessorForML(X=feature_extractor.X, y=feature_extractor.y)
AttributeError: 'FeatureExtractor' object has no attribute 'X'
[2023-04-25T22:48:36.991+0100] {processor.py:755} WARNING - No viable dags retrieved from /home/cavemhan/Documents/python/test_scripts/cyder-test/dags/base_dag.py
[2023-04-25T22:48:37.154+0100] {processor.py:175} INFO - Processing /home/cavemhan/Documents/python/test_scripts/cyder-test/dags/base_dag.py took 9.771 seconds
[2023-04-25T22:50:12.933+0100] {processor.py:153} INFO - Started process (PID=419509) to work on /home/cavemhan/Documents/python/test_scripts/cyder-test/dags/base_dag.py
[2023-04-25T22:50:12.962+0100] {processor.py:743} INFO - Processing file /home/cavemhan/Documents/python/test_scripts/cyder-test/dags/base_dag.py for tasks to queue
[2023-04-25T22:50:12.963+0100] {logging_mixin.py:137} INFO - [2023-04-25T22:50:12.963+0100] {dagbag.py:532} INFO - Filling up the DagBag from /home/cavemhan/Documents/python/test_scripts/cyder-test/dags/base_dag.py
[2023-04-25T22:50:23.036+0100] {logging_mixin.py:137} INFO - output_dir: outputs/data/
[2023-04-25T22:50:24.605+0100] {logging_mixin.py:137} INFO - [2023-04-25T22:50:24.600+0100] {dagbag.py:341} ERROR - Failed to import: /home/cavemhan/Documents/python/test_scripts/cyder-test/dags/base_dag.py
Traceback (most recent call last):
  File "/home/cavemhan/.local/share/virtualenvs/cyder-test-QPBcvLjc/lib/python3.10/site-packages/airflow/models/dagbag.py", line 337, in parse
    loader.exec_module(new_module)
  File "<frozen importlib._bootstrap_external>", line 883, in exec_module
  File "<frozen importlib._bootstrap>", line 241, in _call_with_frames_removed
  File "/home/cavemhan/Documents/python/test_scripts/cyder-test/dags/base_dag.py", line 8, in <module>
    from ml_dags import ml_dag
  File "/home/cavemhan/Documents/python/test_scripts/cyder-test/dags/ml_dags.py", line 32, in <module>
    data_processor_for_ml = DataProcessorForML(X=feature_extractor.X, y=feature_extractor.y)
AttributeError: 'FeatureExtractor' object has no attribute 'X'
[2023-04-25T22:50:24.607+0100] {processor.py:755} WARNING - No viable dags retrieved from /home/cavemhan/Documents/python/test_scripts/cyder-test/dags/base_dag.py
[2023-04-25T22:50:24.641+0100] {processor.py:175} INFO - Processing /home/cavemhan/Documents/python/test_scripts/cyder-test/dags/base_dag.py took 11.744 seconds
[2023-04-25T22:51:26.116+0100] {processor.py:153} INFO - Started process (PID=421639) to work on /home/cavemhan/Documents/python/test_scripts/cyder-test/dags/base_dag.py
[2023-04-25T22:51:26.117+0100] {processor.py:743} INFO - Processing file /home/cavemhan/Documents/python/test_scripts/cyder-test/dags/base_dag.py for tasks to queue
[2023-04-25T22:51:26.118+0100] {logging_mixin.py:137} INFO - [2023-04-25T22:51:26.118+0100] {dagbag.py:532} INFO - Filling up the DagBag from /home/cavemhan/Documents/python/test_scripts/cyder-test/dags/base_dag.py
[2023-04-25T22:51:29.025+0100] {logging_mixin.py:137} INFO - output_dir: outputs/data/
[2023-04-25T22:51:29.919+0100] {logging_mixin.py:137} INFO - [2023-04-25T22:51:29.917+0100] {dagbag.py:341} ERROR - Failed to import: /home/cavemhan/Documents/python/test_scripts/cyder-test/dags/base_dag.py
Traceback (most recent call last):
  File "/home/cavemhan/.local/share/virtualenvs/cyder-test-QPBcvLjc/lib/python3.10/site-packages/airflow/models/dagbag.py", line 337, in parse
    loader.exec_module(new_module)
  File "<frozen importlib._bootstrap_external>", line 883, in exec_module
  File "<frozen importlib._bootstrap>", line 241, in _call_with_frames_removed
  File "/home/cavemhan/Documents/python/test_scripts/cyder-test/dags/base_dag.py", line 8, in <module>
    from ml_dags import ml_dag
  File "/home/cavemhan/Documents/python/test_scripts/cyder-test/dags/ml_dags.py", line 32, in <module>
    data_processor_for_ml = DataProcessorForML(X=feature_extractor.X, y=feature_extractor.y)
AttributeError: 'FeatureExtractor' object has no attribute 'X'
[2023-04-25T22:51:29.920+0100] {processor.py:755} WARNING - No viable dags retrieved from /home/cavemhan/Documents/python/test_scripts/cyder-test/dags/base_dag.py
[2023-04-25T22:51:29.961+0100] {processor.py:175} INFO - Processing /home/cavemhan/Documents/python/test_scripts/cyder-test/dags/base_dag.py took 3.848 seconds
[2023-04-25T22:53:42.448+0100] {processor.py:153} INFO - Started process (PID=4021) to work on /home/cavemhan/Documents/python/test_scripts/cyder-test/dags/base_dag.py
[2023-04-25T22:53:42.452+0100] {processor.py:743} INFO - Processing file /home/cavemhan/Documents/python/test_scripts/cyder-test/dags/base_dag.py for tasks to queue
[2023-04-25T22:53:42.454+0100] {logging_mixin.py:137} INFO - [2023-04-25T22:53:42.453+0100] {dagbag.py:532} INFO - Filling up the DagBag from /home/cavemhan/Documents/python/test_scripts/cyder-test/dags/base_dag.py
[2023-04-25T22:53:44.151+0100] {logging_mixin.py:137} INFO - output_dir: outputs/data/
[2023-04-25T22:53:44.944+0100] {logging_mixin.py:137} INFO - [2023-04-25T22:53:44.943+0100] {dagbag.py:341} ERROR - Failed to import: /home/cavemhan/Documents/python/test_scripts/cyder-test/dags/base_dag.py
Traceback (most recent call last):
  File "/home/cavemhan/.local/share/virtualenvs/cyder-test-QPBcvLjc/lib/python3.10/site-packages/airflow/models/dagbag.py", line 337, in parse
    loader.exec_module(new_module)
  File "<frozen importlib._bootstrap_external>", line 883, in exec_module
  File "<frozen importlib._bootstrap>", line 241, in _call_with_frames_removed
  File "/home/cavemhan/Documents/python/test_scripts/cyder-test/dags/base_dag.py", line 8, in <module>
    from ml_dags import ml_dag
  File "/home/cavemhan/Documents/python/test_scripts/cyder-test/dags/ml_dags.py", line 32, in <module>
    data_processor_for_ml = DataProcessorForML(X=feature_extractor.X, y=feature_extractor.y)
AttributeError: 'FeatureExtractor' object has no attribute 'X'
[2023-04-25T22:53:44.944+0100] {processor.py:755} WARNING - No viable dags retrieved from /home/cavemhan/Documents/python/test_scripts/cyder-test/dags/base_dag.py
[2023-04-25T22:53:44.962+0100] {processor.py:175} INFO - Processing /home/cavemhan/Documents/python/test_scripts/cyder-test/dags/base_dag.py took 2.518 seconds
[2023-04-25T22:54:40.065+0100] {processor.py:153} INFO - Started process (PID=4668) to work on /home/cavemhan/Documents/python/test_scripts/cyder-test/dags/base_dag.py
[2023-04-25T22:54:40.068+0100] {processor.py:743} INFO - Processing file /home/cavemhan/Documents/python/test_scripts/cyder-test/dags/base_dag.py for tasks to queue
[2023-04-25T22:54:40.069+0100] {logging_mixin.py:137} INFO - [2023-04-25T22:54:40.069+0100] {dagbag.py:532} INFO - Filling up the DagBag from /home/cavemhan/Documents/python/test_scripts/cyder-test/dags/base_dag.py
[2023-04-25T22:54:42.070+0100] {logging_mixin.py:137} INFO - output_dir: outputs/data/
[2023-04-25T22:54:43.124+0100] {logging_mixin.py:137} INFO - [2023-04-25T22:54:43.123+0100] {dagbag.py:341} ERROR - Failed to import: /home/cavemhan/Documents/python/test_scripts/cyder-test/dags/base_dag.py
Traceback (most recent call last):
  File "/home/cavemhan/.local/share/virtualenvs/cyder-test-QPBcvLjc/lib/python3.10/site-packages/airflow/models/dagbag.py", line 337, in parse
    loader.exec_module(new_module)
  File "<frozen importlib._bootstrap_external>", line 883, in exec_module
  File "<frozen importlib._bootstrap>", line 241, in _call_with_frames_removed
  File "/home/cavemhan/Documents/python/test_scripts/cyder-test/dags/base_dag.py", line 8, in <module>
    from ml_dags import ml_dag
  File "/home/cavemhan/Documents/python/test_scripts/cyder-test/dags/ml_dags.py", line 32, in <module>
    data_processor_for_ml = DataProcessorForML(X=feature_extractor.X, y=feature_extractor.y)
AttributeError: 'FeatureExtractor' object has no attribute 'X'
[2023-04-25T22:54:43.125+0100] {processor.py:755} WARNING - No viable dags retrieved from /home/cavemhan/Documents/python/test_scripts/cyder-test/dags/base_dag.py
[2023-04-25T22:54:43.144+0100] {processor.py:175} INFO - Processing /home/cavemhan/Documents/python/test_scripts/cyder-test/dags/base_dag.py took 3.083 seconds
[2023-04-25T22:55:41.359+0100] {processor.py:153} INFO - Started process (PID=5027) to work on /home/cavemhan/Documents/python/test_scripts/cyder-test/dags/base_dag.py
[2023-04-25T22:55:41.363+0100] {processor.py:743} INFO - Processing file /home/cavemhan/Documents/python/test_scripts/cyder-test/dags/base_dag.py for tasks to queue
[2023-04-25T22:55:41.363+0100] {logging_mixin.py:137} INFO - [2023-04-25T22:55:41.363+0100] {dagbag.py:532} INFO - Filling up the DagBag from /home/cavemhan/Documents/python/test_scripts/cyder-test/dags/base_dag.py
[2023-04-25T22:55:43.144+0100] {logging_mixin.py:137} INFO - output_dir: outputs/data/
[2023-04-25T22:55:44.141+0100] {logging_mixin.py:137} INFO - [2023-04-25T22:55:44.140+0100] {dagbag.py:341} ERROR - Failed to import: /home/cavemhan/Documents/python/test_scripts/cyder-test/dags/base_dag.py
Traceback (most recent call last):
  File "/home/cavemhan/.local/share/virtualenvs/cyder-test-QPBcvLjc/lib/python3.10/site-packages/airflow/models/dagbag.py", line 337, in parse
    loader.exec_module(new_module)
  File "<frozen importlib._bootstrap_external>", line 883, in exec_module
  File "<frozen importlib._bootstrap>", line 241, in _call_with_frames_removed
  File "/home/cavemhan/Documents/python/test_scripts/cyder-test/dags/base_dag.py", line 8, in <module>
    from ml_dags import ml_dag
  File "/home/cavemhan/Documents/python/test_scripts/cyder-test/dags/ml_dags.py", line 32, in <module>
    data_processor_for_ml = DataProcessorForML(X=feature_extractor.X, y=feature_extractor.y)
AttributeError: 'FeatureExtractor' object has no attribute 'X'
[2023-04-25T22:55:44.141+0100] {processor.py:755} WARNING - No viable dags retrieved from /home/cavemhan/Documents/python/test_scripts/cyder-test/dags/base_dag.py
[2023-04-25T22:55:44.164+0100] {processor.py:175} INFO - Processing /home/cavemhan/Documents/python/test_scripts/cyder-test/dags/base_dag.py took 2.809 seconds
[2023-04-25T22:56:43.074+0100] {processor.py:153} INFO - Started process (PID=5389) to work on /home/cavemhan/Documents/python/test_scripts/cyder-test/dags/base_dag.py
[2023-04-25T22:56:43.074+0100] {processor.py:743} INFO - Processing file /home/cavemhan/Documents/python/test_scripts/cyder-test/dags/base_dag.py for tasks to queue
[2023-04-25T22:56:43.075+0100] {logging_mixin.py:137} INFO - [2023-04-25T22:56:43.075+0100] {dagbag.py:532} INFO - Filling up the DagBag from /home/cavemhan/Documents/python/test_scripts/cyder-test/dags/base_dag.py
[2023-04-25T22:56:44.817+0100] {logging_mixin.py:137} INFO - output_dir: outputs/data/
[2023-04-25T22:56:45.562+0100] {logging_mixin.py:137} INFO - [2023-04-25T22:56:45.561+0100] {dagbag.py:341} ERROR - Failed to import: /home/cavemhan/Documents/python/test_scripts/cyder-test/dags/base_dag.py
Traceback (most recent call last):
  File "/home/cavemhan/.local/share/virtualenvs/cyder-test-QPBcvLjc/lib/python3.10/site-packages/airflow/models/dagbag.py", line 337, in parse
    loader.exec_module(new_module)
  File "<frozen importlib._bootstrap_external>", line 883, in exec_module
  File "<frozen importlib._bootstrap>", line 241, in _call_with_frames_removed
  File "/home/cavemhan/Documents/python/test_scripts/cyder-test/dags/base_dag.py", line 8, in <module>
    from ml_dags import ml_dag
  File "/home/cavemhan/Documents/python/test_scripts/cyder-test/dags/ml_dags.py", line 32, in <module>
    data_processor_for_ml = DataProcessorForML(X=feature_extractor.X, y=feature_extractor.y)
AttributeError: 'FeatureExtractor' object has no attribute 'X'
[2023-04-25T22:56:45.563+0100] {processor.py:755} WARNING - No viable dags retrieved from /home/cavemhan/Documents/python/test_scripts/cyder-test/dags/base_dag.py
[2023-04-25T22:56:45.579+0100] {processor.py:175} INFO - Processing /home/cavemhan/Documents/python/test_scripts/cyder-test/dags/base_dag.py took 2.508 seconds
[2023-04-25T22:57:44.124+0100] {processor.py:153} INFO - Started process (PID=5772) to work on /home/cavemhan/Documents/python/test_scripts/cyder-test/dags/base_dag.py
[2023-04-25T22:57:44.128+0100] {processor.py:743} INFO - Processing file /home/cavemhan/Documents/python/test_scripts/cyder-test/dags/base_dag.py for tasks to queue
[2023-04-25T22:57:44.128+0100] {logging_mixin.py:137} INFO - [2023-04-25T22:57:44.128+0100] {dagbag.py:532} INFO - Filling up the DagBag from /home/cavemhan/Documents/python/test_scripts/cyder-test/dags/base_dag.py
[2023-04-25T22:57:45.847+0100] {logging_mixin.py:137} INFO - output_dir: outputs/data/
[2023-04-25T22:57:46.652+0100] {logging_mixin.py:137} INFO - [2023-04-25T22:57:46.651+0100] {dagbag.py:341} ERROR - Failed to import: /home/cavemhan/Documents/python/test_scripts/cyder-test/dags/base_dag.py
Traceback (most recent call last):
  File "/home/cavemhan/.local/share/virtualenvs/cyder-test-QPBcvLjc/lib/python3.10/site-packages/airflow/models/dagbag.py", line 337, in parse
    loader.exec_module(new_module)
  File "<frozen importlib._bootstrap_external>", line 883, in exec_module
  File "<frozen importlib._bootstrap>", line 241, in _call_with_frames_removed
  File "/home/cavemhan/Documents/python/test_scripts/cyder-test/dags/base_dag.py", line 8, in <module>
    from ml_dags import ml_dag
  File "/home/cavemhan/Documents/python/test_scripts/cyder-test/dags/ml_dags.py", line 32, in <module>
    data_processor_for_ml = DataProcessorForML(data=feature_extractor.df)
AttributeError: 'FeatureExtractor' object has no attribute 'df'
[2023-04-25T22:57:46.652+0100] {processor.py:755} WARNING - No viable dags retrieved from /home/cavemhan/Documents/python/test_scripts/cyder-test/dags/base_dag.py
[2023-04-25T22:57:46.675+0100] {processor.py:175} INFO - Processing /home/cavemhan/Documents/python/test_scripts/cyder-test/dags/base_dag.py took 2.554 seconds
[2023-04-25T22:58:49.031+0100] {processor.py:153} INFO - Started process (PID=6187) to work on /home/cavemhan/Documents/python/test_scripts/cyder-test/dags/base_dag.py
[2023-04-25T22:58:49.034+0100] {processor.py:743} INFO - Processing file /home/cavemhan/Documents/python/test_scripts/cyder-test/dags/base_dag.py for tasks to queue
[2023-04-25T22:58:49.035+0100] {logging_mixin.py:137} INFO - [2023-04-25T22:58:49.035+0100] {dagbag.py:532} INFO - Filling up the DagBag from /home/cavemhan/Documents/python/test_scripts/cyder-test/dags/base_dag.py
[2023-04-25T22:58:50.634+0100] {logging_mixin.py:137} INFO - output_dir: outputs/data/
[2023-04-25T22:58:51.395+0100] {logging_mixin.py:137} INFO - [2023-04-25T22:58:51.394+0100] {dagbag.py:341} ERROR - Failed to import: /home/cavemhan/Documents/python/test_scripts/cyder-test/dags/base_dag.py
Traceback (most recent call last):
  File "/home/cavemhan/.local/share/virtualenvs/cyder-test-QPBcvLjc/lib/python3.10/site-packages/airflow/models/dagbag.py", line 337, in parse
    loader.exec_module(new_module)
  File "<frozen importlib._bootstrap_external>", line 883, in exec_module
  File "<frozen importlib._bootstrap>", line 241, in _call_with_frames_removed
  File "/home/cavemhan/Documents/python/test_scripts/cyder-test/dags/base_dag.py", line 8, in <module>
    from ml_dags import ml_dag
  File "/home/cavemhan/Documents/python/test_scripts/cyder-test/dags/ml_dags.py", line 32, in <module>
    data_processor_for_ml = DataProcessorForML(data=feature_extractor.df)
AttributeError: 'FeatureExtractor' object has no attribute 'df'
[2023-04-25T22:58:51.395+0100] {processor.py:755} WARNING - No viable dags retrieved from /home/cavemhan/Documents/python/test_scripts/cyder-test/dags/base_dag.py
[2023-04-25T22:58:51.411+0100] {processor.py:175} INFO - Processing /home/cavemhan/Documents/python/test_scripts/cyder-test/dags/base_dag.py took 2.384 seconds
[2023-04-25T22:59:29.188+0100] {processor.py:153} INFO - Started process (PID=6688) to work on /home/cavemhan/Documents/python/test_scripts/cyder-test/dags/base_dag.py
[2023-04-25T22:59:29.192+0100] {processor.py:743} INFO - Processing file /home/cavemhan/Documents/python/test_scripts/cyder-test/dags/base_dag.py for tasks to queue
[2023-04-25T22:59:29.193+0100] {logging_mixin.py:137} INFO - [2023-04-25T22:59:29.193+0100] {dagbag.py:532} INFO - Filling up the DagBag from /home/cavemhan/Documents/python/test_scripts/cyder-test/dags/base_dag.py
[2023-04-25T22:59:30.758+0100] {logging_mixin.py:137} INFO - output_dir: outputs/data/
[2023-04-25T22:59:31.479+0100] {logging_mixin.py:137} INFO - [2023-04-25T22:59:31.479+0100] {dagbag.py:341} ERROR - Failed to import: /home/cavemhan/Documents/python/test_scripts/cyder-test/dags/base_dag.py
Traceback (most recent call last):
  File "/home/cavemhan/.local/share/virtualenvs/cyder-test-QPBcvLjc/lib/python3.10/site-packages/airflow/models/dagbag.py", line 337, in parse
    loader.exec_module(new_module)
  File "<frozen importlib._bootstrap_external>", line 883, in exec_module
  File "<frozen importlib._bootstrap>", line 241, in _call_with_frames_removed
  File "/home/cavemhan/Documents/python/test_scripts/cyder-test/dags/base_dag.py", line 8, in <module>
    from ml_dags import ml_dag
  File "/home/cavemhan/Documents/python/test_scripts/cyder-test/dags/ml_dags.py", line 32, in <module>
    data_processor_for_ml = DataProcessorForML(data=feature_extractor.df)
AttributeError: 'FeatureExtractor' object has no attribute 'df'
[2023-04-25T22:59:31.480+0100] {processor.py:755} WARNING - No viable dags retrieved from /home/cavemhan/Documents/python/test_scripts/cyder-test/dags/base_dag.py
[2023-04-25T22:59:31.501+0100] {processor.py:175} INFO - Processing /home/cavemhan/Documents/python/test_scripts/cyder-test/dags/base_dag.py took 2.316 seconds
[2023-04-25T23:00:25.811+0100] {processor.py:153} INFO - Started process (PID=7046) to work on /home/cavemhan/Documents/python/test_scripts/cyder-test/dags/base_dag.py
[2023-04-25T23:00:25.812+0100] {processor.py:743} INFO - Processing file /home/cavemhan/Documents/python/test_scripts/cyder-test/dags/base_dag.py for tasks to queue
[2023-04-25T23:00:25.812+0100] {logging_mixin.py:137} INFO - [2023-04-25T23:00:25.812+0100] {dagbag.py:532} INFO - Filling up the DagBag from /home/cavemhan/Documents/python/test_scripts/cyder-test/dags/base_dag.py
[2023-04-25T23:00:27.729+0100] {logging_mixin.py:137} INFO - output_dir: outputs/data/
[2023-04-25T23:00:28.520+0100] {logging_mixin.py:137} INFO - [2023-04-25T23:00:28.519+0100] {dagbag.py:341} ERROR - Failed to import: /home/cavemhan/Documents/python/test_scripts/cyder-test/dags/base_dag.py
Traceback (most recent call last):
  File "/home/cavemhan/.local/share/virtualenvs/cyder-test-QPBcvLjc/lib/python3.10/site-packages/airflow/models/dagbag.py", line 337, in parse
    loader.exec_module(new_module)
  File "<frozen importlib._bootstrap_external>", line 883, in exec_module
  File "<frozen importlib._bootstrap>", line 241, in _call_with_frames_removed
  File "/home/cavemhan/Documents/python/test_scripts/cyder-test/dags/base_dag.py", line 8, in <module>
    from ml_dags import ml_dag
  File "/home/cavemhan/Documents/python/test_scripts/cyder-test/dags/ml_dags.py", line 32, in <module>
    data_processor_for_ml = DataProcessorForML(data=feature_extractor.df)
AttributeError: 'FeatureExtractor' object has no attribute 'df'
[2023-04-25T23:00:28.521+0100] {processor.py:755} WARNING - No viable dags retrieved from /home/cavemhan/Documents/python/test_scripts/cyder-test/dags/base_dag.py
[2023-04-25T23:00:28.541+0100] {processor.py:175} INFO - Processing /home/cavemhan/Documents/python/test_scripts/cyder-test/dags/base_dag.py took 2.733 seconds
[2023-04-25T23:01:23.128+0100] {processor.py:153} INFO - Started process (PID=7360) to work on /home/cavemhan/Documents/python/test_scripts/cyder-test/dags/base_dag.py
[2023-04-25T23:01:23.132+0100] {processor.py:743} INFO - Processing file /home/cavemhan/Documents/python/test_scripts/cyder-test/dags/base_dag.py for tasks to queue
[2023-04-25T23:01:23.133+0100] {logging_mixin.py:137} INFO - [2023-04-25T23:01:23.133+0100] {dagbag.py:532} INFO - Filling up the DagBag from /home/cavemhan/Documents/python/test_scripts/cyder-test/dags/base_dag.py
[2023-04-25T23:01:24.769+0100] {logging_mixin.py:137} INFO - output_dir: outputs/data/
[2023-04-25T23:01:25.490+0100] {logging_mixin.py:137} INFO - [2023-04-25T23:01:25.489+0100] {dagbag.py:341} ERROR - Failed to import: /home/cavemhan/Documents/python/test_scripts/cyder-test/dags/base_dag.py
Traceback (most recent call last):
  File "/home/cavemhan/.local/share/virtualenvs/cyder-test-QPBcvLjc/lib/python3.10/site-packages/airflow/models/dagbag.py", line 337, in parse
    loader.exec_module(new_module)
  File "<frozen importlib._bootstrap_external>", line 883, in exec_module
  File "<frozen importlib._bootstrap>", line 241, in _call_with_frames_removed
  File "/home/cavemhan/Documents/python/test_scripts/cyder-test/dags/base_dag.py", line 8, in <module>
    from ml_dags import ml_dag
  File "/home/cavemhan/Documents/python/test_scripts/cyder-test/dags/ml_dags.py", line 32, in <module>
    data_processor_for_ml = DataProcessorForML(data=feature_extractor.df)
AttributeError: 'FeatureExtractor' object has no attribute 'df'
[2023-04-25T23:01:25.490+0100] {processor.py:755} WARNING - No viable dags retrieved from /home/cavemhan/Documents/python/test_scripts/cyder-test/dags/base_dag.py
[2023-04-25T23:01:25.514+0100] {processor.py:175} INFO - Processing /home/cavemhan/Documents/python/test_scripts/cyder-test/dags/base_dag.py took 2.390 seconds
[2023-04-25T23:02:18.491+0100] {processor.py:153} INFO - Started process (PID=7694) to work on /home/cavemhan/Documents/python/test_scripts/cyder-test/dags/base_dag.py
[2023-04-25T23:02:18.494+0100] {processor.py:743} INFO - Processing file /home/cavemhan/Documents/python/test_scripts/cyder-test/dags/base_dag.py for tasks to queue
[2023-04-25T23:02:18.495+0100] {logging_mixin.py:137} INFO - [2023-04-25T23:02:18.495+0100] {dagbag.py:532} INFO - Filling up the DagBag from /home/cavemhan/Documents/python/test_scripts/cyder-test/dags/base_dag.py
[2023-04-25T23:02:20.147+0100] {logging_mixin.py:137} INFO - output_dir: outputs/data/
[2023-04-25T23:02:20.880+0100] {logging_mixin.py:137} INFO - [2023-04-25T23:02:20.880+0100] {dagbag.py:341} ERROR - Failed to import: /home/cavemhan/Documents/python/test_scripts/cyder-test/dags/base_dag.py
Traceback (most recent call last):
  File "/home/cavemhan/.local/share/virtualenvs/cyder-test-QPBcvLjc/lib/python3.10/site-packages/airflow/models/dagbag.py", line 337, in parse
    loader.exec_module(new_module)
  File "<frozen importlib._bootstrap_external>", line 883, in exec_module
  File "<frozen importlib._bootstrap>", line 241, in _call_with_frames_removed
  File "/home/cavemhan/Documents/python/test_scripts/cyder-test/dags/base_dag.py", line 8, in <module>
    from ml_dags import ml_dag
  File "/home/cavemhan/Documents/python/test_scripts/cyder-test/dags/ml_dags.py", line 32, in <module>
    data_processor_for_ml = DataProcessorForML(data=feature_extractor.df)
AttributeError: 'FeatureExtractor' object has no attribute 'df'
[2023-04-25T23:02:20.881+0100] {processor.py:755} WARNING - No viable dags retrieved from /home/cavemhan/Documents/python/test_scripts/cyder-test/dags/base_dag.py
[2023-04-25T23:02:20.900+0100] {processor.py:175} INFO - Processing /home/cavemhan/Documents/python/test_scripts/cyder-test/dags/base_dag.py took 2.413 seconds
[2023-04-25T23:03:15.170+0100] {processor.py:153} INFO - Started process (PID=8015) to work on /home/cavemhan/Documents/python/test_scripts/cyder-test/dags/base_dag.py
[2023-04-25T23:03:15.174+0100] {processor.py:743} INFO - Processing file /home/cavemhan/Documents/python/test_scripts/cyder-test/dags/base_dag.py for tasks to queue
[2023-04-25T23:03:15.175+0100] {logging_mixin.py:137} INFO - [2023-04-25T23:03:15.174+0100] {dagbag.py:532} INFO - Filling up the DagBag from /home/cavemhan/Documents/python/test_scripts/cyder-test/dags/base_dag.py
[2023-04-25T23:03:16.745+0100] {logging_mixin.py:137} INFO - output_dir: outputs/data/
[2023-04-25T23:03:17.482+0100] {logging_mixin.py:137} INFO - [2023-04-25T23:03:17.481+0100] {dagbag.py:341} ERROR - Failed to import: /home/cavemhan/Documents/python/test_scripts/cyder-test/dags/base_dag.py
Traceback (most recent call last):
  File "/home/cavemhan/.local/share/virtualenvs/cyder-test-QPBcvLjc/lib/python3.10/site-packages/airflow/models/dagbag.py", line 337, in parse
    loader.exec_module(new_module)
  File "<frozen importlib._bootstrap_external>", line 883, in exec_module
  File "<frozen importlib._bootstrap>", line 241, in _call_with_frames_removed
  File "/home/cavemhan/Documents/python/test_scripts/cyder-test/dags/base_dag.py", line 8, in <module>
    from ml_dags import ml_dag
  File "/home/cavemhan/Documents/python/test_scripts/cyder-test/dags/ml_dags.py", line 32, in <module>
    data_processor_for_ml = DataProcessorForML(data=feature_extractor.df)
AttributeError: 'FeatureExtractor' object has no attribute 'df'
[2023-04-25T23:03:17.482+0100] {processor.py:755} WARNING - No viable dags retrieved from /home/cavemhan/Documents/python/test_scripts/cyder-test/dags/base_dag.py
[2023-04-25T23:03:17.504+0100] {processor.py:175} INFO - Processing /home/cavemhan/Documents/python/test_scripts/cyder-test/dags/base_dag.py took 2.337 seconds
[2023-04-25T23:04:14.391+0100] {processor.py:153} INFO - Started process (PID=8331) to work on /home/cavemhan/Documents/python/test_scripts/cyder-test/dags/base_dag.py
[2023-04-25T23:04:14.394+0100] {processor.py:743} INFO - Processing file /home/cavemhan/Documents/python/test_scripts/cyder-test/dags/base_dag.py for tasks to queue
[2023-04-25T23:04:14.395+0100] {logging_mixin.py:137} INFO - [2023-04-25T23:04:14.395+0100] {dagbag.py:532} INFO - Filling up the DagBag from /home/cavemhan/Documents/python/test_scripts/cyder-test/dags/base_dag.py
[2023-04-25T23:04:16.031+0100] {logging_mixin.py:137} INFO - output_dir: outputs/data/
[2023-04-25T23:04:16.822+0100] {logging_mixin.py:137} INFO - [2023-04-25T23:04:16.821+0100] {dagbag.py:341} ERROR - Failed to import: /home/cavemhan/Documents/python/test_scripts/cyder-test/dags/base_dag.py
Traceback (most recent call last):
  File "/home/cavemhan/.local/share/virtualenvs/cyder-test-QPBcvLjc/lib/python3.10/site-packages/airflow/models/dagbag.py", line 337, in parse
    loader.exec_module(new_module)
  File "<frozen importlib._bootstrap_external>", line 883, in exec_module
  File "<frozen importlib._bootstrap>", line 241, in _call_with_frames_removed
  File "/home/cavemhan/Documents/python/test_scripts/cyder-test/dags/base_dag.py", line 8, in <module>
    from ml_dags import ml_dag
  File "/home/cavemhan/Documents/python/test_scripts/cyder-test/dags/ml_dags.py", line 32, in <module>
    data_processor_for_ml = DataProcessorForML(data=feature_extractor.df)
AttributeError: 'FeatureExtractor' object has no attribute 'df'
[2023-04-25T23:04:16.822+0100] {processor.py:755} WARNING - No viable dags retrieved from /home/cavemhan/Documents/python/test_scripts/cyder-test/dags/base_dag.py
[2023-04-25T23:04:16.843+0100] {processor.py:175} INFO - Processing /home/cavemhan/Documents/python/test_scripts/cyder-test/dags/base_dag.py took 2.456 seconds
[2023-04-25T23:05:15.128+0100] {processor.py:153} INFO - Started process (PID=8740) to work on /home/cavemhan/Documents/python/test_scripts/cyder-test/dags/base_dag.py
[2023-04-25T23:05:15.132+0100] {processor.py:743} INFO - Processing file /home/cavemhan/Documents/python/test_scripts/cyder-test/dags/base_dag.py for tasks to queue
[2023-04-25T23:05:15.133+0100] {logging_mixin.py:137} INFO - [2023-04-25T23:05:15.133+0100] {dagbag.py:532} INFO - Filling up the DagBag from /home/cavemhan/Documents/python/test_scripts/cyder-test/dags/base_dag.py
[2023-04-25T23:05:16.766+0100] {logging_mixin.py:137} INFO - output_dir: outputs/data/
[2023-04-25T23:05:17.492+0100] {logging_mixin.py:137} INFO - [2023-04-25T23:05:17.492+0100] {dagbag.py:341} ERROR - Failed to import: /home/cavemhan/Documents/python/test_scripts/cyder-test/dags/base_dag.py
Traceback (most recent call last):
  File "/home/cavemhan/.local/share/virtualenvs/cyder-test-QPBcvLjc/lib/python3.10/site-packages/airflow/models/dagbag.py", line 337, in parse
    loader.exec_module(new_module)
  File "<frozen importlib._bootstrap_external>", line 883, in exec_module
  File "<frozen importlib._bootstrap>", line 241, in _call_with_frames_removed
  File "/home/cavemhan/Documents/python/test_scripts/cyder-test/dags/base_dag.py", line 8, in <module>
    from ml_dags import ml_dag
  File "/home/cavemhan/Documents/python/test_scripts/cyder-test/dags/ml_dags.py", line 32, in <module>
    data_processor_for_ml = DataProcessorForML(data=feature_extractor.df)
AttributeError: 'FeatureExtractor' object has no attribute 'df'
[2023-04-25T23:05:17.493+0100] {processor.py:755} WARNING - No viable dags retrieved from /home/cavemhan/Documents/python/test_scripts/cyder-test/dags/base_dag.py
[2023-04-25T23:05:17.513+0100] {processor.py:175} INFO - Processing /home/cavemhan/Documents/python/test_scripts/cyder-test/dags/base_dag.py took 2.389 seconds
[2023-04-25T23:10:23.945+0100] {processor.py:153} INFO - Started process (PID=10325) to work on /home/cavemhan/Documents/python/test_scripts/cyder-test/dags/base_dag.py
[2023-04-25T23:10:23.949+0100] {processor.py:743} INFO - Processing file /home/cavemhan/Documents/python/test_scripts/cyder-test/dags/base_dag.py for tasks to queue
[2023-04-25T23:10:23.950+0100] {logging_mixin.py:137} INFO - [2023-04-25T23:10:23.950+0100] {dagbag.py:532} INFO - Filling up the DagBag from /home/cavemhan/Documents/python/test_scripts/cyder-test/dags/base_dag.py
[2023-04-25T23:10:27.260+0100] {logging_mixin.py:137} INFO - output_dir: outputs/data/
[2023-04-25T23:10:28.547+0100] {logging_mixin.py:137} INFO - [2023-04-25T23:10:28.545+0100] {dagbag.py:341} ERROR - Failed to import: /home/cavemhan/Documents/python/test_scripts/cyder-test/dags/base_dag.py
Traceback (most recent call last):
  File "/home/cavemhan/.local/share/virtualenvs/cyder-test-QPBcvLjc/lib/python3.10/site-packages/airflow/models/dagbag.py", line 337, in parse
    loader.exec_module(new_module)
  File "<frozen importlib._bootstrap_external>", line 883, in exec_module
  File "<frozen importlib._bootstrap>", line 241, in _call_with_frames_removed
  File "/home/cavemhan/Documents/python/test_scripts/cyder-test/dags/base_dag.py", line 8, in <module>
    from ml_dags import ml_dag
  File "/home/cavemhan/Documents/python/test_scripts/cyder-test/dags/ml_dags.py", line 32, in <module>
    data_processor_for_ml = DataProcessorForML(data=feature_extractor.df)
AttributeError: 'FeatureExtractor' object has no attribute 'df'
[2023-04-25T23:10:28.547+0100] {processor.py:755} WARNING - No viable dags retrieved from /home/cavemhan/Documents/python/test_scripts/cyder-test/dags/base_dag.py
[2023-04-25T23:10:28.580+0100] {processor.py:175} INFO - Processing /home/cavemhan/Documents/python/test_scripts/cyder-test/dags/base_dag.py took 4.638 seconds
[2023-04-25T23:11:22.919+0100] {processor.py:153} INFO - Started process (PID=10723) to work on /home/cavemhan/Documents/python/test_scripts/cyder-test/dags/base_dag.py
[2023-04-25T23:11:22.923+0100] {processor.py:743} INFO - Processing file /home/cavemhan/Documents/python/test_scripts/cyder-test/dags/base_dag.py for tasks to queue
[2023-04-25T23:11:22.923+0100] {logging_mixin.py:137} INFO - [2023-04-25T23:11:22.923+0100] {dagbag.py:532} INFO - Filling up the DagBag from /home/cavemhan/Documents/python/test_scripts/cyder-test/dags/base_dag.py
[2023-04-25T23:11:24.556+0100] {logging_mixin.py:137} INFO - output_dir: outputs/data/
[2023-04-25T23:11:25.327+0100] {logging_mixin.py:137} INFO - [2023-04-25T23:11:25.326+0100] {dagbag.py:341} ERROR - Failed to import: /home/cavemhan/Documents/python/test_scripts/cyder-test/dags/base_dag.py
Traceback (most recent call last):
  File "/home/cavemhan/.local/share/virtualenvs/cyder-test-QPBcvLjc/lib/python3.10/site-packages/airflow/models/dagbag.py", line 337, in parse
    loader.exec_module(new_module)
  File "<frozen importlib._bootstrap_external>", line 883, in exec_module
  File "<frozen importlib._bootstrap>", line 241, in _call_with_frames_removed
  File "/home/cavemhan/Documents/python/test_scripts/cyder-test/dags/base_dag.py", line 8, in <module>
    from ml_dags import ml_dag
  File "/home/cavemhan/Documents/python/test_scripts/cyder-test/dags/ml_dags.py", line 32, in <module>
    data_processor_for_ml = DataProcessorForML(data=feature_extractor.df)
AttributeError: 'FeatureExtractor' object has no attribute 'df'
[2023-04-25T23:11:25.327+0100] {processor.py:755} WARNING - No viable dags retrieved from /home/cavemhan/Documents/python/test_scripts/cyder-test/dags/base_dag.py
[2023-04-25T23:11:25.345+0100] {processor.py:175} INFO - Processing /home/cavemhan/Documents/python/test_scripts/cyder-test/dags/base_dag.py took 2.430 seconds
[2023-04-25T23:12:21.903+0100] {processor.py:153} INFO - Started process (PID=11060) to work on /home/cavemhan/Documents/python/test_scripts/cyder-test/dags/base_dag.py
[2023-04-25T23:12:21.905+0100] {processor.py:743} INFO - Processing file /home/cavemhan/Documents/python/test_scripts/cyder-test/dags/base_dag.py for tasks to queue
[2023-04-25T23:12:21.905+0100] {logging_mixin.py:137} INFO - [2023-04-25T23:12:21.905+0100] {dagbag.py:532} INFO - Filling up the DagBag from /home/cavemhan/Documents/python/test_scripts/cyder-test/dags/base_dag.py
[2023-04-25T23:12:23.532+0100] {logging_mixin.py:137} INFO - output_dir: outputs/data/
[2023-04-25T23:12:24.267+0100] {logging_mixin.py:137} INFO - [2023-04-25T23:12:24.266+0100] {dagbag.py:341} ERROR - Failed to import: /home/cavemhan/Documents/python/test_scripts/cyder-test/dags/base_dag.py
Traceback (most recent call last):
  File "/home/cavemhan/.local/share/virtualenvs/cyder-test-QPBcvLjc/lib/python3.10/site-packages/airflow/models/dagbag.py", line 337, in parse
    loader.exec_module(new_module)
  File "<frozen importlib._bootstrap_external>", line 883, in exec_module
  File "<frozen importlib._bootstrap>", line 241, in _call_with_frames_removed
  File "/home/cavemhan/Documents/python/test_scripts/cyder-test/dags/base_dag.py", line 8, in <module>
    from ml_dags import ml_dag
  File "/home/cavemhan/Documents/python/test_scripts/cyder-test/dags/ml_dags.py", line 32, in <module>
    data_processor_for_ml = DataProcessorForML(data=feature_extractor.df)
AttributeError: 'FeatureExtractor' object has no attribute 'df'
[2023-04-25T23:12:24.267+0100] {processor.py:755} WARNING - No viable dags retrieved from /home/cavemhan/Documents/python/test_scripts/cyder-test/dags/base_dag.py
[2023-04-25T23:12:24.289+0100] {processor.py:175} INFO - Processing /home/cavemhan/Documents/python/test_scripts/cyder-test/dags/base_dag.py took 2.389 seconds
[2023-04-25T23:13:19.423+0100] {processor.py:153} INFO - Started process (PID=11391) to work on /home/cavemhan/Documents/python/test_scripts/cyder-test/dags/base_dag.py
[2023-04-25T23:13:19.426+0100] {processor.py:743} INFO - Processing file /home/cavemhan/Documents/python/test_scripts/cyder-test/dags/base_dag.py for tasks to queue
[2023-04-25T23:13:19.427+0100] {logging_mixin.py:137} INFO - [2023-04-25T23:13:19.427+0100] {dagbag.py:532} INFO - Filling up the DagBag from /home/cavemhan/Documents/python/test_scripts/cyder-test/dags/base_dag.py
[2023-04-25T23:13:21.024+0100] {logging_mixin.py:137} INFO - output_dir: outputs/data/
[2023-04-25T23:13:21.776+0100] {logging_mixin.py:137} INFO - [2023-04-25T23:13:21.775+0100] {dagbag.py:341} ERROR - Failed to import: /home/cavemhan/Documents/python/test_scripts/cyder-test/dags/base_dag.py
Traceback (most recent call last):
  File "/home/cavemhan/.local/share/virtualenvs/cyder-test-QPBcvLjc/lib/python3.10/site-packages/airflow/models/dagbag.py", line 337, in parse
    loader.exec_module(new_module)
  File "<frozen importlib._bootstrap_external>", line 883, in exec_module
  File "<frozen importlib._bootstrap>", line 241, in _call_with_frames_removed
  File "/home/cavemhan/Documents/python/test_scripts/cyder-test/dags/base_dag.py", line 8, in <module>
    from ml_dags import ml_dag
  File "/home/cavemhan/Documents/python/test_scripts/cyder-test/dags/ml_dags.py", line 32, in <module>
    data_processor_for_ml = DataProcessorForML(data=feature_extractor.df)
AttributeError: 'FeatureExtractor' object has no attribute 'df'
[2023-04-25T23:13:21.776+0100] {processor.py:755} WARNING - No viable dags retrieved from /home/cavemhan/Documents/python/test_scripts/cyder-test/dags/base_dag.py
[2023-04-25T23:13:21.800+0100] {processor.py:175} INFO - Processing /home/cavemhan/Documents/python/test_scripts/cyder-test/dags/base_dag.py took 2.380 seconds
[2023-04-25T23:14:19.667+0100] {processor.py:153} INFO - Started process (PID=11734) to work on /home/cavemhan/Documents/python/test_scripts/cyder-test/dags/base_dag.py
[2023-04-25T23:14:19.668+0100] {processor.py:743} INFO - Processing file /home/cavemhan/Documents/python/test_scripts/cyder-test/dags/base_dag.py for tasks to queue
[2023-04-25T23:14:19.668+0100] {logging_mixin.py:137} INFO - [2023-04-25T23:14:19.668+0100] {dagbag.py:532} INFO - Filling up the DagBag from /home/cavemhan/Documents/python/test_scripts/cyder-test/dags/base_dag.py
[2023-04-25T23:14:21.258+0100] {logging_mixin.py:137} INFO - output_dir: outputs/data/
[2023-04-25T23:14:22.042+0100] {logging_mixin.py:137} INFO - [2023-04-25T23:14:22.041+0100] {dagbag.py:341} ERROR - Failed to import: /home/cavemhan/Documents/python/test_scripts/cyder-test/dags/base_dag.py
Traceback (most recent call last):
  File "/home/cavemhan/.local/share/virtualenvs/cyder-test-QPBcvLjc/lib/python3.10/site-packages/airflow/models/dagbag.py", line 337, in parse
    loader.exec_module(new_module)
  File "<frozen importlib._bootstrap_external>", line 883, in exec_module
  File "<frozen importlib._bootstrap>", line 241, in _call_with_frames_removed
  File "/home/cavemhan/Documents/python/test_scripts/cyder-test/dags/base_dag.py", line 8, in <module>
    from ml_dags import ml_dag
  File "/home/cavemhan/Documents/python/test_scripts/cyder-test/dags/ml_dags.py", line 32, in <module>
    data_processor_for_ml = DataProcessorForML(data=feature_extractor.df)
AttributeError: 'FeatureExtractor' object has no attribute 'df'
[2023-04-25T23:14:22.042+0100] {processor.py:755} WARNING - No viable dags retrieved from /home/cavemhan/Documents/python/test_scripts/cyder-test/dags/base_dag.py
[2023-04-25T23:14:22.070+0100] {processor.py:175} INFO - Processing /home/cavemhan/Documents/python/test_scripts/cyder-test/dags/base_dag.py took 2.407 seconds
[2023-04-25T23:15:19.784+0100] {processor.py:153} INFO - Started process (PID=12095) to work on /home/cavemhan/Documents/python/test_scripts/cyder-test/dags/base_dag.py
[2023-04-25T23:15:19.788+0100] {processor.py:743} INFO - Processing file /home/cavemhan/Documents/python/test_scripts/cyder-test/dags/base_dag.py for tasks to queue
[2023-04-25T23:15:19.788+0100] {logging_mixin.py:137} INFO - [2023-04-25T23:15:19.788+0100] {dagbag.py:532} INFO - Filling up the DagBag from /home/cavemhan/Documents/python/test_scripts/cyder-test/dags/base_dag.py
[2023-04-25T23:15:21.386+0100] {logging_mixin.py:137} INFO - output_dir: outputs/data/
[2023-04-25T23:15:22.126+0100] {logging_mixin.py:137} INFO - [2023-04-25T23:15:22.126+0100] {dagbag.py:341} ERROR - Failed to import: /home/cavemhan/Documents/python/test_scripts/cyder-test/dags/base_dag.py
Traceback (most recent call last):
  File "/home/cavemhan/.local/share/virtualenvs/cyder-test-QPBcvLjc/lib/python3.10/site-packages/airflow/models/dagbag.py", line 337, in parse
    loader.exec_module(new_module)
  File "<frozen importlib._bootstrap_external>", line 883, in exec_module
  File "<frozen importlib._bootstrap>", line 241, in _call_with_frames_removed
  File "/home/cavemhan/Documents/python/test_scripts/cyder-test/dags/base_dag.py", line 8, in <module>
    from ml_dags import ml_dag
  File "/home/cavemhan/Documents/python/test_scripts/cyder-test/dags/ml_dags.py", line 32, in <module>
    data_processor_for_ml = DataProcessorForML(data=feature_extractor.df)
AttributeError: 'FeatureExtractor' object has no attribute 'df'
[2023-04-25T23:15:22.127+0100] {processor.py:755} WARNING - No viable dags retrieved from /home/cavemhan/Documents/python/test_scripts/cyder-test/dags/base_dag.py
[2023-04-25T23:15:22.149+0100] {processor.py:175} INFO - Processing /home/cavemhan/Documents/python/test_scripts/cyder-test/dags/base_dag.py took 2.367 seconds
[2023-04-25T23:16:21.232+0100] {processor.py:153} INFO - Started process (PID=12436) to work on /home/cavemhan/Documents/python/test_scripts/cyder-test/dags/base_dag.py
[2023-04-25T23:16:21.236+0100] {processor.py:743} INFO - Processing file /home/cavemhan/Documents/python/test_scripts/cyder-test/dags/base_dag.py for tasks to queue
[2023-04-25T23:16:21.237+0100] {logging_mixin.py:137} INFO - [2023-04-25T23:16:21.237+0100] {dagbag.py:532} INFO - Filling up the DagBag from /home/cavemhan/Documents/python/test_scripts/cyder-test/dags/base_dag.py
[2023-04-25T23:16:22.876+0100] {logging_mixin.py:137} INFO - output_dir: outputs/data/
[2023-04-25T23:16:23.626+0100] {logging_mixin.py:137} INFO - [2023-04-25T23:16:23.625+0100] {dagbag.py:341} ERROR - Failed to import: /home/cavemhan/Documents/python/test_scripts/cyder-test/dags/base_dag.py
Traceback (most recent call last):
  File "/home/cavemhan/.local/share/virtualenvs/cyder-test-QPBcvLjc/lib/python3.10/site-packages/airflow/models/dagbag.py", line 337, in parse
    loader.exec_module(new_module)
  File "<frozen importlib._bootstrap_external>", line 883, in exec_module
  File "<frozen importlib._bootstrap>", line 241, in _call_with_frames_removed
  File "/home/cavemhan/Documents/python/test_scripts/cyder-test/dags/base_dag.py", line 8, in <module>
    from ml_dags import ml_dag
  File "/home/cavemhan/Documents/python/test_scripts/cyder-test/dags/ml_dags.py", line 32, in <module>
    data_processor_for_ml = DataProcessorForML(data=feature_extractor.df)
AttributeError: 'FeatureExtractor' object has no attribute 'df'
[2023-04-25T23:16:23.627+0100] {processor.py:755} WARNING - No viable dags retrieved from /home/cavemhan/Documents/python/test_scripts/cyder-test/dags/base_dag.py
[2023-04-25T23:16:23.648+0100] {processor.py:175} INFO - Processing /home/cavemhan/Documents/python/test_scripts/cyder-test/dags/base_dag.py took 2.419 seconds
[2023-04-25T23:17:25.032+0100] {processor.py:153} INFO - Started process (PID=12799) to work on /home/cavemhan/Documents/python/test_scripts/cyder-test/dags/base_dag.py
[2023-04-25T23:17:25.036+0100] {processor.py:743} INFO - Processing file /home/cavemhan/Documents/python/test_scripts/cyder-test/dags/base_dag.py for tasks to queue
[2023-04-25T23:17:25.037+0100] {logging_mixin.py:137} INFO - [2023-04-25T23:17:25.037+0100] {dagbag.py:532} INFO - Filling up the DagBag from /home/cavemhan/Documents/python/test_scripts/cyder-test/dags/base_dag.py
[2023-04-25T23:17:26.698+0100] {logging_mixin.py:137} INFO - output_dir: outputs/data/
[2023-04-25T23:17:27.468+0100] {logging_mixin.py:137} INFO - [2023-04-25T23:17:27.467+0100] {dagbag.py:341} ERROR - Failed to import: /home/cavemhan/Documents/python/test_scripts/cyder-test/dags/base_dag.py
Traceback (most recent call last):
  File "/home/cavemhan/.local/share/virtualenvs/cyder-test-QPBcvLjc/lib/python3.10/site-packages/airflow/models/dagbag.py", line 337, in parse
    loader.exec_module(new_module)
  File "<frozen importlib._bootstrap_external>", line 883, in exec_module
  File "<frozen importlib._bootstrap>", line 241, in _call_with_frames_removed
  File "/home/cavemhan/Documents/python/test_scripts/cyder-test/dags/base_dag.py", line 8, in <module>
    from ml_dags import ml_dag
  File "/home/cavemhan/Documents/python/test_scripts/cyder-test/dags/ml_dags.py", line 32, in <module>
    data_processor_for_ml = DataProcessorForML(data=feature_extractor.df)
AttributeError: 'FeatureExtractor' object has no attribute 'df'
[2023-04-25T23:17:27.468+0100] {processor.py:755} WARNING - No viable dags retrieved from /home/cavemhan/Documents/python/test_scripts/cyder-test/dags/base_dag.py
[2023-04-25T23:17:27.487+0100] {processor.py:175} INFO - Processing /home/cavemhan/Documents/python/test_scripts/cyder-test/dags/base_dag.py took 2.458 seconds
[2023-04-25T23:58:55.008+0100] {processor.py:153} INFO - Started process (PID=13501) to work on /home/cavemhan/Documents/python/test_scripts/cyder-test/dags/base_dag.py
[2023-04-25T23:58:55.011+0100] {processor.py:743} INFO - Processing file /home/cavemhan/Documents/python/test_scripts/cyder-test/dags/base_dag.py for tasks to queue
[2023-04-25T23:58:55.012+0100] {logging_mixin.py:137} INFO - [2023-04-25T23:58:55.012+0100] {dagbag.py:532} INFO - Filling up the DagBag from /home/cavemhan/Documents/python/test_scripts/cyder-test/dags/base_dag.py
[2023-04-25T23:58:56.598+0100] {logging_mixin.py:137} INFO - output_dir: outputs/data/
[2023-04-25T23:58:57.352+0100] {logging_mixin.py:137} INFO - [2023-04-25T23:58:57.351+0100] {dagbag.py:341} ERROR - Failed to import: /home/cavemhan/Documents/python/test_scripts/cyder-test/dags/base_dag.py
Traceback (most recent call last):
  File "/home/cavemhan/.local/share/virtualenvs/cyder-test-QPBcvLjc/lib/python3.10/site-packages/airflow/models/dagbag.py", line 337, in parse
    loader.exec_module(new_module)
  File "<frozen importlib._bootstrap_external>", line 883, in exec_module
  File "<frozen importlib._bootstrap>", line 241, in _call_with_frames_removed
  File "/home/cavemhan/Documents/python/test_scripts/cyder-test/dags/base_dag.py", line 8, in <module>
    from ml_dags import ml_dag
  File "/home/cavemhan/Documents/python/test_scripts/cyder-test/dags/ml_dags.py", line 32, in <module>
    data_processor_for_ml = DataProcessorForML(data=feature_extractor.df)
AttributeError: 'FeatureExtractor' object has no attribute 'df'
[2023-04-25T23:58:57.352+0100] {processor.py:755} WARNING - No viable dags retrieved from /home/cavemhan/Documents/python/test_scripts/cyder-test/dags/base_dag.py
[2023-04-25T23:58:57.373+0100] {processor.py:175} INFO - Processing /home/cavemhan/Documents/python/test_scripts/cyder-test/dags/base_dag.py took 2.369 seconds
[2023-04-25T23:59:36.163+0100] {processor.py:153} INFO - Started process (PID=13674) to work on /home/cavemhan/Documents/python/test_scripts/cyder-test/dags/base_dag.py
[2023-04-25T23:59:36.166+0100] {processor.py:743} INFO - Processing file /home/cavemhan/Documents/python/test_scripts/cyder-test/dags/base_dag.py for tasks to queue
[2023-04-25T23:59:36.167+0100] {logging_mixin.py:137} INFO - [2023-04-25T23:59:36.167+0100] {dagbag.py:532} INFO - Filling up the DagBag from /home/cavemhan/Documents/python/test_scripts/cyder-test/dags/base_dag.py
[2023-04-25T23:59:37.773+0100] {logging_mixin.py:137} INFO - output_dir: outputs/data/
[2023-04-25T23:59:38.509+0100] {logging_mixin.py:137} INFO - [2023-04-25T23:59:38.508+0100] {dagbag.py:341} ERROR - Failed to import: /home/cavemhan/Documents/python/test_scripts/cyder-test/dags/base_dag.py
Traceback (most recent call last):
  File "/home/cavemhan/.local/share/virtualenvs/cyder-test-QPBcvLjc/lib/python3.10/site-packages/airflow/models/dagbag.py", line 337, in parse
    loader.exec_module(new_module)
  File "<frozen importlib._bootstrap_external>", line 883, in exec_module
  File "<frozen importlib._bootstrap>", line 241, in _call_with_frames_removed
  File "/home/cavemhan/Documents/python/test_scripts/cyder-test/dags/base_dag.py", line 8, in <module>
    from ml_dags import ml_dag
  File "/home/cavemhan/Documents/python/test_scripts/cyder-test/dags/ml_dags.py", line 32, in <module>
    data_processor_for_ml = DataProcessorForML(data=feature_extractor.df)
AttributeError: 'FeatureExtractor' object has no attribute 'df'
[2023-04-25T23:59:38.509+0100] {processor.py:755} WARNING - No viable dags retrieved from /home/cavemhan/Documents/python/test_scripts/cyder-test/dags/base_dag.py
[2023-04-25T23:59:38.527+0100] {processor.py:175} INFO - Processing /home/cavemhan/Documents/python/test_scripts/cyder-test/dags/base_dag.py took 2.368 seconds
[2023-04-26T00:00:26.827+0100] {processor.py:153} INFO - Started process (PID=13922) to work on /home/cavemhan/Documents/python/test_scripts/cyder-test/dags/base_dag.py
[2023-04-26T00:00:26.831+0100] {processor.py:743} INFO - Processing file /home/cavemhan/Documents/python/test_scripts/cyder-test/dags/base_dag.py for tasks to queue
[2023-04-26T00:00:26.831+0100] {logging_mixin.py:137} INFO - [2023-04-26T00:00:26.831+0100] {dagbag.py:532} INFO - Filling up the DagBag from /home/cavemhan/Documents/python/test_scripts/cyder-test/dags/base_dag.py
[2023-04-26T00:00:28.388+0100] {logging_mixin.py:137} INFO - output_dir: outputs/data/
[2023-04-26T00:00:29.166+0100] {logging_mixin.py:137} INFO - [2023-04-26T00:00:29.165+0100] {dagbag.py:341} ERROR - Failed to import: /home/cavemhan/Documents/python/test_scripts/cyder-test/dags/base_dag.py
Traceback (most recent call last):
  File "/home/cavemhan/.local/share/virtualenvs/cyder-test-QPBcvLjc/lib/python3.10/site-packages/airflow/models/dagbag.py", line 337, in parse
    loader.exec_module(new_module)
  File "<frozen importlib._bootstrap_external>", line 883, in exec_module
  File "<frozen importlib._bootstrap>", line 241, in _call_with_frames_removed
  File "/home/cavemhan/Documents/python/test_scripts/cyder-test/dags/base_dag.py", line 8, in <module>
    from ml_dags import ml_dag
  File "/home/cavemhan/Documents/python/test_scripts/cyder-test/dags/ml_dags.py", line 32, in <module>
    data_processor_for_ml = DataProcessorForML(data=feature_extractor.df)
AttributeError: 'FeatureExtractor' object has no attribute 'df'
[2023-04-26T00:00:29.166+0100] {processor.py:755} WARNING - No viable dags retrieved from /home/cavemhan/Documents/python/test_scripts/cyder-test/dags/base_dag.py
[2023-04-26T00:00:29.183+0100] {processor.py:175} INFO - Processing /home/cavemhan/Documents/python/test_scripts/cyder-test/dags/base_dag.py took 2.359 seconds
[2023-04-26T00:01:22.259+0100] {processor.py:153} INFO - Started process (PID=14396) to work on /home/cavemhan/Documents/python/test_scripts/cyder-test/dags/base_dag.py
[2023-04-26T00:01:22.263+0100] {processor.py:743} INFO - Processing file /home/cavemhan/Documents/python/test_scripts/cyder-test/dags/base_dag.py for tasks to queue
[2023-04-26T00:01:22.264+0100] {logging_mixin.py:137} INFO - [2023-04-26T00:01:22.264+0100] {dagbag.py:532} INFO - Filling up the DagBag from /home/cavemhan/Documents/python/test_scripts/cyder-test/dags/base_dag.py
[2023-04-26T00:01:23.960+0100] {logging_mixin.py:137} INFO - output_dir: outputs/data/
[2023-04-26T00:01:24.742+0100] {logging_mixin.py:137} INFO - [2023-04-26T00:01:24.741+0100] {dagbag.py:341} ERROR - Failed to import: /home/cavemhan/Documents/python/test_scripts/cyder-test/dags/base_dag.py
Traceback (most recent call last):
  File "/home/cavemhan/.local/share/virtualenvs/cyder-test-QPBcvLjc/lib/python3.10/site-packages/airflow/models/dagbag.py", line 337, in parse
    loader.exec_module(new_module)
  File "<frozen importlib._bootstrap_external>", line 883, in exec_module
  File "<frozen importlib._bootstrap>", line 241, in _call_with_frames_removed
  File "/home/cavemhan/Documents/python/test_scripts/cyder-test/dags/base_dag.py", line 8, in <module>
    from ml_dags import ml_dag
  File "/home/cavemhan/Documents/python/test_scripts/cyder-test/dags/ml_dags.py", line 32, in <module>
    data_processor_for_ml = DataProcessorForML(data=feature_extractor.df)
AttributeError: 'FeatureExtractor' object has no attribute 'df'
[2023-04-26T00:01:24.743+0100] {processor.py:755} WARNING - No viable dags retrieved from /home/cavemhan/Documents/python/test_scripts/cyder-test/dags/base_dag.py
[2023-04-26T00:01:24.763+0100] {processor.py:175} INFO - Processing /home/cavemhan/Documents/python/test_scripts/cyder-test/dags/base_dag.py took 2.507 seconds
[2023-04-26T00:02:23.623+0100] {processor.py:153} INFO - Started process (PID=18741) to work on /home/cavemhan/Documents/python/test_scripts/cyder-test/dags/base_dag.py
[2023-04-26T00:02:23.625+0100] {processor.py:743} INFO - Processing file /home/cavemhan/Documents/python/test_scripts/cyder-test/dags/base_dag.py for tasks to queue
[2023-04-26T00:02:23.626+0100] {logging_mixin.py:137} INFO - [2023-04-26T00:02:23.626+0100] {dagbag.py:532} INFO - Filling up the DagBag from /home/cavemhan/Documents/python/test_scripts/cyder-test/dags/base_dag.py
[2023-04-26T00:02:25.374+0100] {logging_mixin.py:137} INFO - output_dir: outputs/data/
[2023-04-26T00:02:26.212+0100] {logging_mixin.py:137} INFO - [2023-04-26T00:02:26.211+0100] {dagbag.py:341} ERROR - Failed to import: /home/cavemhan/Documents/python/test_scripts/cyder-test/dags/base_dag.py
Traceback (most recent call last):
  File "/home/cavemhan/.local/share/virtualenvs/cyder-test-QPBcvLjc/lib/python3.10/site-packages/airflow/models/dagbag.py", line 337, in parse
    loader.exec_module(new_module)
  File "<frozen importlib._bootstrap_external>", line 883, in exec_module
  File "<frozen importlib._bootstrap>", line 241, in _call_with_frames_removed
  File "/home/cavemhan/Documents/python/test_scripts/cyder-test/dags/base_dag.py", line 8, in <module>
    from ml_dags import ml_dag
  File "/home/cavemhan/Documents/python/test_scripts/cyder-test/dags/ml_dags.py", line 32, in <module>
    data_processor_for_ml = DataProcessorForML(data=feature_extractor.df)
AttributeError: 'FeatureExtractor' object has no attribute 'df'
[2023-04-26T00:02:26.213+0100] {processor.py:755} WARNING - No viable dags retrieved from /home/cavemhan/Documents/python/test_scripts/cyder-test/dags/base_dag.py
[2023-04-26T00:02:26.252+0100] {processor.py:175} INFO - Processing /home/cavemhan/Documents/python/test_scripts/cyder-test/dags/base_dag.py took 2.632 seconds
[2023-04-26T00:03:19.207+0100] {processor.py:153} INFO - Started process (PID=20066) to work on /home/cavemhan/Documents/python/test_scripts/cyder-test/dags/base_dag.py
[2023-04-26T00:03:19.208+0100] {processor.py:743} INFO - Processing file /home/cavemhan/Documents/python/test_scripts/cyder-test/dags/base_dag.py for tasks to queue
[2023-04-26T00:03:19.210+0100] {logging_mixin.py:137} INFO - [2023-04-26T00:03:19.209+0100] {dagbag.py:532} INFO - Filling up the DagBag from /home/cavemhan/Documents/python/test_scripts/cyder-test/dags/base_dag.py
[2023-04-26T00:03:21.345+0100] {logging_mixin.py:137} INFO - output_dir: outputs/data/
[2023-04-26T00:03:22.372+0100] {logging_mixin.py:137} INFO - [2023-04-26T00:03:22.371+0100] {dagbag.py:341} ERROR - Failed to import: /home/cavemhan/Documents/python/test_scripts/cyder-test/dags/base_dag.py
Traceback (most recent call last):
  File "/home/cavemhan/.local/share/virtualenvs/cyder-test-QPBcvLjc/lib/python3.10/site-packages/airflow/models/dagbag.py", line 337, in parse
    loader.exec_module(new_module)
  File "<frozen importlib._bootstrap_external>", line 883, in exec_module
  File "<frozen importlib._bootstrap>", line 241, in _call_with_frames_removed
  File "/home/cavemhan/Documents/python/test_scripts/cyder-test/dags/base_dag.py", line 8, in <module>
    from ml_dags import ml_dag
  File "/home/cavemhan/Documents/python/test_scripts/cyder-test/dags/ml_dags.py", line 32, in <module>
    data_processor_for_ml = DataProcessorForML(data=feature_extractor.df)
AttributeError: 'FeatureExtractor' object has no attribute 'df'
[2023-04-26T00:03:22.372+0100] {processor.py:755} WARNING - No viable dags retrieved from /home/cavemhan/Documents/python/test_scripts/cyder-test/dags/base_dag.py
[2023-04-26T00:03:22.394+0100] {processor.py:175} INFO - Processing /home/cavemhan/Documents/python/test_scripts/cyder-test/dags/base_dag.py took 3.190 seconds
[2023-04-26T00:04:13.545+0100] {processor.py:153} INFO - Started process (PID=21248) to work on /home/cavemhan/Documents/python/test_scripts/cyder-test/dags/base_dag.py
[2023-04-26T00:04:13.546+0100] {processor.py:743} INFO - Processing file /home/cavemhan/Documents/python/test_scripts/cyder-test/dags/base_dag.py for tasks to queue
[2023-04-26T00:04:13.549+0100] {logging_mixin.py:137} INFO - [2023-04-26T00:04:13.548+0100] {dagbag.py:532} INFO - Filling up the DagBag from /home/cavemhan/Documents/python/test_scripts/cyder-test/dags/base_dag.py
[2023-04-26T00:04:15.406+0100] {logging_mixin.py:137} INFO - output_dir: outputs/data/
[2023-04-26T00:04:16.226+0100] {logging_mixin.py:137} INFO - [2023-04-26T00:04:16.225+0100] {dagbag.py:341} ERROR - Failed to import: /home/cavemhan/Documents/python/test_scripts/cyder-test/dags/base_dag.py
Traceback (most recent call last):
  File "/home/cavemhan/.local/share/virtualenvs/cyder-test-QPBcvLjc/lib/python3.10/site-packages/airflow/models/dagbag.py", line 337, in parse
    loader.exec_module(new_module)
  File "<frozen importlib._bootstrap_external>", line 883, in exec_module
  File "<frozen importlib._bootstrap>", line 241, in _call_with_frames_removed
  File "/home/cavemhan/Documents/python/test_scripts/cyder-test/dags/base_dag.py", line 8, in <module>
    from ml_dags import ml_dag
  File "/home/cavemhan/Documents/python/test_scripts/cyder-test/dags/ml_dags.py", line 32, in <module>
    data_processor_for_ml = DataProcessorForML(data=feature_extractor.df)
AttributeError: 'FeatureExtractor' object has no attribute 'df'
[2023-04-26T00:04:16.227+0100] {processor.py:755} WARNING - No viable dags retrieved from /home/cavemhan/Documents/python/test_scripts/cyder-test/dags/base_dag.py
[2023-04-26T00:04:16.245+0100] {processor.py:175} INFO - Processing /home/cavemhan/Documents/python/test_scripts/cyder-test/dags/base_dag.py took 2.703 seconds
[2023-04-26T00:05:10.192+0100] {processor.py:153} INFO - Started process (PID=22681) to work on /home/cavemhan/Documents/python/test_scripts/cyder-test/dags/base_dag.py
[2023-04-26T00:05:10.193+0100] {processor.py:743} INFO - Processing file /home/cavemhan/Documents/python/test_scripts/cyder-test/dags/base_dag.py for tasks to queue
[2023-04-26T00:05:10.194+0100] {logging_mixin.py:137} INFO - [2023-04-26T00:05:10.194+0100] {dagbag.py:532} INFO - Filling up the DagBag from /home/cavemhan/Documents/python/test_scripts/cyder-test/dags/base_dag.py
[2023-04-26T00:05:12.656+0100] {logging_mixin.py:137} INFO - output_dir: outputs/data/
[2023-04-26T00:05:13.613+0100] {logging_mixin.py:137} INFO - [2023-04-26T00:05:13.611+0100] {dagbag.py:341} ERROR - Failed to import: /home/cavemhan/Documents/python/test_scripts/cyder-test/dags/base_dag.py
Traceback (most recent call last):
  File "/home/cavemhan/.local/share/virtualenvs/cyder-test-QPBcvLjc/lib/python3.10/site-packages/airflow/models/dagbag.py", line 337, in parse
    loader.exec_module(new_module)
  File "<frozen importlib._bootstrap_external>", line 883, in exec_module
  File "<frozen importlib._bootstrap>", line 241, in _call_with_frames_removed
  File "/home/cavemhan/Documents/python/test_scripts/cyder-test/dags/base_dag.py", line 8, in <module>
    from ml_dags import ml_dag
  File "/home/cavemhan/Documents/python/test_scripts/cyder-test/dags/ml_dags.py", line 40, in <module>
    data_processor_for_ml = DataProcessorForML(data=feature_extractor.df)
AttributeError: 'FeatureExtractor' object has no attribute 'df'
[2023-04-26T00:05:13.613+0100] {processor.py:755} WARNING - No viable dags retrieved from /home/cavemhan/Documents/python/test_scripts/cyder-test/dags/base_dag.py
[2023-04-26T00:05:13.630+0100] {processor.py:175} INFO - Processing /home/cavemhan/Documents/python/test_scripts/cyder-test/dags/base_dag.py took 3.443 seconds
[2023-04-26T00:06:07.199+0100] {processor.py:153} INFO - Started process (PID=23955) to work on /home/cavemhan/Documents/python/test_scripts/cyder-test/dags/base_dag.py
[2023-04-26T00:06:07.200+0100] {processor.py:743} INFO - Processing file /home/cavemhan/Documents/python/test_scripts/cyder-test/dags/base_dag.py for tasks to queue
[2023-04-26T00:06:07.201+0100] {logging_mixin.py:137} INFO - [2023-04-26T00:06:07.201+0100] {dagbag.py:532} INFO - Filling up the DagBag from /home/cavemhan/Documents/python/test_scripts/cyder-test/dags/base_dag.py
[2023-04-26T00:06:09.732+0100] {logging_mixin.py:137} INFO - output_dir: outputs/data/
[2023-04-26T00:06:10.779+0100] {logging_mixin.py:137} INFO - [2023-04-26T00:06:10.778+0100] {dagbag.py:341} ERROR - Failed to import: /home/cavemhan/Documents/python/test_scripts/cyder-test/dags/base_dag.py
Traceback (most recent call last):
  File "/home/cavemhan/.local/share/virtualenvs/cyder-test-QPBcvLjc/lib/python3.10/site-packages/airflow/models/dagbag.py", line 337, in parse
    loader.exec_module(new_module)
  File "<frozen importlib._bootstrap_external>", line 883, in exec_module
  File "<frozen importlib._bootstrap>", line 241, in _call_with_frames_removed
  File "/home/cavemhan/Documents/python/test_scripts/cyder-test/dags/base_dag.py", line 8, in <module>
    from ml_dags import ml_dag
  File "/home/cavemhan/Documents/python/test_scripts/cyder-test/dags/ml_dags.py", line 40, in <module>
    data_processor_for_ml = DataProcessorForML(data=feature_extractor.df)
AttributeError: 'FeatureExtractor' object has no attribute 'df'
[2023-04-26T00:06:10.780+0100] {processor.py:755} WARNING - No viable dags retrieved from /home/cavemhan/Documents/python/test_scripts/cyder-test/dags/base_dag.py
[2023-04-26T00:06:10.799+0100] {processor.py:175} INFO - Processing /home/cavemhan/Documents/python/test_scripts/cyder-test/dags/base_dag.py took 3.605 seconds
[2023-04-26T00:07:02.852+0100] {processor.py:153} INFO - Started process (PID=25252) to work on /home/cavemhan/Documents/python/test_scripts/cyder-test/dags/base_dag.py
[2023-04-26T00:07:02.853+0100] {processor.py:743} INFO - Processing file /home/cavemhan/Documents/python/test_scripts/cyder-test/dags/base_dag.py for tasks to queue
[2023-04-26T00:07:02.854+0100] {logging_mixin.py:137} INFO - [2023-04-26T00:07:02.853+0100] {dagbag.py:532} INFO - Filling up the DagBag from /home/cavemhan/Documents/python/test_scripts/cyder-test/dags/base_dag.py
[2023-04-26T00:07:04.753+0100] {logging_mixin.py:137} INFO - output_dir: outputs/data/
[2023-04-26T00:07:05.544+0100] {logging_mixin.py:137} INFO - [2023-04-26T00:07:05.543+0100] {dagbag.py:341} ERROR - Failed to import: /home/cavemhan/Documents/python/test_scripts/cyder-test/dags/base_dag.py
Traceback (most recent call last):
  File "/home/cavemhan/.local/share/virtualenvs/cyder-test-QPBcvLjc/lib/python3.10/site-packages/airflow/models/dagbag.py", line 337, in parse
    loader.exec_module(new_module)
  File "<frozen importlib._bootstrap_external>", line 883, in exec_module
  File "<frozen importlib._bootstrap>", line 241, in _call_with_frames_removed
  File "/home/cavemhan/Documents/python/test_scripts/cyder-test/dags/base_dag.py", line 8, in <module>
    from ml_dags import ml_dag
  File "/home/cavemhan/Documents/python/test_scripts/cyder-test/dags/ml_dags.py", line 40, in <module>
    data_processor_for_ml = DataProcessorForML(data=feature_extractor.df)
AttributeError: 'FeatureExtractor' object has no attribute 'df'
[2023-04-26T00:07:05.544+0100] {processor.py:755} WARNING - No viable dags retrieved from /home/cavemhan/Documents/python/test_scripts/cyder-test/dags/base_dag.py
[2023-04-26T00:07:05.561+0100] {processor.py:175} INFO - Processing /home/cavemhan/Documents/python/test_scripts/cyder-test/dags/base_dag.py took 2.712 seconds
[2023-04-26T00:07:59.355+0100] {processor.py:153} INFO - Started process (PID=26558) to work on /home/cavemhan/Documents/python/test_scripts/cyder-test/dags/base_dag.py
[2023-04-26T00:07:59.356+0100] {processor.py:743} INFO - Processing file /home/cavemhan/Documents/python/test_scripts/cyder-test/dags/base_dag.py for tasks to queue
[2023-04-26T00:07:59.357+0100] {logging_mixin.py:137} INFO - [2023-04-26T00:07:59.357+0100] {dagbag.py:532} INFO - Filling up the DagBag from /home/cavemhan/Documents/python/test_scripts/cyder-test/dags/base_dag.py
[2023-04-26T00:08:01.695+0100] {logging_mixin.py:137} INFO - output_dir: outputs/data/
[2023-04-26T00:08:02.506+0100] {logging_mixin.py:137} INFO - [2023-04-26T00:08:02.505+0100] {dagbag.py:341} ERROR - Failed to import: /home/cavemhan/Documents/python/test_scripts/cyder-test/dags/base_dag.py
Traceback (most recent call last):
  File "/home/cavemhan/.local/share/virtualenvs/cyder-test-QPBcvLjc/lib/python3.10/site-packages/airflow/models/dagbag.py", line 337, in parse
    loader.exec_module(new_module)
  File "<frozen importlib._bootstrap_external>", line 883, in exec_module
  File "<frozen importlib._bootstrap>", line 241, in _call_with_frames_removed
  File "/home/cavemhan/Documents/python/test_scripts/cyder-test/dags/base_dag.py", line 8, in <module>
    from ml_dags import ml_dag
  File "/home/cavemhan/Documents/python/test_scripts/cyder-test/dags/ml_dags.py", line 40
    data_processor_for_ml = DataProcessorForML(data= "{{ ti.xcom_pull(task_ids='run_example_dag_1', key='df') }}" feature_extractor.)
                                                     ^^^^^^^^^^^^^^^^^^^^^^^^^^^^^^^^^^^^^^^^^^^^^^^^^^^^^^^^^^^^^^^^^^^^^^^^^^^^^^
SyntaxError: invalid syntax. Perhaps you forgot a comma?
[2023-04-26T00:08:02.507+0100] {processor.py:755} WARNING - No viable dags retrieved from /home/cavemhan/Documents/python/test_scripts/cyder-test/dags/base_dag.py
[2023-04-26T00:08:02.528+0100] {processor.py:175} INFO - Processing /home/cavemhan/Documents/python/test_scripts/cyder-test/dags/base_dag.py took 3.178 seconds
[2023-04-26T00:08:53.258+0100] {processor.py:153} INFO - Started process (PID=27823) to work on /home/cavemhan/Documents/python/test_scripts/cyder-test/dags/base_dag.py
[2023-04-26T00:08:53.259+0100] {processor.py:743} INFO - Processing file /home/cavemhan/Documents/python/test_scripts/cyder-test/dags/base_dag.py for tasks to queue
[2023-04-26T00:08:53.260+0100] {logging_mixin.py:137} INFO - [2023-04-26T00:08:53.260+0100] {dagbag.py:532} INFO - Filling up the DagBag from /home/cavemhan/Documents/python/test_scripts/cyder-test/dags/base_dag.py
[2023-04-26T00:08:55.353+0100] {logging_mixin.py:137} INFO - output_dir: outputs/data/
[2023-04-26T00:08:56.235+0100] {logging_mixin.py:137} INFO - [2023-04-26T00:08:56.233+0100] {dagbag.py:341} ERROR - Failed to import: /home/cavemhan/Documents/python/test_scripts/cyder-test/dags/base_dag.py
Traceback (most recent call last):
  File "/home/cavemhan/.local/share/virtualenvs/cyder-test-QPBcvLjc/lib/python3.10/site-packages/airflow/models/dagbag.py", line 337, in parse
    loader.exec_module(new_module)
  File "<frozen importlib._bootstrap_external>", line 883, in exec_module
  File "<frozen importlib._bootstrap>", line 241, in _call_with_frames_removed
  File "/home/cavemhan/Documents/python/test_scripts/cyder-test/dags/base_dag.py", line 8, in <module>
    from ml_dags import ml_dag
  File "/home/cavemhan/Documents/python/test_scripts/cyder-test/dags/ml_dags.py", line 40
    data_processor_for_ml = DataProcessorForML(data= "{{ ti.xcom_pull(task_ids='run_example_dag_1', key='df') }}" feature_extractor.)
                                                     ^^^^^^^^^^^^^^^^^^^^^^^^^^^^^^^^^^^^^^^^^^^^^^^^^^^^^^^^^^^^^^^^^^^^^^^^^^^^^^
SyntaxError: invalid syntax. Perhaps you forgot a comma?
[2023-04-26T00:08:56.235+0100] {processor.py:755} WARNING - No viable dags retrieved from /home/cavemhan/Documents/python/test_scripts/cyder-test/dags/base_dag.py
[2023-04-26T00:08:56.252+0100] {processor.py:175} INFO - Processing /home/cavemhan/Documents/python/test_scripts/cyder-test/dags/base_dag.py took 2.997 seconds
[2023-04-26T00:09:48.435+0100] {processor.py:153} INFO - Started process (PID=29187) to work on /home/cavemhan/Documents/python/test_scripts/cyder-test/dags/base_dag.py
[2023-04-26T00:09:48.436+0100] {processor.py:743} INFO - Processing file /home/cavemhan/Documents/python/test_scripts/cyder-test/dags/base_dag.py for tasks to queue
[2023-04-26T00:09:48.437+0100] {logging_mixin.py:137} INFO - [2023-04-26T00:09:48.437+0100] {dagbag.py:532} INFO - Filling up the DagBag from /home/cavemhan/Documents/python/test_scripts/cyder-test/dags/base_dag.py
[2023-04-26T00:09:51.159+0100] {logging_mixin.py:137} INFO - output_dir: outputs/data/
[2023-04-26T00:09:52.151+0100] {logging_mixin.py:137} INFO - [2023-04-26T00:09:52.148+0100] {dagbag.py:341} ERROR - Failed to import: /home/cavemhan/Documents/python/test_scripts/cyder-test/dags/base_dag.py
Traceback (most recent call last):
  File "/home/cavemhan/.local/share/virtualenvs/cyder-test-QPBcvLjc/lib/python3.10/site-packages/airflow/models/dagbag.py", line 337, in parse
    loader.exec_module(new_module)
  File "<frozen importlib._bootstrap_external>", line 883, in exec_module
  File "<frozen importlib._bootstrap>", line 241, in _call_with_frames_removed
  File "/home/cavemhan/Documents/python/test_scripts/cyder-test/dags/base_dag.py", line 8, in <module>
    from ml_dags import ml_dag
  File "/home/cavemhan/Documents/python/test_scripts/cyder-test/dags/ml_dags.py", line 47, in <module>
    split_train_test = DataSplitter(X="{{ ti.xcom_pull(task_ids='data_processor_for_ml', key='features_df') }}", y=data_processor_for_ml.target_series)
AttributeError: 'DataProcessorForML' object has no attribute 'target_series'
[2023-04-26T00:09:52.152+0100] {processor.py:755} WARNING - No viable dags retrieved from /home/cavemhan/Documents/python/test_scripts/cyder-test/dags/base_dag.py
[2023-04-26T00:09:52.173+0100] {processor.py:175} INFO - Processing /home/cavemhan/Documents/python/test_scripts/cyder-test/dags/base_dag.py took 3.745 seconds
[2023-04-26T00:10:46.111+0100] {processor.py:153} INFO - Started process (PID=30592) to work on /home/cavemhan/Documents/python/test_scripts/cyder-test/dags/base_dag.py
[2023-04-26T00:10:46.112+0100] {processor.py:743} INFO - Processing file /home/cavemhan/Documents/python/test_scripts/cyder-test/dags/base_dag.py for tasks to queue
[2023-04-26T00:10:46.113+0100] {logging_mixin.py:137} INFO - [2023-04-26T00:10:46.113+0100] {dagbag.py:532} INFO - Filling up the DagBag from /home/cavemhan/Documents/python/test_scripts/cyder-test/dags/base_dag.py
[2023-04-26T00:10:48.636+0100] {logging_mixin.py:137} INFO - output_dir: outputs/data/
[2023-04-26T00:10:49.747+0100] {logging_mixin.py:137} INFO - [2023-04-26T00:10:49.745+0100] {dagbag.py:341} ERROR - Failed to import: /home/cavemhan/Documents/python/test_scripts/cyder-test/dags/base_dag.py
Traceback (most recent call last):
  File "/home/cavemhan/.local/share/virtualenvs/cyder-test-QPBcvLjc/lib/python3.10/site-packages/airflow/models/dagbag.py", line 337, in parse
    loader.exec_module(new_module)
  File "<frozen importlib._bootstrap_external>", line 883, in exec_module
  File "<frozen importlib._bootstrap>", line 241, in _call_with_frames_removed
  File "/home/cavemhan/Documents/python/test_scripts/cyder-test/dags/base_dag.py", line 8, in <module>
    from ml_dags import ml_dag
  File "/home/cavemhan/Documents/python/test_scripts/cyder-test/dags/ml_dags.py", line 63, in <module>
    model_tester = ModelTester(model=model_trainer.model, X_test=split_train_test.X_test, y_test=split_train_test.y_test)
AttributeError: 'DataSplitter' object has no attribute 'X_test'
[2023-04-26T00:10:49.748+0100] {processor.py:755} WARNING - No viable dags retrieved from /home/cavemhan/Documents/python/test_scripts/cyder-test/dags/base_dag.py
[2023-04-26T00:10:49.767+0100] {processor.py:175} INFO - Processing /home/cavemhan/Documents/python/test_scripts/cyder-test/dags/base_dag.py took 3.661 seconds
[2023-04-26T00:11:46.114+0100] {processor.py:153} INFO - Started process (PID=32092) to work on /home/cavemhan/Documents/python/test_scripts/cyder-test/dags/base_dag.py
[2023-04-26T00:11:46.115+0100] {processor.py:743} INFO - Processing file /home/cavemhan/Documents/python/test_scripts/cyder-test/dags/base_dag.py for tasks to queue
[2023-04-26T00:11:46.116+0100] {logging_mixin.py:137} INFO - [2023-04-26T00:11:46.116+0100] {dagbag.py:532} INFO - Filling up the DagBag from /home/cavemhan/Documents/python/test_scripts/cyder-test/dags/base_dag.py
[2023-04-26T00:11:48.373+0100] {logging_mixin.py:137} INFO - output_dir: outputs/data/
[2023-04-26T00:11:49.533+0100] {logging_mixin.py:137} INFO - [2023-04-26T00:11:49.531+0100] {dagbag.py:341} ERROR - Failed to import: /home/cavemhan/Documents/python/test_scripts/cyder-test/dags/base_dag.py
Traceback (most recent call last):
  File "/home/cavemhan/.local/share/virtualenvs/cyder-test-QPBcvLjc/lib/python3.10/site-packages/airflow/models/dagbag.py", line 337, in parse
    loader.exec_module(new_module)
  File "<frozen importlib._bootstrap_external>", line 883, in exec_module
  File "<frozen importlib._bootstrap>", line 241, in _call_with_frames_removed
  File "/home/cavemhan/Documents/python/test_scripts/cyder-test/dags/base_dag.py", line 8, in <module>
    from ml_dags import ml_dag
  File "/home/cavemhan/Documents/python/test_scripts/cyder-test/dags/ml_dags.py", line 63, in <module>
    model_tester = ModelTester(model="{{ ti.xcom_pull(task_ids='model_trainer', key='model') }}", X_test="{{ ti.xcom_pull(task_ids='split_train_test', key='X_test') }}", y_test=split_train_test.y_test)
AttributeError: 'DataSplitter' object has no attribute 'y_test'
[2023-04-26T00:11:49.534+0100] {processor.py:755} WARNING - No viable dags retrieved from /home/cavemhan/Documents/python/test_scripts/cyder-test/dags/base_dag.py
[2023-04-26T00:11:49.554+0100] {processor.py:175} INFO - Processing /home/cavemhan/Documents/python/test_scripts/cyder-test/dags/base_dag.py took 3.445 seconds
[2023-04-26T00:12:42.536+0100] {processor.py:153} INFO - Started process (PID=33396) to work on /home/cavemhan/Documents/python/test_scripts/cyder-test/dags/base_dag.py
[2023-04-26T00:12:42.537+0100] {processor.py:743} INFO - Processing file /home/cavemhan/Documents/python/test_scripts/cyder-test/dags/base_dag.py for tasks to queue
[2023-04-26T00:12:42.538+0100] {logging_mixin.py:137} INFO - [2023-04-26T00:12:42.537+0100] {dagbag.py:532} INFO - Filling up the DagBag from /home/cavemhan/Documents/python/test_scripts/cyder-test/dags/base_dag.py
[2023-04-26T00:12:44.412+0100] {logging_mixin.py:137} INFO - output_dir: outputs/data/
[2023-04-26T00:12:45.245+0100] {logging_mixin.py:137} INFO - [2023-04-26T00:12:45.242+0100] {dagbag.py:341} ERROR - Failed to import: /home/cavemhan/Documents/python/test_scripts/cyder-test/dags/base_dag.py
Traceback (most recent call last):
  File "/home/cavemhan/.local/share/virtualenvs/cyder-test-QPBcvLjc/lib/python3.10/site-packages/airflow/models/dagbag.py", line 337, in parse
    loader.exec_module(new_module)
  File "<frozen importlib._bootstrap_external>", line 883, in exec_module
  File "<frozen importlib._bootstrap>", line 241, in _call_with_frames_removed
  File "/home/cavemhan/Documents/python/test_scripts/cyder-test/dags/base_dag.py", line 38, in <module>
    ml_subdag = SubDagOperator(
  File "/home/cavemhan/.local/share/virtualenvs/cyder-test-QPBcvLjc/lib/python3.10/site-packages/airflow/models/baseoperator.py", line 394, in apply_defaults
    result = func(self, **kwargs, default_args=default_args)
  File "/home/cavemhan/.local/share/virtualenvs/cyder-test-QPBcvLjc/lib/python3.10/site-packages/airflow/utils/session.py", line 75, in wrapper
    return func(*args, session=session, **kwargs)
  File "/home/cavemhan/.local/share/virtualenvs/cyder-test-QPBcvLjc/lib/python3.10/site-packages/airflow/operators/subdag.py", line 89, in __init__
    self._validate_dag(kwargs)
  File "/home/cavemhan/.local/share/virtualenvs/cyder-test-QPBcvLjc/lib/python3.10/site-packages/airflow/operators/subdag.py", line 105, in _validate_dag
    raise AirflowException(
airflow.exceptions.AirflowException: The subdag's dag_id should have the form '{parent_dag_id}.{this_task_id}'. Expected 'base_dag.ml_subdag'; received 'ml_analysis_pipeline'.
[2023-04-26T00:12:45.245+0100] {processor.py:755} WARNING - No viable dags retrieved from /home/cavemhan/Documents/python/test_scripts/cyder-test/dags/base_dag.py
[2023-04-26T00:12:45.264+0100] {processor.py:175} INFO - Processing /home/cavemhan/Documents/python/test_scripts/cyder-test/dags/base_dag.py took 2.732 seconds
[2023-04-26T00:13:36.511+0100] {processor.py:153} INFO - Started process (PID=34624) to work on /home/cavemhan/Documents/python/test_scripts/cyder-test/dags/base_dag.py
[2023-04-26T00:13:36.513+0100] {processor.py:743} INFO - Processing file /home/cavemhan/Documents/python/test_scripts/cyder-test/dags/base_dag.py for tasks to queue
[2023-04-26T00:13:36.513+0100] {logging_mixin.py:137} INFO - [2023-04-26T00:13:36.513+0100] {dagbag.py:532} INFO - Filling up the DagBag from /home/cavemhan/Documents/python/test_scripts/cyder-test/dags/base_dag.py
[2023-04-26T00:13:38.494+0100] {logging_mixin.py:137} INFO - output_dir: outputs/data/
[2023-04-26T00:13:39.904+0100] {logging_mixin.py:137} INFO - [2023-04-26T00:13:39.901+0100] {dagbag.py:341} ERROR - Failed to import: /home/cavemhan/Documents/python/test_scripts/cyder-test/dags/base_dag.py
Traceback (most recent call last):
  File "/home/cavemhan/.local/share/virtualenvs/cyder-test-QPBcvLjc/lib/python3.10/site-packages/airflow/models/dagbag.py", line 337, in parse
    loader.exec_module(new_module)
  File "<frozen importlib._bootstrap_external>", line 883, in exec_module
  File "<frozen importlib._bootstrap>", line 241, in _call_with_frames_removed
  File "/home/cavemhan/Documents/python/test_scripts/cyder-test/dags/base_dag.py", line 38, in <module>
    ml_subdag = SubDagOperator(
  File "/home/cavemhan/.local/share/virtualenvs/cyder-test-QPBcvLjc/lib/python3.10/site-packages/airflow/models/baseoperator.py", line 394, in apply_defaults
    result = func(self, **kwargs, default_args=default_args)
  File "/home/cavemhan/.local/share/virtualenvs/cyder-test-QPBcvLjc/lib/python3.10/site-packages/airflow/utils/session.py", line 75, in wrapper
    return func(*args, session=session, **kwargs)
  File "/home/cavemhan/.local/share/virtualenvs/cyder-test-QPBcvLjc/lib/python3.10/site-packages/airflow/operators/subdag.py", line 89, in __init__
    self._validate_dag(kwargs)
  File "/home/cavemhan/.local/share/virtualenvs/cyder-test-QPBcvLjc/lib/python3.10/site-packages/airflow/operators/subdag.py", line 105, in _validate_dag
    raise AirflowException(
airflow.exceptions.AirflowException: The subdag's dag_id should have the form '{parent_dag_id}.{this_task_id}'. Expected 'base_dag.ml_subdag'; received 'ml_analysis_pipeline'.
[2023-04-26T00:13:39.905+0100] {processor.py:755} WARNING - No viable dags retrieved from /home/cavemhan/Documents/python/test_scripts/cyder-test/dags/base_dag.py
[2023-04-26T00:13:39.927+0100] {processor.py:175} INFO - Processing /home/cavemhan/Documents/python/test_scripts/cyder-test/dags/base_dag.py took 3.420 seconds
[2023-04-26T00:14:32.497+0100] {processor.py:153} INFO - Started process (PID=35970) to work on /home/cavemhan/Documents/python/test_scripts/cyder-test/dags/base_dag.py
[2023-04-26T00:14:32.498+0100] {processor.py:743} INFO - Processing file /home/cavemhan/Documents/python/test_scripts/cyder-test/dags/base_dag.py for tasks to queue
[2023-04-26T00:14:32.499+0100] {logging_mixin.py:137} INFO - [2023-04-26T00:14:32.499+0100] {dagbag.py:532} INFO - Filling up the DagBag from /home/cavemhan/Documents/python/test_scripts/cyder-test/dags/base_dag.py
[2023-04-26T00:14:34.815+0100] {logging_mixin.py:137} INFO - output_dir: outputs/data/
[2023-04-26T00:14:35.787+0100] {logging_mixin.py:137} INFO - [2023-04-26T00:14:35.786+0100] {dagbag.py:341} ERROR - Failed to import: /home/cavemhan/Documents/python/test_scripts/cyder-test/dags/base_dag.py
Traceback (most recent call last):
  File "/home/cavemhan/.local/share/virtualenvs/cyder-test-QPBcvLjc/lib/python3.10/site-packages/airflow/models/dagbag.py", line 337, in parse
    loader.exec_module(new_module)
  File "<frozen importlib._bootstrap_external>", line 883, in exec_module
  File "<frozen importlib._bootstrap>", line 241, in _call_with_frames_removed
  File "/home/cavemhan/Documents/python/test_scripts/cyder-test/dags/base_dag.py", line 8, in <module>
    from ml_dags import ml_dag
  File "/home/cavemhan/Documents/python/test_scripts/cyder-test/dags/ml_dags.py", line 60
    op_kwargs={'split_train_test_attribute': get_attribute}
              
SyntaxError: invalid syntax. Perhaps you forgot a comma?
[2023-04-26T00:14:35.788+0100] {processor.py:755} WARNING - No viable dags retrieved from /home/cavemhan/Documents/python/test_scripts/cyder-test/dags/base_dag.py
[2023-04-26T00:14:35.812+0100] {processor.py:175} INFO - Processing /home/cavemhan/Documents/python/test_scripts/cyder-test/dags/base_dag.py took 3.319 seconds
[2023-04-26T00:15:22.416+0100] {processor.py:153} INFO - Started process (PID=37171) to work on /home/cavemhan/Documents/python/test_scripts/cyder-test/dags/base_dag.py
[2023-04-26T00:15:22.417+0100] {processor.py:743} INFO - Processing file /home/cavemhan/Documents/python/test_scripts/cyder-test/dags/base_dag.py for tasks to queue
[2023-04-26T00:15:22.418+0100] {logging_mixin.py:137} INFO - [2023-04-26T00:15:22.418+0100] {dagbag.py:532} INFO - Filling up the DagBag from /home/cavemhan/Documents/python/test_scripts/cyder-test/dags/base_dag.py
[2023-04-26T00:15:24.512+0100] {logging_mixin.py:137} INFO - output_dir: outputs/data/
[2023-04-26T00:15:25.287+0100] {logging_mixin.py:137} INFO - [2023-04-26T00:15:25.286+0100] {dagbag.py:341} ERROR - Failed to import: /home/cavemhan/Documents/python/test_scripts/cyder-test/dags/base_dag.py
Traceback (most recent call last):
  File "/home/cavemhan/.local/share/virtualenvs/cyder-test-QPBcvLjc/lib/python3.10/site-packages/airflow/models/dagbag.py", line 337, in parse
    loader.exec_module(new_module)
  File "<frozen importlib._bootstrap_external>", line 883, in exec_module
  File "<frozen importlib._bootstrap>", line 241, in _call_with_frames_removed
  File "/home/cavemhan/Documents/python/test_scripts/cyder-test/dags/base_dag.py", line 8, in <module>
    from ml_dags import ml_dag
  File "/home/cavemhan/Documents/python/test_scripts/cyder-test/dags/ml_dags.py", line 60
    op_kwargs={'split_train_test_attribute': get_attribute}
              
SyntaxError: invalid syntax. Perhaps you forgot a comma?
[2023-04-26T00:15:25.287+0100] {processor.py:755} WARNING - No viable dags retrieved from /home/cavemhan/Documents/python/test_scripts/cyder-test/dags/base_dag.py
[2023-04-26T00:15:25.305+0100] {processor.py:175} INFO - Processing /home/cavemhan/Documents/python/test_scripts/cyder-test/dags/base_dag.py took 2.893 seconds
[2023-04-26T00:16:12.127+0100] {processor.py:153} INFO - Started process (PID=38315) to work on /home/cavemhan/Documents/python/test_scripts/cyder-test/dags/base_dag.py
[2023-04-26T00:16:12.128+0100] {processor.py:743} INFO - Processing file /home/cavemhan/Documents/python/test_scripts/cyder-test/dags/base_dag.py for tasks to queue
[2023-04-26T00:16:12.128+0100] {logging_mixin.py:137} INFO - [2023-04-26T00:16:12.128+0100] {dagbag.py:532} INFO - Filling up the DagBag from /home/cavemhan/Documents/python/test_scripts/cyder-test/dags/base_dag.py
[2023-04-26T00:16:15.562+0100] {logging_mixin.py:137} INFO - output_dir: outputs/data/
[2023-04-26T00:16:16.854+0100] {logging_mixin.py:137} INFO - [2023-04-26T00:16:16.851+0100] {dagbag.py:341} ERROR - Failed to import: /home/cavemhan/Documents/python/test_scripts/cyder-test/dags/base_dag.py
Traceback (most recent call last):
  File "/home/cavemhan/.local/share/virtualenvs/cyder-test-QPBcvLjc/lib/python3.10/site-packages/airflow/models/dagbag.py", line 337, in parse
    loader.exec_module(new_module)
  File "<frozen importlib._bootstrap_external>", line 883, in exec_module
  File "<frozen importlib._bootstrap>", line 241, in _call_with_frames_removed
  File "/home/cavemhan/Documents/python/test_scripts/cyder-test/dags/base_dag.py", line 8, in <module>
    from ml_dags import ml_dag
  File "/home/cavemhan/Documents/python/test_scripts/cyder-test/dags/ml_dags.py", line 60
    op_kwargs={'split_train_test_attribute': get_attribute}
              
SyntaxError: invalid syntax. Perhaps you forgot a comma?
[2023-04-26T00:16:16.854+0100] {processor.py:755} WARNING - No viable dags retrieved from /home/cavemhan/Documents/python/test_scripts/cyder-test/dags/base_dag.py
[2023-04-26T00:16:16.922+0100] {processor.py:175} INFO - Processing /home/cavemhan/Documents/python/test_scripts/cyder-test/dags/base_dag.py took 4.800 seconds
[2023-04-26T00:17:13.569+0100] {processor.py:153} INFO - Started process (PID=39715) to work on /home/cavemhan/Documents/python/test_scripts/cyder-test/dags/base_dag.py
[2023-04-26T00:17:13.571+0100] {processor.py:743} INFO - Processing file /home/cavemhan/Documents/python/test_scripts/cyder-test/dags/base_dag.py for tasks to queue
[2023-04-26T00:17:13.571+0100] {logging_mixin.py:137} INFO - [2023-04-26T00:17:13.571+0100] {dagbag.py:532} INFO - Filling up the DagBag from /home/cavemhan/Documents/python/test_scripts/cyder-test/dags/base_dag.py
[2023-04-26T00:17:17.610+0100] {logging_mixin.py:137} INFO - output_dir: outputs/data/
[2023-04-26T00:17:18.953+0100] {logging_mixin.py:137} INFO - [2023-04-26T00:17:18.927+0100] {dagbag.py:341} ERROR - Failed to import: /home/cavemhan/Documents/python/test_scripts/cyder-test/dags/base_dag.py
Traceback (most recent call last):
  File "/home/cavemhan/.local/share/virtualenvs/cyder-test-QPBcvLjc/lib/python3.10/site-packages/airflow/models/dagbag.py", line 337, in parse
    loader.exec_module(new_module)
  File "<frozen importlib._bootstrap_external>", line 883, in exec_module
  File "<frozen importlib._bootstrap>", line 241, in _call_with_frames_removed
  File "/home/cavemhan/Documents/python/test_scripts/cyder-test/dags/base_dag.py", line 38, in <module>
    ml_subdag = SubDagOperator(
  File "/home/cavemhan/.local/share/virtualenvs/cyder-test-QPBcvLjc/lib/python3.10/site-packages/airflow/models/baseoperator.py", line 394, in apply_defaults
    result = func(self, **kwargs, default_args=default_args)
  File "/home/cavemhan/.local/share/virtualenvs/cyder-test-QPBcvLjc/lib/python3.10/site-packages/airflow/utils/session.py", line 75, in wrapper
    return func(*args, session=session, **kwargs)
  File "/home/cavemhan/.local/share/virtualenvs/cyder-test-QPBcvLjc/lib/python3.10/site-packages/airflow/operators/subdag.py", line 89, in __init__
    self._validate_dag(kwargs)
  File "/home/cavemhan/.local/share/virtualenvs/cyder-test-QPBcvLjc/lib/python3.10/site-packages/airflow/operators/subdag.py", line 105, in _validate_dag
    raise AirflowException(
airflow.exceptions.AirflowException: The subdag's dag_id should have the form '{parent_dag_id}.{this_task_id}'. Expected 'base_dag.ml_subdag'; received 'ml_analysis_pipeline'.
[2023-04-26T00:17:18.963+0100] {processor.py:755} WARNING - No viable dags retrieved from /home/cavemhan/Documents/python/test_scripts/cyder-test/dags/base_dag.py
[2023-04-26T00:17:19.019+0100] {processor.py:175} INFO - Processing /home/cavemhan/Documents/python/test_scripts/cyder-test/dags/base_dag.py took 5.452 seconds
[2023-04-26T00:18:14.943+0100] {processor.py:153} INFO - Started process (PID=41112) to work on /home/cavemhan/Documents/python/test_scripts/cyder-test/dags/base_dag.py
[2023-04-26T00:18:14.944+0100] {processor.py:743} INFO - Processing file /home/cavemhan/Documents/python/test_scripts/cyder-test/dags/base_dag.py for tasks to queue
[2023-04-26T00:18:14.945+0100] {logging_mixin.py:137} INFO - [2023-04-26T00:18:14.945+0100] {dagbag.py:532} INFO - Filling up the DagBag from /home/cavemhan/Documents/python/test_scripts/cyder-test/dags/base_dag.py
[2023-04-26T00:18:18.366+0100] {logging_mixin.py:137} INFO - output_dir: outputs/data/
[2023-04-26T00:18:19.982+0100] {logging_mixin.py:137} INFO - [2023-04-26T00:18:19.975+0100] {dagbag.py:341} ERROR - Failed to import: /home/cavemhan/Documents/python/test_scripts/cyder-test/dags/base_dag.py
Traceback (most recent call last):
  File "/home/cavemhan/.local/share/virtualenvs/cyder-test-QPBcvLjc/lib/python3.10/site-packages/airflow/models/dagbag.py", line 337, in parse
    loader.exec_module(new_module)
  File "<frozen importlib._bootstrap_external>", line 883, in exec_module
  File "<frozen importlib._bootstrap>", line 241, in _call_with_frames_removed
  File "/home/cavemhan/Documents/python/test_scripts/cyder-test/dags/base_dag.py", line 38, in <module>
    ml_subdag = SubDagOperator(
  File "/home/cavemhan/.local/share/virtualenvs/cyder-test-QPBcvLjc/lib/python3.10/site-packages/airflow/models/baseoperator.py", line 394, in apply_defaults
    result = func(self, **kwargs, default_args=default_args)
  File "/home/cavemhan/.local/share/virtualenvs/cyder-test-QPBcvLjc/lib/python3.10/site-packages/airflow/utils/session.py", line 75, in wrapper
    return func(*args, session=session, **kwargs)
  File "/home/cavemhan/.local/share/virtualenvs/cyder-test-QPBcvLjc/lib/python3.10/site-packages/airflow/operators/subdag.py", line 89, in __init__
    self._validate_dag(kwargs)
  File "/home/cavemhan/.local/share/virtualenvs/cyder-test-QPBcvLjc/lib/python3.10/site-packages/airflow/operators/subdag.py", line 105, in _validate_dag
    raise AirflowException(
airflow.exceptions.AirflowException: The subdag's dag_id should have the form '{parent_dag_id}.{this_task_id}'. Expected 'base_dag.ml_subdag'; received 'ml_analysis_pipeline'.
[2023-04-26T00:18:19.984+0100] {processor.py:755} WARNING - No viable dags retrieved from /home/cavemhan/Documents/python/test_scripts/cyder-test/dags/base_dag.py
[2023-04-26T00:18:20.028+0100] {processor.py:175} INFO - Processing /home/cavemhan/Documents/python/test_scripts/cyder-test/dags/base_dag.py took 5.088 seconds
