[2023-04-25T22:39:22.512+0100] {processor.py:153} INFO - Started process (PID=403199) to work on /home/cavemhan/Documents/python/test_scripts/cyder-test/dags/ml_dags.py
[2023-04-25T22:39:22.513+0100] {processor.py:743} INFO - Processing file /home/cavemhan/Documents/python/test_scripts/cyder-test/dags/ml_dags.py for tasks to queue
[2023-04-25T22:39:22.529+0100] {logging_mixin.py:137} INFO - [2023-04-25T22:39:22.525+0100] {dagbag.py:532} INFO - Filling up the DagBag from /home/cavemhan/Documents/python/test_scripts/cyder-test/dags/ml_dags.py
[2023-04-25T22:39:27.159+0100] {logging_mixin.py:137} INFO - [2023-04-25T22:39:27.153+0100] {dagbag.py:341} ERROR - Failed to import: /home/cavemhan/Documents/python/test_scripts/cyder-test/dags/ml_dags.py
Traceback (most recent call last):
  File "/home/cavemhan/.local/share/virtualenvs/cyder-test-QPBcvLjc/lib/python3.10/site-packages/airflow/models/dagbag.py", line 337, in parse
    loader.exec_module(new_module)
  File "<frozen importlib._bootstrap_external>", line 883, in exec_module
  File "<frozen importlib._bootstrap>", line 241, in _call_with_frames_removed
  File "/home/cavemhan/Documents/python/test_scripts/cyder-test/dags/ml_dags.py", line 26, in <module>
    extract_ml_features_target_task = PythonOperator(
  File "/home/cavemhan/.local/share/virtualenvs/cyder-test-QPBcvLjc/lib/python3.10/site-packages/airflow/models/baseoperator.py", line 394, in apply_defaults
    result = func(self, **kwargs, default_args=default_args)
  File "/home/cavemhan/.local/share/virtualenvs/cyder-test-QPBcvLjc/lib/python3.10/site-packages/airflow/operators/python.py", line 160, in __init__
    super().__init__(**kwargs)
  File "/home/cavemhan/.local/share/virtualenvs/cyder-test-QPBcvLjc/lib/python3.10/site-packages/airflow/models/baseoperator.py", line 394, in apply_defaults
    result = func(self, **kwargs, default_args=default_args)
  File "/home/cavemhan/.local/share/virtualenvs/cyder-test-QPBcvLjc/lib/python3.10/site-packages/airflow/models/baseoperator.py", line 742, in __init__
    raise AirflowException(
airflow.exceptions.AirflowException: Invalid arguments were passed to PythonOperator (task_id: extract_ml_features_target). Invalid arguments were:
**kwargs: {'bash_command': 'echo "extract_ml_features_target_task is Running"'}
[2023-04-25T22:39:27.161+0100] {processor.py:755} WARNING - No viable dags retrieved from /home/cavemhan/Documents/python/test_scripts/cyder-test/dags/ml_dags.py
[2023-04-25T22:39:27.199+0100] {processor.py:175} INFO - Processing /home/cavemhan/Documents/python/test_scripts/cyder-test/dags/ml_dags.py took 4.707 seconds
[2023-04-25T22:40:30.752+0100] {processor.py:153} INFO - Started process (PID=404851) to work on /home/cavemhan/Documents/python/test_scripts/cyder-test/dags/ml_dags.py
[2023-04-25T22:40:30.753+0100] {processor.py:743} INFO - Processing file /home/cavemhan/Documents/python/test_scripts/cyder-test/dags/ml_dags.py for tasks to queue
[2023-04-25T22:40:30.756+0100] {logging_mixin.py:137} INFO - [2023-04-25T22:40:30.755+0100] {dagbag.py:532} INFO - Filling up the DagBag from /home/cavemhan/Documents/python/test_scripts/cyder-test/dags/ml_dags.py
[2023-04-25T22:40:34.762+0100] {logging_mixin.py:137} INFO - [2023-04-25T22:40:34.757+0100] {dagbag.py:341} ERROR - Failed to import: /home/cavemhan/Documents/python/test_scripts/cyder-test/dags/ml_dags.py
Traceback (most recent call last):
  File "/home/cavemhan/.local/share/virtualenvs/cyder-test-QPBcvLjc/lib/python3.10/site-packages/airflow/models/dagbag.py", line 337, in parse
    loader.exec_module(new_module)
  File "<frozen importlib._bootstrap_external>", line 883, in exec_module
  File "<frozen importlib._bootstrap>", line 241, in _call_with_frames_removed
  File "/home/cavemhan/Documents/python/test_scripts/cyder-test/dags/ml_dags.py", line 26, in <module>
    extract_ml_features_target_task = PythonOperator(
  File "/home/cavemhan/.local/share/virtualenvs/cyder-test-QPBcvLjc/lib/python3.10/site-packages/airflow/models/baseoperator.py", line 394, in apply_defaults
    result = func(self, **kwargs, default_args=default_args)
  File "/home/cavemhan/.local/share/virtualenvs/cyder-test-QPBcvLjc/lib/python3.10/site-packages/airflow/operators/python.py", line 160, in __init__
    super().__init__(**kwargs)
  File "/home/cavemhan/.local/share/virtualenvs/cyder-test-QPBcvLjc/lib/python3.10/site-packages/airflow/models/baseoperator.py", line 394, in apply_defaults
    result = func(self, **kwargs, default_args=default_args)
  File "/home/cavemhan/.local/share/virtualenvs/cyder-test-QPBcvLjc/lib/python3.10/site-packages/airflow/models/baseoperator.py", line 742, in __init__
    raise AirflowException(
airflow.exceptions.AirflowException: Invalid arguments were passed to PythonOperator (task_id: extract_ml_features_target). Invalid arguments were:
**kwargs: {'bash_command': 'echo "extract_ml_features_target_task is Running"'}
[2023-04-25T22:40:34.763+0100] {processor.py:755} WARNING - No viable dags retrieved from /home/cavemhan/Documents/python/test_scripts/cyder-test/dags/ml_dags.py
[2023-04-25T22:40:34.800+0100] {processor.py:175} INFO - Processing /home/cavemhan/Documents/python/test_scripts/cyder-test/dags/ml_dags.py took 4.054 seconds
[2023-04-25T22:41:36.653+0100] {processor.py:153} INFO - Started process (PID=406535) to work on /home/cavemhan/Documents/python/test_scripts/cyder-test/dags/ml_dags.py
[2023-04-25T22:41:36.655+0100] {processor.py:743} INFO - Processing file /home/cavemhan/Documents/python/test_scripts/cyder-test/dags/ml_dags.py for tasks to queue
[2023-04-25T22:41:36.656+0100] {logging_mixin.py:137} INFO - [2023-04-25T22:41:36.656+0100] {dagbag.py:532} INFO - Filling up the DagBag from /home/cavemhan/Documents/python/test_scripts/cyder-test/dags/ml_dags.py
[2023-04-25T22:41:39.518+0100] {logging_mixin.py:137} INFO - [2023-04-25T22:41:39.513+0100] {dagbag.py:341} ERROR - Failed to import: /home/cavemhan/Documents/python/test_scripts/cyder-test/dags/ml_dags.py
Traceback (most recent call last):
  File "/home/cavemhan/.local/share/virtualenvs/cyder-test-QPBcvLjc/lib/python3.10/site-packages/airflow/models/dagbag.py", line 337, in parse
    loader.exec_module(new_module)
  File "<frozen importlib._bootstrap_external>", line 883, in exec_module
  File "<frozen importlib._bootstrap>", line 241, in _call_with_frames_removed
  File "/home/cavemhan/Documents/python/test_scripts/cyder-test/dags/ml_dags.py", line 26, in <module>
    extract_ml_features_target_task = PythonOperator(
  File "/home/cavemhan/.local/share/virtualenvs/cyder-test-QPBcvLjc/lib/python3.10/site-packages/airflow/models/baseoperator.py", line 394, in apply_defaults
    result = func(self, **kwargs, default_args=default_args)
  File "/home/cavemhan/.local/share/virtualenvs/cyder-test-QPBcvLjc/lib/python3.10/site-packages/airflow/operators/python.py", line 160, in __init__
    super().__init__(**kwargs)
  File "/home/cavemhan/.local/share/virtualenvs/cyder-test-QPBcvLjc/lib/python3.10/site-packages/airflow/models/baseoperator.py", line 394, in apply_defaults
    result = func(self, **kwargs, default_args=default_args)
  File "/home/cavemhan/.local/share/virtualenvs/cyder-test-QPBcvLjc/lib/python3.10/site-packages/airflow/models/baseoperator.py", line 742, in __init__
    raise AirflowException(
airflow.exceptions.AirflowException: Invalid arguments were passed to PythonOperator (task_id: extract_ml_features_target). Invalid arguments were:
**kwargs: {'bash_command': 'echo "extract_ml_features_target_task is Running"'}
[2023-04-25T22:41:39.518+0100] {processor.py:755} WARNING - No viable dags retrieved from /home/cavemhan/Documents/python/test_scripts/cyder-test/dags/ml_dags.py
[2023-04-25T22:41:39.545+0100] {processor.py:175} INFO - Processing /home/cavemhan/Documents/python/test_scripts/cyder-test/dags/ml_dags.py took 2.895 seconds
[2023-04-25T22:42:46.568+0100] {processor.py:153} INFO - Started process (PID=408192) to work on /home/cavemhan/Documents/python/test_scripts/cyder-test/dags/ml_dags.py
[2023-04-25T22:42:46.570+0100] {processor.py:743} INFO - Processing file /home/cavemhan/Documents/python/test_scripts/cyder-test/dags/ml_dags.py for tasks to queue
[2023-04-25T22:42:46.571+0100] {logging_mixin.py:137} INFO - [2023-04-25T22:42:46.571+0100] {dagbag.py:532} INFO - Filling up the DagBag from /home/cavemhan/Documents/python/test_scripts/cyder-test/dags/ml_dags.py
[2023-04-25T22:42:49.483+0100] {logging_mixin.py:137} INFO - [2023-04-25T22:42:49.478+0100] {dagbag.py:341} ERROR - Failed to import: /home/cavemhan/Documents/python/test_scripts/cyder-test/dags/ml_dags.py
Traceback (most recent call last):
  File "/home/cavemhan/.local/share/virtualenvs/cyder-test-QPBcvLjc/lib/python3.10/site-packages/airflow/models/dagbag.py", line 337, in parse
    loader.exec_module(new_module)
  File "<frozen importlib._bootstrap_external>", line 883, in exec_module
  File "<frozen importlib._bootstrap>", line 241, in _call_with_frames_removed
  File "/home/cavemhan/Documents/python/test_scripts/cyder-test/dags/ml_dags.py", line 26, in <module>
    extract_ml_features_target_task = PythonOperator(
  File "/home/cavemhan/.local/share/virtualenvs/cyder-test-QPBcvLjc/lib/python3.10/site-packages/airflow/models/baseoperator.py", line 394, in apply_defaults
    result = func(self, **kwargs, default_args=default_args)
  File "/home/cavemhan/.local/share/virtualenvs/cyder-test-QPBcvLjc/lib/python3.10/site-packages/airflow/operators/python.py", line 160, in __init__
    super().__init__(**kwargs)
  File "/home/cavemhan/.local/share/virtualenvs/cyder-test-QPBcvLjc/lib/python3.10/site-packages/airflow/models/baseoperator.py", line 394, in apply_defaults
    result = func(self, **kwargs, default_args=default_args)
  File "/home/cavemhan/.local/share/virtualenvs/cyder-test-QPBcvLjc/lib/python3.10/site-packages/airflow/models/baseoperator.py", line 742, in __init__
    raise AirflowException(
airflow.exceptions.AirflowException: Invalid arguments were passed to PythonOperator (task_id: extract_ml_features_target). Invalid arguments were:
**kwargs: {'bash_command': 'echo "extract_ml_features_target_task is Running"'}
[2023-04-25T22:42:49.484+0100] {processor.py:755} WARNING - No viable dags retrieved from /home/cavemhan/Documents/python/test_scripts/cyder-test/dags/ml_dags.py
[2023-04-25T22:42:49.519+0100] {processor.py:175} INFO - Processing /home/cavemhan/Documents/python/test_scripts/cyder-test/dags/ml_dags.py took 2.956 seconds
[2023-04-25T22:43:19.563+0100] {processor.py:153} INFO - Started process (PID=409068) to work on /home/cavemhan/Documents/python/test_scripts/cyder-test/dags/ml_dags.py
[2023-04-25T22:43:19.564+0100] {processor.py:743} INFO - Processing file /home/cavemhan/Documents/python/test_scripts/cyder-test/dags/ml_dags.py for tasks to queue
[2023-04-25T22:43:19.565+0100] {logging_mixin.py:137} INFO - [2023-04-25T22:43:19.565+0100] {dagbag.py:532} INFO - Filling up the DagBag from /home/cavemhan/Documents/python/test_scripts/cyder-test/dags/ml_dags.py
[2023-04-25T22:43:20.955+0100] {logging_mixin.py:137} INFO - [2023-04-25T22:43:20.954+0100] {dagbag.py:341} ERROR - Failed to import: /home/cavemhan/Documents/python/test_scripts/cyder-test/dags/ml_dags.py
Traceback (most recent call last):
  File "/home/cavemhan/.local/share/virtualenvs/cyder-test-QPBcvLjc/lib/python3.10/site-packages/airflow/models/dagbag.py", line 337, in parse
    loader.exec_module(new_module)
  File "<frozen importlib._bootstrap_external>", line 883, in exec_module
  File "<frozen importlib._bootstrap>", line 241, in _call_with_frames_removed
  File "/home/cavemhan/Documents/python/test_scripts/cyder-test/dags/ml_dags.py", line 26, in <module>
    extract_ml_features_target_task = PythonOperator(
  File "/home/cavemhan/.local/share/virtualenvs/cyder-test-QPBcvLjc/lib/python3.10/site-packages/airflow/models/baseoperator.py", line 394, in apply_defaults
    result = func(self, **kwargs, default_args=default_args)
  File "/home/cavemhan/.local/share/virtualenvs/cyder-test-QPBcvLjc/lib/python3.10/site-packages/airflow/operators/python.py", line 160, in __init__
    super().__init__(**kwargs)
  File "/home/cavemhan/.local/share/virtualenvs/cyder-test-QPBcvLjc/lib/python3.10/site-packages/airflow/models/baseoperator.py", line 394, in apply_defaults
    result = func(self, **kwargs, default_args=default_args)
  File "/home/cavemhan/.local/share/virtualenvs/cyder-test-QPBcvLjc/lib/python3.10/site-packages/airflow/models/baseoperator.py", line 742, in __init__
    raise AirflowException(
airflow.exceptions.AirflowException: Invalid arguments were passed to PythonOperator (task_id: feature_extractor). Invalid arguments were:
**kwargs: {'bash_command': 'echo "extract_ml_features_target_task is Running"'}
[2023-04-25T22:43:20.956+0100] {processor.py:755} WARNING - No viable dags retrieved from /home/cavemhan/Documents/python/test_scripts/cyder-test/dags/ml_dags.py
[2023-04-25T22:43:20.972+0100] {processor.py:175} INFO - Processing /home/cavemhan/Documents/python/test_scripts/cyder-test/dags/ml_dags.py took 1.412 seconds
[2023-04-25T22:44:15.832+0100] {processor.py:153} INFO - Started process (PID=410655) to work on /home/cavemhan/Documents/python/test_scripts/cyder-test/dags/ml_dags.py
[2023-04-25T22:44:15.833+0100] {processor.py:743} INFO - Processing file /home/cavemhan/Documents/python/test_scripts/cyder-test/dags/ml_dags.py for tasks to queue
[2023-04-25T22:44:15.834+0100] {logging_mixin.py:137} INFO - [2023-04-25T22:44:15.834+0100] {dagbag.py:532} INFO - Filling up the DagBag from /home/cavemhan/Documents/python/test_scripts/cyder-test/dags/ml_dags.py
[2023-04-25T22:44:18.521+0100] {logging_mixin.py:137} INFO - [2023-04-25T22:44:18.517+0100] {dagbag.py:341} ERROR - Failed to import: /home/cavemhan/Documents/python/test_scripts/cyder-test/dags/ml_dags.py
Traceback (most recent call last):
  File "/home/cavemhan/.local/share/virtualenvs/cyder-test-QPBcvLjc/lib/python3.10/site-packages/airflow/models/dagbag.py", line 337, in parse
    loader.exec_module(new_module)
  File "<frozen importlib._bootstrap_external>", line 883, in exec_module
  File "<frozen importlib._bootstrap>", line 241, in _call_with_frames_removed
  File "/home/cavemhan/Documents/python/test_scripts/cyder-test/dags/ml_dags.py", line 26, in <module>
    extract_ml_features_target_task = PythonOperator(
  File "/home/cavemhan/.local/share/virtualenvs/cyder-test-QPBcvLjc/lib/python3.10/site-packages/airflow/models/baseoperator.py", line 394, in apply_defaults
    result = func(self, **kwargs, default_args=default_args)
  File "/home/cavemhan/.local/share/virtualenvs/cyder-test-QPBcvLjc/lib/python3.10/site-packages/airflow/operators/python.py", line 160, in __init__
    super().__init__(**kwargs)
  File "/home/cavemhan/.local/share/virtualenvs/cyder-test-QPBcvLjc/lib/python3.10/site-packages/airflow/models/baseoperator.py", line 394, in apply_defaults
    result = func(self, **kwargs, default_args=default_args)
  File "/home/cavemhan/.local/share/virtualenvs/cyder-test-QPBcvLjc/lib/python3.10/site-packages/airflow/models/baseoperator.py", line 742, in __init__
    raise AirflowException(
airflow.exceptions.AirflowException: Invalid arguments were passed to PythonOperator (task_id: feature_extractor). Invalid arguments were:
**kwargs: {'bash_command': 'echo "extract_ml_features_target_task is Running"'}
[2023-04-25T22:44:18.522+0100] {processor.py:755} WARNING - No viable dags retrieved from /home/cavemhan/Documents/python/test_scripts/cyder-test/dags/ml_dags.py
[2023-04-25T22:44:18.555+0100] {processor.py:175} INFO - Processing /home/cavemhan/Documents/python/test_scripts/cyder-test/dags/ml_dags.py took 2.727 seconds
[2023-04-25T22:44:49.082+0100] {processor.py:153} INFO - Started process (PID=411431) to work on /home/cavemhan/Documents/python/test_scripts/cyder-test/dags/ml_dags.py
[2023-04-25T22:44:49.083+0100] {processor.py:743} INFO - Processing file /home/cavemhan/Documents/python/test_scripts/cyder-test/dags/ml_dags.py for tasks to queue
[2023-04-25T22:44:49.083+0100] {logging_mixin.py:137} INFO - [2023-04-25T22:44:49.083+0100] {dagbag.py:532} INFO - Filling up the DagBag from /home/cavemhan/Documents/python/test_scripts/cyder-test/dags/ml_dags.py
[2023-04-25T22:44:51.811+0100] {logging_mixin.py:137} INFO - [2023-04-25T22:44:51.805+0100] {dagbag.py:341} ERROR - Failed to import: /home/cavemhan/Documents/python/test_scripts/cyder-test/dags/ml_dags.py
Traceback (most recent call last):
  File "/home/cavemhan/.local/share/virtualenvs/cyder-test-QPBcvLjc/lib/python3.10/site-packages/airflow/models/dagbag.py", line 337, in parse
    loader.exec_module(new_module)
  File "<frozen importlib._bootstrap_external>", line 883, in exec_module
  File "<frozen importlib._bootstrap>", line 241, in _call_with_frames_removed
  File "/home/cavemhan/Documents/python/test_scripts/cyder-test/dags/ml_dags.py", line 26, in <module>
    extract_ml_features_target_task = PythonOperator(
  File "/home/cavemhan/.local/share/virtualenvs/cyder-test-QPBcvLjc/lib/python3.10/site-packages/airflow/models/baseoperator.py", line 394, in apply_defaults
    result = func(self, **kwargs, default_args=default_args)
  File "/home/cavemhan/.local/share/virtualenvs/cyder-test-QPBcvLjc/lib/python3.10/site-packages/airflow/operators/python.py", line 160, in __init__
    super().__init__(**kwargs)
  File "/home/cavemhan/.local/share/virtualenvs/cyder-test-QPBcvLjc/lib/python3.10/site-packages/airflow/models/baseoperator.py", line 394, in apply_defaults
    result = func(self, **kwargs, default_args=default_args)
  File "/home/cavemhan/.local/share/virtualenvs/cyder-test-QPBcvLjc/lib/python3.10/site-packages/airflow/models/baseoperator.py", line 742, in __init__
    raise AirflowException(
airflow.exceptions.AirflowException: Invalid arguments were passed to PythonOperator (task_id: feature_extractor). Invalid arguments were:
**kwargs: {'bash_command': 'echo "extract_ml_features_target_task is Running"'}
[2023-04-25T22:44:51.811+0100] {processor.py:755} WARNING - No viable dags retrieved from /home/cavemhan/Documents/python/test_scripts/cyder-test/dags/ml_dags.py
[2023-04-25T22:44:51.845+0100] {processor.py:175} INFO - Processing /home/cavemhan/Documents/python/test_scripts/cyder-test/dags/ml_dags.py took 2.766 seconds
[2023-04-25T22:45:25.497+0100] {processor.py:153} INFO - Started process (PID=412291) to work on /home/cavemhan/Documents/python/test_scripts/cyder-test/dags/ml_dags.py
[2023-04-25T22:45:25.498+0100] {processor.py:743} INFO - Processing file /home/cavemhan/Documents/python/test_scripts/cyder-test/dags/ml_dags.py for tasks to queue
[2023-04-25T22:45:25.499+0100] {logging_mixin.py:137} INFO - [2023-04-25T22:45:25.499+0100] {dagbag.py:532} INFO - Filling up the DagBag from /home/cavemhan/Documents/python/test_scripts/cyder-test/dags/ml_dags.py
[2023-04-25T22:45:28.167+0100] {logging_mixin.py:137} INFO - [2023-04-25T22:45:28.163+0100] {dagbag.py:341} ERROR - Failed to import: /home/cavemhan/Documents/python/test_scripts/cyder-test/dags/ml_dags.py
Traceback (most recent call last):
  File "/home/cavemhan/.local/share/virtualenvs/cyder-test-QPBcvLjc/lib/python3.10/site-packages/airflow/models/dagbag.py", line 337, in parse
    loader.exec_module(new_module)
  File "<frozen importlib._bootstrap_external>", line 883, in exec_module
  File "<frozen importlib._bootstrap>", line 241, in _call_with_frames_removed
  File "/home/cavemhan/Documents/python/test_scripts/cyder-test/dags/ml_dags.py", line 26, in <module>
    extract_ml_features_target_task = PythonOperator(
  File "/home/cavemhan/.local/share/virtualenvs/cyder-test-QPBcvLjc/lib/python3.10/site-packages/airflow/models/baseoperator.py", line 394, in apply_defaults
    result = func(self, **kwargs, default_args=default_args)
  File "/home/cavemhan/.local/share/virtualenvs/cyder-test-QPBcvLjc/lib/python3.10/site-packages/airflow/operators/python.py", line 160, in __init__
    super().__init__(**kwargs)
  File "/home/cavemhan/.local/share/virtualenvs/cyder-test-QPBcvLjc/lib/python3.10/site-packages/airflow/models/baseoperator.py", line 394, in apply_defaults
    result = func(self, **kwargs, default_args=default_args)
  File "/home/cavemhan/.local/share/virtualenvs/cyder-test-QPBcvLjc/lib/python3.10/site-packages/airflow/models/baseoperator.py", line 742, in __init__
    raise AirflowException(
airflow.exceptions.AirflowException: Invalid arguments were passed to PythonOperator (task_id: feature_extractor). Invalid arguments were:
**kwargs: {'bash_command': 'echo "extract_ml_features_target_task is Running"'}
[2023-04-25T22:45:28.168+0100] {processor.py:755} WARNING - No viable dags retrieved from /home/cavemhan/Documents/python/test_scripts/cyder-test/dags/ml_dags.py
[2023-04-25T22:45:28.199+0100] {processor.py:175} INFO - Processing /home/cavemhan/Documents/python/test_scripts/cyder-test/dags/ml_dags.py took 2.705 seconds
[2023-04-25T22:45:53.236+0100] {processor.py:153} INFO - Started process (PID=413008) to work on /home/cavemhan/Documents/python/test_scripts/cyder-test/dags/ml_dags.py
[2023-04-25T22:45:53.237+0100] {processor.py:743} INFO - Processing file /home/cavemhan/Documents/python/test_scripts/cyder-test/dags/ml_dags.py for tasks to queue
[2023-04-25T22:45:53.237+0100] {logging_mixin.py:137} INFO - [2023-04-25T22:45:53.237+0100] {dagbag.py:532} INFO - Filling up the DagBag from /home/cavemhan/Documents/python/test_scripts/cyder-test/dags/ml_dags.py
[2023-04-25T22:45:56.942+0100] {logging_mixin.py:137} INFO - [2023-04-25T22:45:56.927+0100] {dagbag.py:341} ERROR - Failed to import: /home/cavemhan/Documents/python/test_scripts/cyder-test/dags/ml_dags.py
Traceback (most recent call last):
  File "/home/cavemhan/.local/share/virtualenvs/cyder-test-QPBcvLjc/lib/python3.10/site-packages/airflow/models/dagbag.py", line 337, in parse
    loader.exec_module(new_module)
  File "<frozen importlib._bootstrap_external>", line 883, in exec_module
  File "<frozen importlib._bootstrap>", line 241, in _call_with_frames_removed
  File "/home/cavemhan/Documents/python/test_scripts/cyder-test/dags/ml_dags.py", line 26, in <module>
    extract_ml_features_target_task = PythonOperator(
  File "/home/cavemhan/.local/share/virtualenvs/cyder-test-QPBcvLjc/lib/python3.10/site-packages/airflow/models/baseoperator.py", line 394, in apply_defaults
    result = func(self, **kwargs, default_args=default_args)
  File "/home/cavemhan/.local/share/virtualenvs/cyder-test-QPBcvLjc/lib/python3.10/site-packages/airflow/operators/python.py", line 160, in __init__
    super().__init__(**kwargs)
  File "/home/cavemhan/.local/share/virtualenvs/cyder-test-QPBcvLjc/lib/python3.10/site-packages/airflow/models/baseoperator.py", line 394, in apply_defaults
    result = func(self, **kwargs, default_args=default_args)
  File "/home/cavemhan/.local/share/virtualenvs/cyder-test-QPBcvLjc/lib/python3.10/site-packages/airflow/models/baseoperator.py", line 742, in __init__
    raise AirflowException(
airflow.exceptions.AirflowException: Invalid arguments were passed to PythonOperator (task_id: feature_extractor). Invalid arguments were:
**kwargs: {'bash_command': 'echo "extract_ml_features_target_task is Running"'}
[2023-04-25T22:45:56.945+0100] {processor.py:755} WARNING - No viable dags retrieved from /home/cavemhan/Documents/python/test_scripts/cyder-test/dags/ml_dags.py
[2023-04-25T22:45:57.012+0100] {processor.py:175} INFO - Processing /home/cavemhan/Documents/python/test_scripts/cyder-test/dags/ml_dags.py took 3.779 seconds
[2023-04-25T22:46:44.242+0100] {processor.py:153} INFO - Started process (PID=414489) to work on /home/cavemhan/Documents/python/test_scripts/cyder-test/dags/ml_dags.py
[2023-04-25T22:46:44.243+0100] {processor.py:743} INFO - Processing file /home/cavemhan/Documents/python/test_scripts/cyder-test/dags/ml_dags.py for tasks to queue
[2023-04-25T22:46:44.245+0100] {logging_mixin.py:137} INFO - [2023-04-25T22:46:44.244+0100] {dagbag.py:532} INFO - Filling up the DagBag from /home/cavemhan/Documents/python/test_scripts/cyder-test/dags/ml_dags.py
[2023-04-25T22:46:47.283+0100] {logging_mixin.py:137} INFO - [2023-04-25T22:46:47.273+0100] {dagbag.py:341} ERROR - Failed to import: /home/cavemhan/Documents/python/test_scripts/cyder-test/dags/ml_dags.py
Traceback (most recent call last):
  File "/home/cavemhan/.local/share/virtualenvs/cyder-test-QPBcvLjc/lib/python3.10/site-packages/airflow/models/dagbag.py", line 337, in parse
    loader.exec_module(new_module)
  File "<frozen importlib._bootstrap_external>", line 883, in exec_module
  File "<frozen importlib._bootstrap>", line 241, in _call_with_frames_removed
  File "/home/cavemhan/Documents/python/test_scripts/cyder-test/dags/ml_dags.py", line 26, in <module>
    extract_ml_features_target_task = PythonOperator(
  File "/home/cavemhan/.local/share/virtualenvs/cyder-test-QPBcvLjc/lib/python3.10/site-packages/airflow/models/baseoperator.py", line 394, in apply_defaults
    result = func(self, **kwargs, default_args=default_args)
  File "/home/cavemhan/.local/share/virtualenvs/cyder-test-QPBcvLjc/lib/python3.10/site-packages/airflow/operators/python.py", line 160, in __init__
    super().__init__(**kwargs)
  File "/home/cavemhan/.local/share/virtualenvs/cyder-test-QPBcvLjc/lib/python3.10/site-packages/airflow/models/baseoperator.py", line 394, in apply_defaults
    result = func(self, **kwargs, default_args=default_args)
  File "/home/cavemhan/.local/share/virtualenvs/cyder-test-QPBcvLjc/lib/python3.10/site-packages/airflow/models/baseoperator.py", line 742, in __init__
    raise AirflowException(
airflow.exceptions.AirflowException: Invalid arguments were passed to PythonOperator (task_id: feature_extractor). Invalid arguments were:
**kwargs: {'bash_command': 'echo "extract_ml_features_target_task is Running"'}
[2023-04-25T22:46:47.284+0100] {processor.py:755} WARNING - No viable dags retrieved from /home/cavemhan/Documents/python/test_scripts/cyder-test/dags/ml_dags.py
[2023-04-25T22:46:47.318+0100] {processor.py:175} INFO - Processing /home/cavemhan/Documents/python/test_scripts/cyder-test/dags/ml_dags.py took 3.079 seconds
[2023-04-25T22:47:47.270+0100] {processor.py:153} INFO - Started process (PID=416126) to work on /home/cavemhan/Documents/python/test_scripts/cyder-test/dags/ml_dags.py
[2023-04-25T22:47:47.271+0100] {processor.py:743} INFO - Processing file /home/cavemhan/Documents/python/test_scripts/cyder-test/dags/ml_dags.py for tasks to queue
[2023-04-25T22:47:47.272+0100] {logging_mixin.py:137} INFO - [2023-04-25T22:47:47.272+0100] {dagbag.py:532} INFO - Filling up the DagBag from /home/cavemhan/Documents/python/test_scripts/cyder-test/dags/ml_dags.py
[2023-04-25T22:47:50.265+0100] {logging_mixin.py:137} INFO - [2023-04-25T22:47:50.260+0100] {dagbag.py:341} ERROR - Failed to import: /home/cavemhan/Documents/python/test_scripts/cyder-test/dags/ml_dags.py
Traceback (most recent call last):
  File "/home/cavemhan/.local/share/virtualenvs/cyder-test-QPBcvLjc/lib/python3.10/site-packages/airflow/models/dagbag.py", line 337, in parse
    loader.exec_module(new_module)
  File "<frozen importlib._bootstrap_external>", line 883, in exec_module
  File "<frozen importlib._bootstrap>", line 241, in _call_with_frames_removed
  File "/home/cavemhan/Documents/python/test_scripts/cyder-test/dags/ml_dags.py", line 33, in <module>
    data_processor_for_ml = DataProcessorForML(X=feature_extractor.X, y=feature_extractor.y)
AttributeError: 'FeatureExtractor' object has no attribute 'X'
[2023-04-25T22:47:50.266+0100] {processor.py:755} WARNING - No viable dags retrieved from /home/cavemhan/Documents/python/test_scripts/cyder-test/dags/ml_dags.py
[2023-04-25T22:47:50.299+0100] {processor.py:175} INFO - Processing /home/cavemhan/Documents/python/test_scripts/cyder-test/dags/ml_dags.py took 3.032 seconds
[2023-04-25T22:48:20.866+0100] {processor.py:153} INFO - Started process (PID=417262) to work on /home/cavemhan/Documents/python/test_scripts/cyder-test/dags/ml_dags.py
[2023-04-25T22:48:20.869+0100] {processor.py:743} INFO - Processing file /home/cavemhan/Documents/python/test_scripts/cyder-test/dags/ml_dags.py for tasks to queue
[2023-04-25T22:48:20.874+0100] {logging_mixin.py:137} INFO - [2023-04-25T22:48:20.873+0100] {dagbag.py:532} INFO - Filling up the DagBag from /home/cavemhan/Documents/python/test_scripts/cyder-test/dags/ml_dags.py
[2023-04-25T22:48:26.162+0100] {logging_mixin.py:137} INFO - [2023-04-25T22:48:26.158+0100] {dagbag.py:341} ERROR - Failed to import: /home/cavemhan/Documents/python/test_scripts/cyder-test/dags/ml_dags.py
Traceback (most recent call last):
  File "/home/cavemhan/.local/share/virtualenvs/cyder-test-QPBcvLjc/lib/python3.10/site-packages/airflow/models/dagbag.py", line 337, in parse
    loader.exec_module(new_module)
  File "<frozen importlib._bootstrap_external>", line 883, in exec_module
  File "<frozen importlib._bootstrap>", line 241, in _call_with_frames_removed
  File "/home/cavemhan/Documents/python/test_scripts/cyder-test/dags/ml_dags.py", line 33, in <module>
    data_processor_for_ml = DataProcessorForML(X=feature_extractor.X, y=feature_extractor.y)
AttributeError: 'FeatureExtractor' object has no attribute 'X'
[2023-04-25T22:48:26.163+0100] {processor.py:755} WARNING - No viable dags retrieved from /home/cavemhan/Documents/python/test_scripts/cyder-test/dags/ml_dags.py
[2023-04-25T22:48:26.195+0100] {processor.py:175} INFO - Processing /home/cavemhan/Documents/python/test_scripts/cyder-test/dags/ml_dags.py took 5.337 seconds
[2023-04-25T22:49:24.893+0100] {processor.py:153} INFO - Started process (PID=418941) to work on /home/cavemhan/Documents/python/test_scripts/cyder-test/dags/ml_dags.py
[2023-04-25T22:49:24.894+0100] {processor.py:743} INFO - Processing file /home/cavemhan/Documents/python/test_scripts/cyder-test/dags/ml_dags.py for tasks to queue
[2023-04-25T22:49:24.895+0100] {logging_mixin.py:137} INFO - [2023-04-25T22:49:24.895+0100] {dagbag.py:532} INFO - Filling up the DagBag from /home/cavemhan/Documents/python/test_scripts/cyder-test/dags/ml_dags.py
[2023-04-25T22:49:28.159+0100] {logging_mixin.py:137} INFO - [2023-04-25T22:49:28.152+0100] {dagbag.py:341} ERROR - Failed to import: /home/cavemhan/Documents/python/test_scripts/cyder-test/dags/ml_dags.py
Traceback (most recent call last):
  File "/home/cavemhan/.local/share/virtualenvs/cyder-test-QPBcvLjc/lib/python3.10/site-packages/airflow/models/dagbag.py", line 337, in parse
    loader.exec_module(new_module)
  File "<frozen importlib._bootstrap_external>", line 883, in exec_module
  File "<frozen importlib._bootstrap>", line 241, in _call_with_frames_removed
  File "/home/cavemhan/Documents/python/test_scripts/cyder-test/dags/ml_dags.py", line 33, in <module>
    data_processor_for_ml = DataProcessorForML(X=feature_extractor.X, y=feature_extractor.y)
AttributeError: 'FeatureExtractor' object has no attribute 'X'
[2023-04-25T22:49:28.163+0100] {processor.py:755} WARNING - No viable dags retrieved from /home/cavemhan/Documents/python/test_scripts/cyder-test/dags/ml_dags.py
[2023-04-25T22:49:28.218+0100] {processor.py:175} INFO - Processing /home/cavemhan/Documents/python/test_scripts/cyder-test/dags/ml_dags.py took 3.327 seconds
[2023-04-25T22:50:42.936+0100] {processor.py:153} INFO - Started process (PID=420762) to work on /home/cavemhan/Documents/python/test_scripts/cyder-test/dags/ml_dags.py
[2023-04-25T22:50:42.946+0100] {processor.py:743} INFO - Processing file /home/cavemhan/Documents/python/test_scripts/cyder-test/dags/ml_dags.py for tasks to queue
[2023-04-25T22:50:42.947+0100] {logging_mixin.py:137} INFO - [2023-04-25T22:50:42.947+0100] {dagbag.py:532} INFO - Filling up the DagBag from /home/cavemhan/Documents/python/test_scripts/cyder-test/dags/ml_dags.py
[2023-04-25T22:50:45.359+0100] {logging_mixin.py:137} INFO - [2023-04-25T22:50:45.356+0100] {dagbag.py:341} ERROR - Failed to import: /home/cavemhan/Documents/python/test_scripts/cyder-test/dags/ml_dags.py
Traceback (most recent call last):
  File "/home/cavemhan/.local/share/virtualenvs/cyder-test-QPBcvLjc/lib/python3.10/site-packages/airflow/models/dagbag.py", line 337, in parse
    loader.exec_module(new_module)
  File "<frozen importlib._bootstrap_external>", line 883, in exec_module
  File "<frozen importlib._bootstrap>", line 241, in _call_with_frames_removed
  File "/home/cavemhan/Documents/python/test_scripts/cyder-test/dags/ml_dags.py", line 32, in <module>
    data_processor_for_ml = DataProcessorForML(X=feature_extractor.X, y=feature_extractor.y)
AttributeError: 'FeatureExtractor' object has no attribute 'X'
[2023-04-25T22:50:45.360+0100] {processor.py:755} WARNING - No viable dags retrieved from /home/cavemhan/Documents/python/test_scripts/cyder-test/dags/ml_dags.py
[2023-04-25T22:50:45.386+0100] {processor.py:175} INFO - Processing /home/cavemhan/Documents/python/test_scripts/cyder-test/dags/ml_dags.py took 2.454 seconds
[2023-04-25T22:51:18.533+0100] {processor.py:153} INFO - Started process (PID=421518) to work on /home/cavemhan/Documents/python/test_scripts/cyder-test/dags/ml_dags.py
[2023-04-25T22:51:18.534+0100] {processor.py:743} INFO - Processing file /home/cavemhan/Documents/python/test_scripts/cyder-test/dags/ml_dags.py for tasks to queue
[2023-04-25T22:51:18.535+0100] {logging_mixin.py:137} INFO - [2023-04-25T22:51:18.535+0100] {dagbag.py:532} INFO - Filling up the DagBag from /home/cavemhan/Documents/python/test_scripts/cyder-test/dags/ml_dags.py
[2023-04-25T22:51:20.978+0100] {logging_mixin.py:137} INFO - [2023-04-25T22:51:20.974+0100] {dagbag.py:341} ERROR - Failed to import: /home/cavemhan/Documents/python/test_scripts/cyder-test/dags/ml_dags.py
Traceback (most recent call last):
  File "/home/cavemhan/.local/share/virtualenvs/cyder-test-QPBcvLjc/lib/python3.10/site-packages/airflow/models/dagbag.py", line 337, in parse
    loader.exec_module(new_module)
  File "<frozen importlib._bootstrap_external>", line 883, in exec_module
  File "<frozen importlib._bootstrap>", line 241, in _call_with_frames_removed
  File "/home/cavemhan/Documents/python/test_scripts/cyder-test/dags/ml_dags.py", line 32, in <module>
    data_processor_for_ml = DataProcessorForML(X=feature_extractor.X, y=feature_extractor.y)
AttributeError: 'FeatureExtractor' object has no attribute 'X'
[2023-04-25T22:51:20.979+0100] {processor.py:755} WARNING - No viable dags retrieved from /home/cavemhan/Documents/python/test_scripts/cyder-test/dags/ml_dags.py
[2023-04-25T22:51:21.008+0100] {processor.py:175} INFO - Processing /home/cavemhan/Documents/python/test_scripts/cyder-test/dags/ml_dags.py took 2.479 seconds
[2023-04-25T22:51:48.120+0100] {processor.py:153} INFO - Started process (PID=422162) to work on /home/cavemhan/Documents/python/test_scripts/cyder-test/dags/ml_dags.py
[2023-04-25T22:51:48.122+0100] {processor.py:743} INFO - Processing file /home/cavemhan/Documents/python/test_scripts/cyder-test/dags/ml_dags.py for tasks to queue
[2023-04-25T22:51:48.123+0100] {logging_mixin.py:137} INFO - [2023-04-25T22:51:48.122+0100] {dagbag.py:532} INFO - Filling up the DagBag from /home/cavemhan/Documents/python/test_scripts/cyder-test/dags/ml_dags.py
[2023-04-25T22:51:50.514+0100] {logging_mixin.py:137} INFO - [2023-04-25T22:51:50.511+0100] {dagbag.py:341} ERROR - Failed to import: /home/cavemhan/Documents/python/test_scripts/cyder-test/dags/ml_dags.py
Traceback (most recent call last):
  File "/home/cavemhan/.local/share/virtualenvs/cyder-test-QPBcvLjc/lib/python3.10/site-packages/airflow/models/dagbag.py", line 337, in parse
    loader.exec_module(new_module)
  File "<frozen importlib._bootstrap_external>", line 883, in exec_module
  File "<frozen importlib._bootstrap>", line 241, in _call_with_frames_removed
  File "/home/cavemhan/Documents/python/test_scripts/cyder-test/dags/ml_dags.py", line 32, in <module>
    data_processor_for_ml = DataProcessorForML(X=feature_extractor.X, y=feature_extractor.y)
AttributeError: 'FeatureExtractor' object has no attribute 'X'
[2023-04-25T22:51:50.515+0100] {processor.py:755} WARNING - No viable dags retrieved from /home/cavemhan/Documents/python/test_scripts/cyder-test/dags/ml_dags.py
[2023-04-25T22:51:50.539+0100] {processor.py:175} INFO - Processing /home/cavemhan/Documents/python/test_scripts/cyder-test/dags/ml_dags.py took 2.422 seconds
[2023-04-25T22:53:34.527+0100] {processor.py:153} INFO - Started process (PID=3885) to work on /home/cavemhan/Documents/python/test_scripts/cyder-test/dags/ml_dags.py
[2023-04-25T22:53:34.528+0100] {processor.py:743} INFO - Processing file /home/cavemhan/Documents/python/test_scripts/cyder-test/dags/ml_dags.py for tasks to queue
[2023-04-25T22:53:34.529+0100] {logging_mixin.py:137} INFO - [2023-04-25T22:53:34.529+0100] {dagbag.py:532} INFO - Filling up the DagBag from /home/cavemhan/Documents/python/test_scripts/cyder-test/dags/ml_dags.py
[2023-04-25T22:53:37.093+0100] {logging_mixin.py:137} INFO - [2023-04-25T22:53:37.092+0100] {dagbag.py:341} ERROR - Failed to import: /home/cavemhan/Documents/python/test_scripts/cyder-test/dags/ml_dags.py
Traceback (most recent call last):
  File "/home/cavemhan/.local/share/virtualenvs/cyder-test-QPBcvLjc/lib/python3.10/site-packages/airflow/models/dagbag.py", line 337, in parse
    loader.exec_module(new_module)
  File "<frozen importlib._bootstrap_external>", line 883, in exec_module
  File "<frozen importlib._bootstrap>", line 241, in _call_with_frames_removed
  File "/home/cavemhan/Documents/python/test_scripts/cyder-test/dags/ml_dags.py", line 32, in <module>
    data_processor_for_ml = DataProcessorForML(X=feature_extractor.X, y=feature_extractor.y)
AttributeError: 'FeatureExtractor' object has no attribute 'X'
[2023-04-25T22:53:37.094+0100] {processor.py:755} WARNING - No viable dags retrieved from /home/cavemhan/Documents/python/test_scripts/cyder-test/dags/ml_dags.py
[2023-04-25T22:53:37.114+0100] {processor.py:175} INFO - Processing /home/cavemhan/Documents/python/test_scripts/cyder-test/dags/ml_dags.py took 2.590 seconds
[2023-04-25T22:54:33.201+0100] {processor.py:153} INFO - Started process (PID=4626) to work on /home/cavemhan/Documents/python/test_scripts/cyder-test/dags/ml_dags.py
[2023-04-25T22:54:33.204+0100] {processor.py:743} INFO - Processing file /home/cavemhan/Documents/python/test_scripts/cyder-test/dags/ml_dags.py for tasks to queue
[2023-04-25T22:54:33.205+0100] {logging_mixin.py:137} INFO - [2023-04-25T22:54:33.205+0100] {dagbag.py:532} INFO - Filling up the DagBag from /home/cavemhan/Documents/python/test_scripts/cyder-test/dags/ml_dags.py
[2023-04-25T22:54:34.768+0100] {logging_mixin.py:137} INFO - [2023-04-25T22:54:34.766+0100] {dagbag.py:341} ERROR - Failed to import: /home/cavemhan/Documents/python/test_scripts/cyder-test/dags/ml_dags.py
Traceback (most recent call last):
  File "/home/cavemhan/.local/share/virtualenvs/cyder-test-QPBcvLjc/lib/python3.10/site-packages/airflow/models/dagbag.py", line 337, in parse
    loader.exec_module(new_module)
  File "<frozen importlib._bootstrap_external>", line 883, in exec_module
  File "<frozen importlib._bootstrap>", line 241, in _call_with_frames_removed
  File "/home/cavemhan/Documents/python/test_scripts/cyder-test/dags/ml_dags.py", line 32, in <module>
    data_processor_for_ml = DataProcessorForML(X=feature_extractor.X, y=feature_extractor.y)
AttributeError: 'FeatureExtractor' object has no attribute 'X'
[2023-04-25T22:54:34.769+0100] {processor.py:755} WARNING - No viable dags retrieved from /home/cavemhan/Documents/python/test_scripts/cyder-test/dags/ml_dags.py
[2023-04-25T22:54:34.798+0100] {processor.py:175} INFO - Processing /home/cavemhan/Documents/python/test_scripts/cyder-test/dags/ml_dags.py took 1.600 seconds
[2023-04-25T22:55:03.041+0100] {processor.py:153} INFO - Started process (PID=4800) to work on /home/cavemhan/Documents/python/test_scripts/cyder-test/dags/ml_dags.py
[2023-04-25T22:55:03.047+0100] {processor.py:743} INFO - Processing file /home/cavemhan/Documents/python/test_scripts/cyder-test/dags/ml_dags.py for tasks to queue
[2023-04-25T22:55:03.048+0100] {logging_mixin.py:137} INFO - [2023-04-25T22:55:03.048+0100] {dagbag.py:532} INFO - Filling up the DagBag from /home/cavemhan/Documents/python/test_scripts/cyder-test/dags/ml_dags.py
[2023-04-25T22:55:04.677+0100] {logging_mixin.py:137} INFO - [2023-04-25T22:55:04.676+0100] {dagbag.py:341} ERROR - Failed to import: /home/cavemhan/Documents/python/test_scripts/cyder-test/dags/ml_dags.py
Traceback (most recent call last):
  File "/home/cavemhan/.local/share/virtualenvs/cyder-test-QPBcvLjc/lib/python3.10/site-packages/airflow/models/dagbag.py", line 337, in parse
    loader.exec_module(new_module)
  File "<frozen importlib._bootstrap_external>", line 883, in exec_module
  File "<frozen importlib._bootstrap>", line 241, in _call_with_frames_removed
  File "/home/cavemhan/Documents/python/test_scripts/cyder-test/dags/ml_dags.py", line 32, in <module>
    data_processor_for_ml = DataProcessorForML(X=feature_extractor.X, y=feature_extractor.y)
AttributeError: 'FeatureExtractor' object has no attribute 'X'
[2023-04-25T22:55:04.677+0100] {processor.py:755} WARNING - No viable dags retrieved from /home/cavemhan/Documents/python/test_scripts/cyder-test/dags/ml_dags.py
[2023-04-25T22:55:04.698+0100] {processor.py:175} INFO - Processing /home/cavemhan/Documents/python/test_scripts/cyder-test/dags/ml_dags.py took 1.663 seconds
[2023-04-25T22:55:35.210+0100] {processor.py:153} INFO - Started process (PID=4977) to work on /home/cavemhan/Documents/python/test_scripts/cyder-test/dags/ml_dags.py
[2023-04-25T22:55:35.214+0100] {processor.py:743} INFO - Processing file /home/cavemhan/Documents/python/test_scripts/cyder-test/dags/ml_dags.py for tasks to queue
[2023-04-25T22:55:35.214+0100] {logging_mixin.py:137} INFO - [2023-04-25T22:55:35.214+0100] {dagbag.py:532} INFO - Filling up the DagBag from /home/cavemhan/Documents/python/test_scripts/cyder-test/dags/ml_dags.py
[2023-04-25T22:55:36.643+0100] {logging_mixin.py:137} INFO - [2023-04-25T22:55:36.642+0100] {dagbag.py:341} ERROR - Failed to import: /home/cavemhan/Documents/python/test_scripts/cyder-test/dags/ml_dags.py
Traceback (most recent call last):
  File "/home/cavemhan/.local/share/virtualenvs/cyder-test-QPBcvLjc/lib/python3.10/site-packages/airflow/models/dagbag.py", line 337, in parse
    loader.exec_module(new_module)
  File "<frozen importlib._bootstrap_external>", line 883, in exec_module
  File "<frozen importlib._bootstrap>", line 241, in _call_with_frames_removed
  File "/home/cavemhan/Documents/python/test_scripts/cyder-test/dags/ml_dags.py", line 32, in <module>
    data_processor_for_ml = DataProcessorForML(X=feature_extractor.X, y=feature_extractor.y)
AttributeError: 'FeatureExtractor' object has no attribute 'X'
[2023-04-25T22:55:36.643+0100] {processor.py:755} WARNING - No viable dags retrieved from /home/cavemhan/Documents/python/test_scripts/cyder-test/dags/ml_dags.py
[2023-04-25T22:55:36.660+0100] {processor.py:175} INFO - Processing /home/cavemhan/Documents/python/test_scripts/cyder-test/dags/ml_dags.py took 1.453 seconds
[2023-04-25T22:56:04.397+0100] {processor.py:153} INFO - Started process (PID=5160) to work on /home/cavemhan/Documents/python/test_scripts/cyder-test/dags/ml_dags.py
[2023-04-25T22:56:04.401+0100] {processor.py:743} INFO - Processing file /home/cavemhan/Documents/python/test_scripts/cyder-test/dags/ml_dags.py for tasks to queue
[2023-04-25T22:56:04.402+0100] {logging_mixin.py:137} INFO - [2023-04-25T22:56:04.402+0100] {dagbag.py:532} INFO - Filling up the DagBag from /home/cavemhan/Documents/python/test_scripts/cyder-test/dags/ml_dags.py
[2023-04-25T22:56:05.650+0100] {logging_mixin.py:137} INFO - [2023-04-25T22:56:05.649+0100] {dagbag.py:341} ERROR - Failed to import: /home/cavemhan/Documents/python/test_scripts/cyder-test/dags/ml_dags.py
Traceback (most recent call last):
  File "/home/cavemhan/.local/share/virtualenvs/cyder-test-QPBcvLjc/lib/python3.10/site-packages/airflow/models/dagbag.py", line 337, in parse
    loader.exec_module(new_module)
  File "<frozen importlib._bootstrap_external>", line 883, in exec_module
  File "<frozen importlib._bootstrap>", line 241, in _call_with_frames_removed
  File "/home/cavemhan/Documents/python/test_scripts/cyder-test/dags/ml_dags.py", line 32, in <module>
    data_processor_for_ml = DataProcessorForML(X=feature_extractor.X, y=feature_extractor.y)
AttributeError: 'FeatureExtractor' object has no attribute 'X'
[2023-04-25T22:56:05.651+0100] {processor.py:755} WARNING - No viable dags retrieved from /home/cavemhan/Documents/python/test_scripts/cyder-test/dags/ml_dags.py
[2023-04-25T22:56:05.670+0100] {processor.py:175} INFO - Processing /home/cavemhan/Documents/python/test_scripts/cyder-test/dags/ml_dags.py took 1.277 seconds
[2023-04-25T22:56:36.747+0100] {processor.py:153} INFO - Started process (PID=5354) to work on /home/cavemhan/Documents/python/test_scripts/cyder-test/dags/ml_dags.py
[2023-04-25T22:56:36.750+0100] {processor.py:743} INFO - Processing file /home/cavemhan/Documents/python/test_scripts/cyder-test/dags/ml_dags.py for tasks to queue
[2023-04-25T22:56:36.751+0100] {logging_mixin.py:137} INFO - [2023-04-25T22:56:36.751+0100] {dagbag.py:532} INFO - Filling up the DagBag from /home/cavemhan/Documents/python/test_scripts/cyder-test/dags/ml_dags.py
[2023-04-25T22:56:38.140+0100] {logging_mixin.py:137} INFO - [2023-04-25T22:56:38.139+0100] {dagbag.py:341} ERROR - Failed to import: /home/cavemhan/Documents/python/test_scripts/cyder-test/dags/ml_dags.py
Traceback (most recent call last):
  File "/home/cavemhan/.local/share/virtualenvs/cyder-test-QPBcvLjc/lib/python3.10/site-packages/airflow/models/dagbag.py", line 337, in parse
    loader.exec_module(new_module)
  File "<frozen importlib._bootstrap_external>", line 883, in exec_module
  File "<frozen importlib._bootstrap>", line 241, in _call_with_frames_removed
  File "/home/cavemhan/Documents/python/test_scripts/cyder-test/dags/ml_dags.py", line 32, in <module>
    data_processor_for_ml = DataProcessorForML(X=feature_extractor.X, y=feature_extractor.y)
AttributeError: 'FeatureExtractor' object has no attribute 'X'
[2023-04-25T22:56:38.141+0100] {processor.py:755} WARNING - No viable dags retrieved from /home/cavemhan/Documents/python/test_scripts/cyder-test/dags/ml_dags.py
[2023-04-25T22:56:38.167+0100] {processor.py:175} INFO - Processing /home/cavemhan/Documents/python/test_scripts/cyder-test/dags/ml_dags.py took 1.424 seconds
[2023-04-25T22:57:05.979+0100] {processor.py:153} INFO - Started process (PID=5538) to work on /home/cavemhan/Documents/python/test_scripts/cyder-test/dags/ml_dags.py
[2023-04-25T22:57:05.983+0100] {processor.py:743} INFO - Processing file /home/cavemhan/Documents/python/test_scripts/cyder-test/dags/ml_dags.py for tasks to queue
[2023-04-25T22:57:05.983+0100] {logging_mixin.py:137} INFO - [2023-04-25T22:57:05.983+0100] {dagbag.py:532} INFO - Filling up the DagBag from /home/cavemhan/Documents/python/test_scripts/cyder-test/dags/ml_dags.py
[2023-04-25T22:57:07.615+0100] {logging_mixin.py:137} INFO - [2023-04-25T22:57:07.613+0100] {dagbag.py:341} ERROR - Failed to import: /home/cavemhan/Documents/python/test_scripts/cyder-test/dags/ml_dags.py
Traceback (most recent call last):
  File "/home/cavemhan/.local/share/virtualenvs/cyder-test-QPBcvLjc/lib/python3.10/site-packages/airflow/models/dagbag.py", line 337, in parse
    loader.exec_module(new_module)
  File "<frozen importlib._bootstrap_external>", line 883, in exec_module
  File "<frozen importlib._bootstrap>", line 241, in _call_with_frames_removed
  File "/home/cavemhan/Documents/python/test_scripts/cyder-test/dags/ml_dags.py", line 32, in <module>
    data_processor_for_ml = DataProcessorForML(X=feature_extractor.X, y=feature_extractor.y)
AttributeError: 'FeatureExtractor' object has no attribute 'X'
[2023-04-25T22:57:07.615+0100] {processor.py:755} WARNING - No viable dags retrieved from /home/cavemhan/Documents/python/test_scripts/cyder-test/dags/ml_dags.py
[2023-04-25T22:57:07.634+0100] {processor.py:175} INFO - Processing /home/cavemhan/Documents/python/test_scripts/cyder-test/dags/ml_dags.py took 1.658 seconds
[2023-04-25T22:57:37.516+0100] {processor.py:153} INFO - Started process (PID=5736) to work on /home/cavemhan/Documents/python/test_scripts/cyder-test/dags/ml_dags.py
[2023-04-25T22:57:37.516+0100] {processor.py:743} INFO - Processing file /home/cavemhan/Documents/python/test_scripts/cyder-test/dags/ml_dags.py for tasks to queue
[2023-04-25T22:57:37.517+0100] {logging_mixin.py:137} INFO - [2023-04-25T22:57:37.517+0100] {dagbag.py:532} INFO - Filling up the DagBag from /home/cavemhan/Documents/python/test_scripts/cyder-test/dags/ml_dags.py
[2023-04-25T22:57:38.890+0100] {logging_mixin.py:137} INFO - [2023-04-25T22:57:38.889+0100] {dagbag.py:341} ERROR - Failed to import: /home/cavemhan/Documents/python/test_scripts/cyder-test/dags/ml_dags.py
Traceback (most recent call last):
  File "/home/cavemhan/.local/share/virtualenvs/cyder-test-QPBcvLjc/lib/python3.10/site-packages/airflow/models/dagbag.py", line 337, in parse
    loader.exec_module(new_module)
  File "<frozen importlib._bootstrap_external>", line 883, in exec_module
  File "<frozen importlib._bootstrap>", line 241, in _call_with_frames_removed
  File "/home/cavemhan/Documents/python/test_scripts/cyder-test/dags/ml_dags.py", line 32, in <module>
    data_processor_for_ml = DataProcessorForML(data=feature_extractor.df)
AttributeError: 'FeatureExtractor' object has no attribute 'df'
[2023-04-25T22:57:38.891+0100] {processor.py:755} WARNING - No viable dags retrieved from /home/cavemhan/Documents/python/test_scripts/cyder-test/dags/ml_dags.py
[2023-04-25T22:57:38.911+0100] {processor.py:175} INFO - Processing /home/cavemhan/Documents/python/test_scripts/cyder-test/dags/ml_dags.py took 1.399 seconds
[2023-04-25T22:58:09.782+0100] {processor.py:153} INFO - Started process (PID=5909) to work on /home/cavemhan/Documents/python/test_scripts/cyder-test/dags/ml_dags.py
[2023-04-25T22:58:09.783+0100] {processor.py:743} INFO - Processing file /home/cavemhan/Documents/python/test_scripts/cyder-test/dags/ml_dags.py for tasks to queue
[2023-04-25T22:58:09.784+0100] {logging_mixin.py:137} INFO - [2023-04-25T22:58:09.784+0100] {dagbag.py:532} INFO - Filling up the DagBag from /home/cavemhan/Documents/python/test_scripts/cyder-test/dags/ml_dags.py
[2023-04-25T22:58:11.136+0100] {logging_mixin.py:137} INFO - [2023-04-25T22:58:11.135+0100] {dagbag.py:341} ERROR - Failed to import: /home/cavemhan/Documents/python/test_scripts/cyder-test/dags/ml_dags.py
Traceback (most recent call last):
  File "/home/cavemhan/.local/share/virtualenvs/cyder-test-QPBcvLjc/lib/python3.10/site-packages/airflow/models/dagbag.py", line 337, in parse
    loader.exec_module(new_module)
  File "<frozen importlib._bootstrap_external>", line 883, in exec_module
  File "<frozen importlib._bootstrap>", line 241, in _call_with_frames_removed
  File "/home/cavemhan/Documents/python/test_scripts/cyder-test/dags/ml_dags.py", line 32, in <module>
    data_processor_for_ml = DataProcessorForML(data=feature_extractor.df)
AttributeError: 'FeatureExtractor' object has no attribute 'df'
[2023-04-25T22:58:11.137+0100] {processor.py:755} WARNING - No viable dags retrieved from /home/cavemhan/Documents/python/test_scripts/cyder-test/dags/ml_dags.py
[2023-04-25T22:58:11.156+0100] {processor.py:175} INFO - Processing /home/cavemhan/Documents/python/test_scripts/cyder-test/dags/ml_dags.py took 1.378 seconds
[2023-04-25T22:58:43.434+0100] {processor.py:153} INFO - Started process (PID=6155) to work on /home/cavemhan/Documents/python/test_scripts/cyder-test/dags/ml_dags.py
[2023-04-25T22:58:43.438+0100] {processor.py:743} INFO - Processing file /home/cavemhan/Documents/python/test_scripts/cyder-test/dags/ml_dags.py for tasks to queue
[2023-04-25T22:58:43.438+0100] {logging_mixin.py:137} INFO - [2023-04-25T22:58:43.438+0100] {dagbag.py:532} INFO - Filling up the DagBag from /home/cavemhan/Documents/python/test_scripts/cyder-test/dags/ml_dags.py
[2023-04-25T22:58:44.738+0100] {logging_mixin.py:137} INFO - [2023-04-25T22:58:44.737+0100] {dagbag.py:341} ERROR - Failed to import: /home/cavemhan/Documents/python/test_scripts/cyder-test/dags/ml_dags.py
Traceback (most recent call last):
  File "/home/cavemhan/.local/share/virtualenvs/cyder-test-QPBcvLjc/lib/python3.10/site-packages/airflow/models/dagbag.py", line 337, in parse
    loader.exec_module(new_module)
  File "<frozen importlib._bootstrap_external>", line 883, in exec_module
  File "<frozen importlib._bootstrap>", line 241, in _call_with_frames_removed
  File "/home/cavemhan/Documents/python/test_scripts/cyder-test/dags/ml_dags.py", line 32, in <module>
    data_processor_for_ml = DataProcessorForML(data=feature_extractor.df)
AttributeError: 'FeatureExtractor' object has no attribute 'df'
[2023-04-25T22:58:44.739+0100] {processor.py:755} WARNING - No viable dags retrieved from /home/cavemhan/Documents/python/test_scripts/cyder-test/dags/ml_dags.py
[2023-04-25T22:58:44.758+0100] {processor.py:175} INFO - Processing /home/cavemhan/Documents/python/test_scripts/cyder-test/dags/ml_dags.py took 1.328 seconds
[2023-04-25T22:59:22.497+0100] {processor.py:153} INFO - Started process (PID=6538) to work on /home/cavemhan/Documents/python/test_scripts/cyder-test/dags/ml_dags.py
[2023-04-25T22:59:22.501+0100] {processor.py:743} INFO - Processing file /home/cavemhan/Documents/python/test_scripts/cyder-test/dags/ml_dags.py for tasks to queue
[2023-04-25T22:59:22.502+0100] {logging_mixin.py:137} INFO - [2023-04-25T22:59:22.502+0100] {dagbag.py:532} INFO - Filling up the DagBag from /home/cavemhan/Documents/python/test_scripts/cyder-test/dags/ml_dags.py
[2023-04-25T22:59:24.198+0100] {logging_mixin.py:137} INFO - [2023-04-25T22:59:24.196+0100] {dagbag.py:341} ERROR - Failed to import: /home/cavemhan/Documents/python/test_scripts/cyder-test/dags/ml_dags.py
Traceback (most recent call last):
  File "/home/cavemhan/.local/share/virtualenvs/cyder-test-QPBcvLjc/lib/python3.10/site-packages/airflow/models/dagbag.py", line 337, in parse
    loader.exec_module(new_module)
  File "<frozen importlib._bootstrap_external>", line 883, in exec_module
  File "<frozen importlib._bootstrap>", line 241, in _call_with_frames_removed
  File "/home/cavemhan/Documents/python/test_scripts/cyder-test/dags/ml_dags.py", line 32, in <module>
    data_processor_for_ml = DataProcessorForML(data=feature_extractor.df)
AttributeError: 'FeatureExtractor' object has no attribute 'df'
[2023-04-25T22:59:24.198+0100] {processor.py:755} WARNING - No viable dags retrieved from /home/cavemhan/Documents/python/test_scripts/cyder-test/dags/ml_dags.py
[2023-04-25T22:59:24.221+0100] {processor.py:175} INFO - Processing /home/cavemhan/Documents/python/test_scripts/cyder-test/dags/ml_dags.py took 1.728 seconds
[2023-04-25T23:00:19.522+0100] {processor.py:153} INFO - Started process (PID=6993) to work on /home/cavemhan/Documents/python/test_scripts/cyder-test/dags/ml_dags.py
[2023-04-25T23:00:19.525+0100] {processor.py:743} INFO - Processing file /home/cavemhan/Documents/python/test_scripts/cyder-test/dags/ml_dags.py for tasks to queue
[2023-04-25T23:00:19.526+0100] {logging_mixin.py:137} INFO - [2023-04-25T23:00:19.526+0100] {dagbag.py:532} INFO - Filling up the DagBag from /home/cavemhan/Documents/python/test_scripts/cyder-test/dags/ml_dags.py
[2023-04-25T23:00:20.792+0100] {logging_mixin.py:137} INFO - [2023-04-25T23:00:20.791+0100] {dagbag.py:341} ERROR - Failed to import: /home/cavemhan/Documents/python/test_scripts/cyder-test/dags/ml_dags.py
Traceback (most recent call last):
  File "/home/cavemhan/.local/share/virtualenvs/cyder-test-QPBcvLjc/lib/python3.10/site-packages/airflow/models/dagbag.py", line 337, in parse
    loader.exec_module(new_module)
  File "<frozen importlib._bootstrap_external>", line 883, in exec_module
  File "<frozen importlib._bootstrap>", line 241, in _call_with_frames_removed
  File "/home/cavemhan/Documents/python/test_scripts/cyder-test/dags/ml_dags.py", line 32, in <module>
    data_processor_for_ml = DataProcessorForML(data=feature_extractor.df)
AttributeError: 'FeatureExtractor' object has no attribute 'df'
[2023-04-25T23:00:20.792+0100] {processor.py:755} WARNING - No viable dags retrieved from /home/cavemhan/Documents/python/test_scripts/cyder-test/dags/ml_dags.py
[2023-04-25T23:00:20.813+0100] {processor.py:175} INFO - Processing /home/cavemhan/Documents/python/test_scripts/cyder-test/dags/ml_dags.py took 1.295 seconds
[2023-04-25T23:00:47.647+0100] {processor.py:153} INFO - Started process (PID=7166) to work on /home/cavemhan/Documents/python/test_scripts/cyder-test/dags/ml_dags.py
[2023-04-25T23:00:47.651+0100] {processor.py:743} INFO - Processing file /home/cavemhan/Documents/python/test_scripts/cyder-test/dags/ml_dags.py for tasks to queue
[2023-04-25T23:00:47.652+0100] {logging_mixin.py:137} INFO - [2023-04-25T23:00:47.652+0100] {dagbag.py:532} INFO - Filling up the DagBag from /home/cavemhan/Documents/python/test_scripts/cyder-test/dags/ml_dags.py
[2023-04-25T23:00:48.923+0100] {logging_mixin.py:137} INFO - [2023-04-25T23:00:48.922+0100] {dagbag.py:341} ERROR - Failed to import: /home/cavemhan/Documents/python/test_scripts/cyder-test/dags/ml_dags.py
Traceback (most recent call last):
  File "/home/cavemhan/.local/share/virtualenvs/cyder-test-QPBcvLjc/lib/python3.10/site-packages/airflow/models/dagbag.py", line 337, in parse
    loader.exec_module(new_module)
  File "<frozen importlib._bootstrap_external>", line 883, in exec_module
  File "<frozen importlib._bootstrap>", line 241, in _call_with_frames_removed
  File "/home/cavemhan/Documents/python/test_scripts/cyder-test/dags/ml_dags.py", line 32, in <module>
    data_processor_for_ml = DataProcessorForML(data=feature_extractor.df)
AttributeError: 'FeatureExtractor' object has no attribute 'df'
[2023-04-25T23:00:48.923+0100] {processor.py:755} WARNING - No viable dags retrieved from /home/cavemhan/Documents/python/test_scripts/cyder-test/dags/ml_dags.py
[2023-04-25T23:00:48.942+0100] {processor.py:175} INFO - Processing /home/cavemhan/Documents/python/test_scripts/cyder-test/dags/ml_dags.py took 1.298 seconds
[2023-04-25T23:01:17.205+0100] {processor.py:153} INFO - Started process (PID=7319) to work on /home/cavemhan/Documents/python/test_scripts/cyder-test/dags/ml_dags.py
[2023-04-25T23:01:17.209+0100] {processor.py:743} INFO - Processing file /home/cavemhan/Documents/python/test_scripts/cyder-test/dags/ml_dags.py for tasks to queue
[2023-04-25T23:01:17.210+0100] {logging_mixin.py:137} INFO - [2023-04-25T23:01:17.210+0100] {dagbag.py:532} INFO - Filling up the DagBag from /home/cavemhan/Documents/python/test_scripts/cyder-test/dags/ml_dags.py
[2023-04-25T23:01:18.548+0100] {logging_mixin.py:137} INFO - [2023-04-25T23:01:18.547+0100] {dagbag.py:341} ERROR - Failed to import: /home/cavemhan/Documents/python/test_scripts/cyder-test/dags/ml_dags.py
Traceback (most recent call last):
  File "/home/cavemhan/.local/share/virtualenvs/cyder-test-QPBcvLjc/lib/python3.10/site-packages/airflow/models/dagbag.py", line 337, in parse
    loader.exec_module(new_module)
  File "<frozen importlib._bootstrap_external>", line 883, in exec_module
  File "<frozen importlib._bootstrap>", line 241, in _call_with_frames_removed
  File "/home/cavemhan/Documents/python/test_scripts/cyder-test/dags/ml_dags.py", line 32, in <module>
    data_processor_for_ml = DataProcessorForML(data=feature_extractor.df)
AttributeError: 'FeatureExtractor' object has no attribute 'df'
[2023-04-25T23:01:18.548+0100] {processor.py:755} WARNING - No viable dags retrieved from /home/cavemhan/Documents/python/test_scripts/cyder-test/dags/ml_dags.py
[2023-04-25T23:01:18.569+0100] {processor.py:175} INFO - Processing /home/cavemhan/Documents/python/test_scripts/cyder-test/dags/ml_dags.py took 1.368 seconds
[2023-04-25T23:01:45.063+0100] {processor.py:153} INFO - Started process (PID=7494) to work on /home/cavemhan/Documents/python/test_scripts/cyder-test/dags/ml_dags.py
[2023-04-25T23:01:45.063+0100] {processor.py:743} INFO - Processing file /home/cavemhan/Documents/python/test_scripts/cyder-test/dags/ml_dags.py for tasks to queue
[2023-04-25T23:01:45.064+0100] {logging_mixin.py:137} INFO - [2023-04-25T23:01:45.064+0100] {dagbag.py:532} INFO - Filling up the DagBag from /home/cavemhan/Documents/python/test_scripts/cyder-test/dags/ml_dags.py
[2023-04-25T23:01:46.332+0100] {logging_mixin.py:137} INFO - [2023-04-25T23:01:46.331+0100] {dagbag.py:341} ERROR - Failed to import: /home/cavemhan/Documents/python/test_scripts/cyder-test/dags/ml_dags.py
Traceback (most recent call last):
  File "/home/cavemhan/.local/share/virtualenvs/cyder-test-QPBcvLjc/lib/python3.10/site-packages/airflow/models/dagbag.py", line 337, in parse
    loader.exec_module(new_module)
  File "<frozen importlib._bootstrap_external>", line 883, in exec_module
  File "<frozen importlib._bootstrap>", line 241, in _call_with_frames_removed
  File "/home/cavemhan/Documents/python/test_scripts/cyder-test/dags/ml_dags.py", line 32, in <module>
    data_processor_for_ml = DataProcessorForML(data=feature_extractor.df)
AttributeError: 'FeatureExtractor' object has no attribute 'df'
[2023-04-25T23:01:46.333+0100] {processor.py:755} WARNING - No viable dags retrieved from /home/cavemhan/Documents/python/test_scripts/cyder-test/dags/ml_dags.py
[2023-04-25T23:01:46.355+0100] {processor.py:175} INFO - Processing /home/cavemhan/Documents/python/test_scripts/cyder-test/dags/ml_dags.py took 1.296 seconds
[2023-04-25T23:02:13.497+0100] {processor.py:153} INFO - Started process (PID=7662) to work on /home/cavemhan/Documents/python/test_scripts/cyder-test/dags/ml_dags.py
[2023-04-25T23:02:13.501+0100] {processor.py:743} INFO - Processing file /home/cavemhan/Documents/python/test_scripts/cyder-test/dags/ml_dags.py for tasks to queue
[2023-04-25T23:02:13.501+0100] {logging_mixin.py:137} INFO - [2023-04-25T23:02:13.501+0100] {dagbag.py:532} INFO - Filling up the DagBag from /home/cavemhan/Documents/python/test_scripts/cyder-test/dags/ml_dags.py
[2023-04-25T23:02:14.757+0100] {logging_mixin.py:137} INFO - [2023-04-25T23:02:14.756+0100] {dagbag.py:341} ERROR - Failed to import: /home/cavemhan/Documents/python/test_scripts/cyder-test/dags/ml_dags.py
Traceback (most recent call last):
  File "/home/cavemhan/.local/share/virtualenvs/cyder-test-QPBcvLjc/lib/python3.10/site-packages/airflow/models/dagbag.py", line 337, in parse
    loader.exec_module(new_module)
  File "<frozen importlib._bootstrap_external>", line 883, in exec_module
  File "<frozen importlib._bootstrap>", line 241, in _call_with_frames_removed
  File "/home/cavemhan/Documents/python/test_scripts/cyder-test/dags/ml_dags.py", line 32, in <module>
    data_processor_for_ml = DataProcessorForML(data=feature_extractor.df)
AttributeError: 'FeatureExtractor' object has no attribute 'df'
[2023-04-25T23:02:14.758+0100] {processor.py:755} WARNING - No viable dags retrieved from /home/cavemhan/Documents/python/test_scripts/cyder-test/dags/ml_dags.py
[2023-04-25T23:02:14.776+0100] {processor.py:175} INFO - Processing /home/cavemhan/Documents/python/test_scripts/cyder-test/dags/ml_dags.py took 1.282 seconds
[2023-04-25T23:02:40.643+0100] {processor.py:153} INFO - Started process (PID=7811) to work on /home/cavemhan/Documents/python/test_scripts/cyder-test/dags/ml_dags.py
[2023-04-25T23:02:40.647+0100] {processor.py:743} INFO - Processing file /home/cavemhan/Documents/python/test_scripts/cyder-test/dags/ml_dags.py for tasks to queue
[2023-04-25T23:02:40.647+0100] {logging_mixin.py:137} INFO - [2023-04-25T23:02:40.647+0100] {dagbag.py:532} INFO - Filling up the DagBag from /home/cavemhan/Documents/python/test_scripts/cyder-test/dags/ml_dags.py
[2023-04-25T23:02:41.916+0100] {logging_mixin.py:137} INFO - [2023-04-25T23:02:41.915+0100] {dagbag.py:341} ERROR - Failed to import: /home/cavemhan/Documents/python/test_scripts/cyder-test/dags/ml_dags.py
Traceback (most recent call last):
  File "/home/cavemhan/.local/share/virtualenvs/cyder-test-QPBcvLjc/lib/python3.10/site-packages/airflow/models/dagbag.py", line 337, in parse
    loader.exec_module(new_module)
  File "<frozen importlib._bootstrap_external>", line 883, in exec_module
  File "<frozen importlib._bootstrap>", line 241, in _call_with_frames_removed
  File "/home/cavemhan/Documents/python/test_scripts/cyder-test/dags/ml_dags.py", line 32, in <module>
    data_processor_for_ml = DataProcessorForML(data=feature_extractor.df)
AttributeError: 'FeatureExtractor' object has no attribute 'df'
[2023-04-25T23:02:41.916+0100] {processor.py:755} WARNING - No viable dags retrieved from /home/cavemhan/Documents/python/test_scripts/cyder-test/dags/ml_dags.py
[2023-04-25T23:02:41.938+0100] {processor.py:175} INFO - Processing /home/cavemhan/Documents/python/test_scripts/cyder-test/dags/ml_dags.py took 1.298 seconds
[2023-04-25T23:03:10.131+0100] {processor.py:153} INFO - Started process (PID=7983) to work on /home/cavemhan/Documents/python/test_scripts/cyder-test/dags/ml_dags.py
[2023-04-25T23:03:10.132+0100] {processor.py:743} INFO - Processing file /home/cavemhan/Documents/python/test_scripts/cyder-test/dags/ml_dags.py for tasks to queue
[2023-04-25T23:03:10.133+0100] {logging_mixin.py:137} INFO - [2023-04-25T23:03:10.133+0100] {dagbag.py:532} INFO - Filling up the DagBag from /home/cavemhan/Documents/python/test_scripts/cyder-test/dags/ml_dags.py
[2023-04-25T23:03:11.362+0100] {logging_mixin.py:137} INFO - [2023-04-25T23:03:11.360+0100] {dagbag.py:341} ERROR - Failed to import: /home/cavemhan/Documents/python/test_scripts/cyder-test/dags/ml_dags.py
Traceback (most recent call last):
  File "/home/cavemhan/.local/share/virtualenvs/cyder-test-QPBcvLjc/lib/python3.10/site-packages/airflow/models/dagbag.py", line 337, in parse
    loader.exec_module(new_module)
  File "<frozen importlib._bootstrap_external>", line 883, in exec_module
  File "<frozen importlib._bootstrap>", line 241, in _call_with_frames_removed
  File "/home/cavemhan/Documents/python/test_scripts/cyder-test/dags/ml_dags.py", line 32, in <module>
    data_processor_for_ml = DataProcessorForML(data=feature_extractor.df)
AttributeError: 'FeatureExtractor' object has no attribute 'df'
[2023-04-25T23:03:11.362+0100] {processor.py:755} WARNING - No viable dags retrieved from /home/cavemhan/Documents/python/test_scripts/cyder-test/dags/ml_dags.py
[2023-04-25T23:03:11.384+0100] {processor.py:175} INFO - Processing /home/cavemhan/Documents/python/test_scripts/cyder-test/dags/ml_dags.py took 1.257 seconds
[2023-04-25T23:03:40.089+0100] {processor.py:153} INFO - Started process (PID=8154) to work on /home/cavemhan/Documents/python/test_scripts/cyder-test/dags/ml_dags.py
[2023-04-25T23:03:40.093+0100] {processor.py:743} INFO - Processing file /home/cavemhan/Documents/python/test_scripts/cyder-test/dags/ml_dags.py for tasks to queue
[2023-04-25T23:03:40.094+0100] {logging_mixin.py:137} INFO - [2023-04-25T23:03:40.093+0100] {dagbag.py:532} INFO - Filling up the DagBag from /home/cavemhan/Documents/python/test_scripts/cyder-test/dags/ml_dags.py
[2023-04-25T23:03:41.334+0100] {logging_mixin.py:137} INFO - [2023-04-25T23:03:41.333+0100] {dagbag.py:341} ERROR - Failed to import: /home/cavemhan/Documents/python/test_scripts/cyder-test/dags/ml_dags.py
Traceback (most recent call last):
  File "/home/cavemhan/.local/share/virtualenvs/cyder-test-QPBcvLjc/lib/python3.10/site-packages/airflow/models/dagbag.py", line 337, in parse
    loader.exec_module(new_module)
  File "<frozen importlib._bootstrap_external>", line 883, in exec_module
  File "<frozen importlib._bootstrap>", line 241, in _call_with_frames_removed
  File "/home/cavemhan/Documents/python/test_scripts/cyder-test/dags/ml_dags.py", line 32, in <module>
    data_processor_for_ml = DataProcessorForML(data=feature_extractor.df)
AttributeError: 'FeatureExtractor' object has no attribute 'df'
[2023-04-25T23:03:41.335+0100] {processor.py:755} WARNING - No viable dags retrieved from /home/cavemhan/Documents/python/test_scripts/cyder-test/dags/ml_dags.py
[2023-04-25T23:03:41.355+0100] {processor.py:175} INFO - Processing /home/cavemhan/Documents/python/test_scripts/cyder-test/dags/ml_dags.py took 1.269 seconds
[2023-04-25T23:04:08.412+0100] {processor.py:153} INFO - Started process (PID=8297) to work on /home/cavemhan/Documents/python/test_scripts/cyder-test/dags/ml_dags.py
[2023-04-25T23:04:08.415+0100] {processor.py:743} INFO - Processing file /home/cavemhan/Documents/python/test_scripts/cyder-test/dags/ml_dags.py for tasks to queue
[2023-04-25T23:04:08.416+0100] {logging_mixin.py:137} INFO - [2023-04-25T23:04:08.416+0100] {dagbag.py:532} INFO - Filling up the DagBag from /home/cavemhan/Documents/python/test_scripts/cyder-test/dags/ml_dags.py
[2023-04-25T23:04:09.665+0100] {logging_mixin.py:137} INFO - [2023-04-25T23:04:09.664+0100] {dagbag.py:341} ERROR - Failed to import: /home/cavemhan/Documents/python/test_scripts/cyder-test/dags/ml_dags.py
Traceback (most recent call last):
  File "/home/cavemhan/.local/share/virtualenvs/cyder-test-QPBcvLjc/lib/python3.10/site-packages/airflow/models/dagbag.py", line 337, in parse
    loader.exec_module(new_module)
  File "<frozen importlib._bootstrap_external>", line 883, in exec_module
  File "<frozen importlib._bootstrap>", line 241, in _call_with_frames_removed
  File "/home/cavemhan/Documents/python/test_scripts/cyder-test/dags/ml_dags.py", line 32, in <module>
    data_processor_for_ml = DataProcessorForML(data=feature_extractor.df)
AttributeError: 'FeatureExtractor' object has no attribute 'df'
[2023-04-25T23:04:09.665+0100] {processor.py:755} WARNING - No viable dags retrieved from /home/cavemhan/Documents/python/test_scripts/cyder-test/dags/ml_dags.py
[2023-04-25T23:04:09.687+0100] {processor.py:175} INFO - Processing /home/cavemhan/Documents/python/test_scripts/cyder-test/dags/ml_dags.py took 1.279 seconds
[2023-04-25T23:04:38.670+0100] {processor.py:153} INFO - Started process (PID=8507) to work on /home/cavemhan/Documents/python/test_scripts/cyder-test/dags/ml_dags.py
[2023-04-25T23:04:38.673+0100] {processor.py:743} INFO - Processing file /home/cavemhan/Documents/python/test_scripts/cyder-test/dags/ml_dags.py for tasks to queue
[2023-04-25T23:04:38.674+0100] {logging_mixin.py:137} INFO - [2023-04-25T23:04:38.674+0100] {dagbag.py:532} INFO - Filling up the DagBag from /home/cavemhan/Documents/python/test_scripts/cyder-test/dags/ml_dags.py
[2023-04-25T23:04:39.942+0100] {logging_mixin.py:137} INFO - [2023-04-25T23:04:39.942+0100] {dagbag.py:341} ERROR - Failed to import: /home/cavemhan/Documents/python/test_scripts/cyder-test/dags/ml_dags.py
Traceback (most recent call last):
  File "/home/cavemhan/.local/share/virtualenvs/cyder-test-QPBcvLjc/lib/python3.10/site-packages/airflow/models/dagbag.py", line 337, in parse
    loader.exec_module(new_module)
  File "<frozen importlib._bootstrap_external>", line 883, in exec_module
  File "<frozen importlib._bootstrap>", line 241, in _call_with_frames_removed
  File "/home/cavemhan/Documents/python/test_scripts/cyder-test/dags/ml_dags.py", line 32, in <module>
    data_processor_for_ml = DataProcessorForML(data=feature_extractor.df)
AttributeError: 'FeatureExtractor' object has no attribute 'df'
[2023-04-25T23:04:39.943+0100] {processor.py:755} WARNING - No viable dags retrieved from /home/cavemhan/Documents/python/test_scripts/cyder-test/dags/ml_dags.py
[2023-04-25T23:04:39.965+0100] {processor.py:175} INFO - Processing /home/cavemhan/Documents/python/test_scripts/cyder-test/dags/ml_dags.py took 1.299 seconds
[2023-04-25T23:05:09.706+0100] {processor.py:153} INFO - Started process (PID=8707) to work on /home/cavemhan/Documents/python/test_scripts/cyder-test/dags/ml_dags.py
[2023-04-25T23:05:09.707+0100] {processor.py:743} INFO - Processing file /home/cavemhan/Documents/python/test_scripts/cyder-test/dags/ml_dags.py for tasks to queue
[2023-04-25T23:05:09.707+0100] {logging_mixin.py:137} INFO - [2023-04-25T23:05:09.707+0100] {dagbag.py:532} INFO - Filling up the DagBag from /home/cavemhan/Documents/python/test_scripts/cyder-test/dags/ml_dags.py
[2023-04-25T23:05:10.974+0100] {logging_mixin.py:137} INFO - [2023-04-25T23:05:10.973+0100] {dagbag.py:341} ERROR - Failed to import: /home/cavemhan/Documents/python/test_scripts/cyder-test/dags/ml_dags.py
Traceback (most recent call last):
  File "/home/cavemhan/.local/share/virtualenvs/cyder-test-QPBcvLjc/lib/python3.10/site-packages/airflow/models/dagbag.py", line 337, in parse
    loader.exec_module(new_module)
  File "<frozen importlib._bootstrap_external>", line 883, in exec_module
  File "<frozen importlib._bootstrap>", line 241, in _call_with_frames_removed
  File "/home/cavemhan/Documents/python/test_scripts/cyder-test/dags/ml_dags.py", line 32, in <module>
    data_processor_for_ml = DataProcessorForML(data=feature_extractor.df)
AttributeError: 'FeatureExtractor' object has no attribute 'df'
[2023-04-25T23:05:10.974+0100] {processor.py:755} WARNING - No viable dags retrieved from /home/cavemhan/Documents/python/test_scripts/cyder-test/dags/ml_dags.py
[2023-04-25T23:05:10.993+0100] {processor.py:175} INFO - Processing /home/cavemhan/Documents/python/test_scripts/cyder-test/dags/ml_dags.py took 1.291 seconds
[2023-04-25T23:05:39.050+0100] {processor.py:153} INFO - Started process (PID=8859) to work on /home/cavemhan/Documents/python/test_scripts/cyder-test/dags/ml_dags.py
[2023-04-25T23:05:39.053+0100] {processor.py:743} INFO - Processing file /home/cavemhan/Documents/python/test_scripts/cyder-test/dags/ml_dags.py for tasks to queue
[2023-04-25T23:05:39.054+0100] {logging_mixin.py:137} INFO - [2023-04-25T23:05:39.054+0100] {dagbag.py:532} INFO - Filling up the DagBag from /home/cavemhan/Documents/python/test_scripts/cyder-test/dags/ml_dags.py
[2023-04-25T23:05:40.313+0100] {logging_mixin.py:137} INFO - [2023-04-25T23:05:40.312+0100] {dagbag.py:341} ERROR - Failed to import: /home/cavemhan/Documents/python/test_scripts/cyder-test/dags/ml_dags.py
Traceback (most recent call last):
  File "/home/cavemhan/.local/share/virtualenvs/cyder-test-QPBcvLjc/lib/python3.10/site-packages/airflow/models/dagbag.py", line 337, in parse
    loader.exec_module(new_module)
  File "<frozen importlib._bootstrap_external>", line 883, in exec_module
  File "<frozen importlib._bootstrap>", line 241, in _call_with_frames_removed
  File "/home/cavemhan/Documents/python/test_scripts/cyder-test/dags/ml_dags.py", line 32, in <module>
    data_processor_for_ml = DataProcessorForML(data=feature_extractor.df)
AttributeError: 'FeatureExtractor' object has no attribute 'df'
[2023-04-25T23:05:40.313+0100] {processor.py:755} WARNING - No viable dags retrieved from /home/cavemhan/Documents/python/test_scripts/cyder-test/dags/ml_dags.py
[2023-04-25T23:05:40.330+0100] {processor.py:175} INFO - Processing /home/cavemhan/Documents/python/test_scripts/cyder-test/dags/ml_dags.py took 1.284 seconds
[2023-04-25T23:06:11.453+0100] {processor.py:153} INFO - Started process (PID=9031) to work on /home/cavemhan/Documents/python/test_scripts/cyder-test/dags/ml_dags.py
[2023-04-25T23:06:11.454+0100] {processor.py:743} INFO - Processing file /home/cavemhan/Documents/python/test_scripts/cyder-test/dags/ml_dags.py for tasks to queue
[2023-04-25T23:06:11.455+0100] {logging_mixin.py:137} INFO - [2023-04-25T23:06:11.454+0100] {dagbag.py:532} INFO - Filling up the DagBag from /home/cavemhan/Documents/python/test_scripts/cyder-test/dags/ml_dags.py
[2023-04-25T23:06:13.052+0100] {logging_mixin.py:137} INFO - [2023-04-25T23:06:13.051+0100] {dagbag.py:341} ERROR - Failed to import: /home/cavemhan/Documents/python/test_scripts/cyder-test/dags/ml_dags.py
Traceback (most recent call last):
  File "/home/cavemhan/.local/share/virtualenvs/cyder-test-QPBcvLjc/lib/python3.10/site-packages/airflow/models/dagbag.py", line 337, in parse
    loader.exec_module(new_module)
  File "<frozen importlib._bootstrap_external>", line 883, in exec_module
  File "<frozen importlib._bootstrap>", line 241, in _call_with_frames_removed
  File "/home/cavemhan/Documents/python/test_scripts/cyder-test/dags/ml_dags.py", line 32, in <module>
    data_processor_for_ml = DataProcessorForML(data=feature_extractor.df)
AttributeError: 'FeatureExtractor' object has no attribute 'df'
[2023-04-25T23:06:13.052+0100] {processor.py:755} WARNING - No viable dags retrieved from /home/cavemhan/Documents/python/test_scripts/cyder-test/dags/ml_dags.py
[2023-04-25T23:06:13.073+0100] {processor.py:175} INFO - Processing /home/cavemhan/Documents/python/test_scripts/cyder-test/dags/ml_dags.py took 1.623 seconds
[2023-04-25T23:10:16.833+0100] {processor.py:153} INFO - Started process (PID=10194) to work on /home/cavemhan/Documents/python/test_scripts/cyder-test/dags/ml_dags.py
[2023-04-25T23:10:16.837+0100] {processor.py:743} INFO - Processing file /home/cavemhan/Documents/python/test_scripts/cyder-test/dags/ml_dags.py for tasks to queue
[2023-04-25T23:10:16.837+0100] {logging_mixin.py:137} INFO - [2023-04-25T23:10:16.837+0100] {dagbag.py:532} INFO - Filling up the DagBag from /home/cavemhan/Documents/python/test_scripts/cyder-test/dags/ml_dags.py
[2023-04-25T23:10:18.894+0100] {logging_mixin.py:137} INFO - [2023-04-25T23:10:18.892+0100] {dagbag.py:341} ERROR - Failed to import: /home/cavemhan/Documents/python/test_scripts/cyder-test/dags/ml_dags.py
Traceback (most recent call last):
  File "/home/cavemhan/.local/share/virtualenvs/cyder-test-QPBcvLjc/lib/python3.10/site-packages/airflow/models/dagbag.py", line 337, in parse
    loader.exec_module(new_module)
  File "<frozen importlib._bootstrap_external>", line 883, in exec_module
  File "<frozen importlib._bootstrap>", line 241, in _call_with_frames_removed
  File "/home/cavemhan/Documents/python/test_scripts/cyder-test/dags/ml_dags.py", line 32, in <module>
    data_processor_for_ml = DataProcessorForML(data=feature_extractor.df)
AttributeError: 'FeatureExtractor' object has no attribute 'df'
[2023-04-25T23:10:18.895+0100] {processor.py:755} WARNING - No viable dags retrieved from /home/cavemhan/Documents/python/test_scripts/cyder-test/dags/ml_dags.py
[2023-04-25T23:10:18.920+0100] {processor.py:175} INFO - Processing /home/cavemhan/Documents/python/test_scripts/cyder-test/dags/ml_dags.py took 2.090 seconds
[2023-04-25T23:11:16.756+0100] {processor.py:153} INFO - Started process (PID=10690) to work on /home/cavemhan/Documents/python/test_scripts/cyder-test/dags/ml_dags.py
[2023-04-25T23:11:16.757+0100] {processor.py:743} INFO - Processing file /home/cavemhan/Documents/python/test_scripts/cyder-test/dags/ml_dags.py for tasks to queue
[2023-04-25T23:11:16.757+0100] {logging_mixin.py:137} INFO - [2023-04-25T23:11:16.757+0100] {dagbag.py:532} INFO - Filling up the DagBag from /home/cavemhan/Documents/python/test_scripts/cyder-test/dags/ml_dags.py
[2023-04-25T23:11:18.056+0100] {logging_mixin.py:137} INFO - [2023-04-25T23:11:18.055+0100] {dagbag.py:341} ERROR - Failed to import: /home/cavemhan/Documents/python/test_scripts/cyder-test/dags/ml_dags.py
Traceback (most recent call last):
  File "/home/cavemhan/.local/share/virtualenvs/cyder-test-QPBcvLjc/lib/python3.10/site-packages/airflow/models/dagbag.py", line 337, in parse
    loader.exec_module(new_module)
  File "<frozen importlib._bootstrap_external>", line 883, in exec_module
  File "<frozen importlib._bootstrap>", line 241, in _call_with_frames_removed
  File "/home/cavemhan/Documents/python/test_scripts/cyder-test/dags/ml_dags.py", line 32, in <module>
    data_processor_for_ml = DataProcessorForML(data=feature_extractor.df)
AttributeError: 'FeatureExtractor' object has no attribute 'df'
[2023-04-25T23:11:18.057+0100] {processor.py:755} WARNING - No viable dags retrieved from /home/cavemhan/Documents/python/test_scripts/cyder-test/dags/ml_dags.py
[2023-04-25T23:11:18.075+0100] {processor.py:175} INFO - Processing /home/cavemhan/Documents/python/test_scripts/cyder-test/dags/ml_dags.py took 1.321 seconds
[2023-04-25T23:11:44.838+0100] {processor.py:153} INFO - Started process (PID=10856) to work on /home/cavemhan/Documents/python/test_scripts/cyder-test/dags/ml_dags.py
[2023-04-25T23:11:44.842+0100] {processor.py:743} INFO - Processing file /home/cavemhan/Documents/python/test_scripts/cyder-test/dags/ml_dags.py for tasks to queue
[2023-04-25T23:11:44.843+0100] {logging_mixin.py:137} INFO - [2023-04-25T23:11:44.843+0100] {dagbag.py:532} INFO - Filling up the DagBag from /home/cavemhan/Documents/python/test_scripts/cyder-test/dags/ml_dags.py
[2023-04-25T23:11:46.092+0100] {logging_mixin.py:137} INFO - [2023-04-25T23:11:46.091+0100] {dagbag.py:341} ERROR - Failed to import: /home/cavemhan/Documents/python/test_scripts/cyder-test/dags/ml_dags.py
Traceback (most recent call last):
  File "/home/cavemhan/.local/share/virtualenvs/cyder-test-QPBcvLjc/lib/python3.10/site-packages/airflow/models/dagbag.py", line 337, in parse
    loader.exec_module(new_module)
  File "<frozen importlib._bootstrap_external>", line 883, in exec_module
  File "<frozen importlib._bootstrap>", line 241, in _call_with_frames_removed
  File "/home/cavemhan/Documents/python/test_scripts/cyder-test/dags/ml_dags.py", line 32, in <module>
    data_processor_for_ml = DataProcessorForML(data=feature_extractor.df)
AttributeError: 'FeatureExtractor' object has no attribute 'df'
[2023-04-25T23:11:46.092+0100] {processor.py:755} WARNING - No viable dags retrieved from /home/cavemhan/Documents/python/test_scripts/cyder-test/dags/ml_dags.py
[2023-04-25T23:11:46.109+0100] {processor.py:175} INFO - Processing /home/cavemhan/Documents/python/test_scripts/cyder-test/dags/ml_dags.py took 1.276 seconds
[2023-04-25T23:12:15.781+0100] {processor.py:153} INFO - Started process (PID=11027) to work on /home/cavemhan/Documents/python/test_scripts/cyder-test/dags/ml_dags.py
[2023-04-25T23:12:15.782+0100] {processor.py:743} INFO - Processing file /home/cavemhan/Documents/python/test_scripts/cyder-test/dags/ml_dags.py for tasks to queue
[2023-04-25T23:12:15.783+0100] {logging_mixin.py:137} INFO - [2023-04-25T23:12:15.783+0100] {dagbag.py:532} INFO - Filling up the DagBag from /home/cavemhan/Documents/python/test_scripts/cyder-test/dags/ml_dags.py
[2023-04-25T23:12:17.067+0100] {logging_mixin.py:137} INFO - [2023-04-25T23:12:17.067+0100] {dagbag.py:341} ERROR - Failed to import: /home/cavemhan/Documents/python/test_scripts/cyder-test/dags/ml_dags.py
Traceback (most recent call last):
  File "/home/cavemhan/.local/share/virtualenvs/cyder-test-QPBcvLjc/lib/python3.10/site-packages/airflow/models/dagbag.py", line 337, in parse
    loader.exec_module(new_module)
  File "<frozen importlib._bootstrap_external>", line 883, in exec_module
  File "<frozen importlib._bootstrap>", line 241, in _call_with_frames_removed
  File "/home/cavemhan/Documents/python/test_scripts/cyder-test/dags/ml_dags.py", line 32, in <module>
    data_processor_for_ml = DataProcessorForML(data=feature_extractor.df)
AttributeError: 'FeatureExtractor' object has no attribute 'df'
[2023-04-25T23:12:17.068+0100] {processor.py:755} WARNING - No viable dags retrieved from /home/cavemhan/Documents/python/test_scripts/cyder-test/dags/ml_dags.py
[2023-04-25T23:12:17.090+0100] {processor.py:175} INFO - Processing /home/cavemhan/Documents/python/test_scripts/cyder-test/dags/ml_dags.py took 1.311 seconds
[2023-04-25T23:12:43.845+0100] {processor.py:153} INFO - Started process (PID=11179) to work on /home/cavemhan/Documents/python/test_scripts/cyder-test/dags/ml_dags.py
[2023-04-25T23:12:43.846+0100] {processor.py:743} INFO - Processing file /home/cavemhan/Documents/python/test_scripts/cyder-test/dags/ml_dags.py for tasks to queue
[2023-04-25T23:12:43.847+0100] {logging_mixin.py:137} INFO - [2023-04-25T23:12:43.847+0100] {dagbag.py:532} INFO - Filling up the DagBag from /home/cavemhan/Documents/python/test_scripts/cyder-test/dags/ml_dags.py
[2023-04-25T23:12:45.124+0100] {logging_mixin.py:137} INFO - [2023-04-25T23:12:45.123+0100] {dagbag.py:341} ERROR - Failed to import: /home/cavemhan/Documents/python/test_scripts/cyder-test/dags/ml_dags.py
Traceback (most recent call last):
  File "/home/cavemhan/.local/share/virtualenvs/cyder-test-QPBcvLjc/lib/python3.10/site-packages/airflow/models/dagbag.py", line 337, in parse
    loader.exec_module(new_module)
  File "<frozen importlib._bootstrap_external>", line 883, in exec_module
  File "<frozen importlib._bootstrap>", line 241, in _call_with_frames_removed
  File "/home/cavemhan/Documents/python/test_scripts/cyder-test/dags/ml_dags.py", line 32, in <module>
    data_processor_for_ml = DataProcessorForML(data=feature_extractor.df)
AttributeError: 'FeatureExtractor' object has no attribute 'df'
[2023-04-25T23:12:45.125+0100] {processor.py:755} WARNING - No viable dags retrieved from /home/cavemhan/Documents/python/test_scripts/cyder-test/dags/ml_dags.py
[2023-04-25T23:12:45.146+0100] {processor.py:175} INFO - Processing /home/cavemhan/Documents/python/test_scripts/cyder-test/dags/ml_dags.py took 1.305 seconds
[2023-04-25T23:13:13.585+0100] {processor.py:153} INFO - Started process (PID=11358) to work on /home/cavemhan/Documents/python/test_scripts/cyder-test/dags/ml_dags.py
[2023-04-25T23:13:13.588+0100] {processor.py:743} INFO - Processing file /home/cavemhan/Documents/python/test_scripts/cyder-test/dags/ml_dags.py for tasks to queue
[2023-04-25T23:13:13.589+0100] {logging_mixin.py:137} INFO - [2023-04-25T23:13:13.589+0100] {dagbag.py:532} INFO - Filling up the DagBag from /home/cavemhan/Documents/python/test_scripts/cyder-test/dags/ml_dags.py
[2023-04-25T23:13:14.832+0100] {logging_mixin.py:137} INFO - [2023-04-25T23:13:14.832+0100] {dagbag.py:341} ERROR - Failed to import: /home/cavemhan/Documents/python/test_scripts/cyder-test/dags/ml_dags.py
Traceback (most recent call last):
  File "/home/cavemhan/.local/share/virtualenvs/cyder-test-QPBcvLjc/lib/python3.10/site-packages/airflow/models/dagbag.py", line 337, in parse
    loader.exec_module(new_module)
  File "<frozen importlib._bootstrap_external>", line 883, in exec_module
  File "<frozen importlib._bootstrap>", line 241, in _call_with_frames_removed
  File "/home/cavemhan/Documents/python/test_scripts/cyder-test/dags/ml_dags.py", line 32, in <module>
    data_processor_for_ml = DataProcessorForML(data=feature_extractor.df)
AttributeError: 'FeatureExtractor' object has no attribute 'df'
[2023-04-25T23:13:14.833+0100] {processor.py:755} WARNING - No viable dags retrieved from /home/cavemhan/Documents/python/test_scripts/cyder-test/dags/ml_dags.py
[2023-04-25T23:13:14.854+0100] {processor.py:175} INFO - Processing /home/cavemhan/Documents/python/test_scripts/cyder-test/dags/ml_dags.py took 1.273 seconds
[2023-04-25T23:13:42.902+0100] {processor.py:153} INFO - Started process (PID=11508) to work on /home/cavemhan/Documents/python/test_scripts/cyder-test/dags/ml_dags.py
[2023-04-25T23:13:42.905+0100] {processor.py:743} INFO - Processing file /home/cavemhan/Documents/python/test_scripts/cyder-test/dags/ml_dags.py for tasks to queue
[2023-04-25T23:13:42.906+0100] {logging_mixin.py:137} INFO - [2023-04-25T23:13:42.906+0100] {dagbag.py:532} INFO - Filling up the DagBag from /home/cavemhan/Documents/python/test_scripts/cyder-test/dags/ml_dags.py
[2023-04-25T23:13:44.206+0100] {logging_mixin.py:137} INFO - [2023-04-25T23:13:44.205+0100] {dagbag.py:341} ERROR - Failed to import: /home/cavemhan/Documents/python/test_scripts/cyder-test/dags/ml_dags.py
Traceback (most recent call last):
  File "/home/cavemhan/.local/share/virtualenvs/cyder-test-QPBcvLjc/lib/python3.10/site-packages/airflow/models/dagbag.py", line 337, in parse
    loader.exec_module(new_module)
  File "<frozen importlib._bootstrap_external>", line 883, in exec_module
  File "<frozen importlib._bootstrap>", line 241, in _call_with_frames_removed
  File "/home/cavemhan/Documents/python/test_scripts/cyder-test/dags/ml_dags.py", line 32, in <module>
    data_processor_for_ml = DataProcessorForML(data=feature_extractor.df)
AttributeError: 'FeatureExtractor' object has no attribute 'df'
[2023-04-25T23:13:44.206+0100] {processor.py:755} WARNING - No viable dags retrieved from /home/cavemhan/Documents/python/test_scripts/cyder-test/dags/ml_dags.py
[2023-04-25T23:13:44.223+0100] {processor.py:175} INFO - Processing /home/cavemhan/Documents/python/test_scripts/cyder-test/dags/ml_dags.py took 1.325 seconds
[2023-04-25T23:14:13.940+0100] {processor.py:153} INFO - Started process (PID=11702) to work on /home/cavemhan/Documents/python/test_scripts/cyder-test/dags/ml_dags.py
[2023-04-25T23:14:13.941+0100] {processor.py:743} INFO - Processing file /home/cavemhan/Documents/python/test_scripts/cyder-test/dags/ml_dags.py for tasks to queue
[2023-04-25T23:14:13.942+0100] {logging_mixin.py:137} INFO - [2023-04-25T23:14:13.942+0100] {dagbag.py:532} INFO - Filling up the DagBag from /home/cavemhan/Documents/python/test_scripts/cyder-test/dags/ml_dags.py
[2023-04-25T23:14:15.216+0100] {logging_mixin.py:137} INFO - [2023-04-25T23:14:15.215+0100] {dagbag.py:341} ERROR - Failed to import: /home/cavemhan/Documents/python/test_scripts/cyder-test/dags/ml_dags.py
Traceback (most recent call last):
  File "/home/cavemhan/.local/share/virtualenvs/cyder-test-QPBcvLjc/lib/python3.10/site-packages/airflow/models/dagbag.py", line 337, in parse
    loader.exec_module(new_module)
  File "<frozen importlib._bootstrap_external>", line 883, in exec_module
  File "<frozen importlib._bootstrap>", line 241, in _call_with_frames_removed
  File "/home/cavemhan/Documents/python/test_scripts/cyder-test/dags/ml_dags.py", line 32, in <module>
    data_processor_for_ml = DataProcessorForML(data=feature_extractor.df)
AttributeError: 'FeatureExtractor' object has no attribute 'df'
[2023-04-25T23:14:15.217+0100] {processor.py:755} WARNING - No viable dags retrieved from /home/cavemhan/Documents/python/test_scripts/cyder-test/dags/ml_dags.py
[2023-04-25T23:14:15.239+0100] {processor.py:175} INFO - Processing /home/cavemhan/Documents/python/test_scripts/cyder-test/dags/ml_dags.py took 1.304 seconds
[2023-04-25T23:14:43.255+0100] {processor.py:153} INFO - Started process (PID=11867) to work on /home/cavemhan/Documents/python/test_scripts/cyder-test/dags/ml_dags.py
[2023-04-25T23:14:43.258+0100] {processor.py:743} INFO - Processing file /home/cavemhan/Documents/python/test_scripts/cyder-test/dags/ml_dags.py for tasks to queue
[2023-04-25T23:14:43.259+0100] {logging_mixin.py:137} INFO - [2023-04-25T23:14:43.259+0100] {dagbag.py:532} INFO - Filling up the DagBag from /home/cavemhan/Documents/python/test_scripts/cyder-test/dags/ml_dags.py
[2023-04-25T23:14:44.549+0100] {logging_mixin.py:137} INFO - [2023-04-25T23:14:44.548+0100] {dagbag.py:341} ERROR - Failed to import: /home/cavemhan/Documents/python/test_scripts/cyder-test/dags/ml_dags.py
Traceback (most recent call last):
  File "/home/cavemhan/.local/share/virtualenvs/cyder-test-QPBcvLjc/lib/python3.10/site-packages/airflow/models/dagbag.py", line 337, in parse
    loader.exec_module(new_module)
  File "<frozen importlib._bootstrap_external>", line 883, in exec_module
  File "<frozen importlib._bootstrap>", line 241, in _call_with_frames_removed
  File "/home/cavemhan/Documents/python/test_scripts/cyder-test/dags/ml_dags.py", line 32, in <module>
    data_processor_for_ml = DataProcessorForML(data=feature_extractor.df)
AttributeError: 'FeatureExtractor' object has no attribute 'df'
[2023-04-25T23:14:44.550+0100] {processor.py:755} WARNING - No viable dags retrieved from /home/cavemhan/Documents/python/test_scripts/cyder-test/dags/ml_dags.py
[2023-04-25T23:14:44.568+0100] {processor.py:175} INFO - Processing /home/cavemhan/Documents/python/test_scripts/cyder-test/dags/ml_dags.py took 1.317 seconds
[2023-04-25T23:15:14.601+0100] {processor.py:153} INFO - Started process (PID=12047) to work on /home/cavemhan/Documents/python/test_scripts/cyder-test/dags/ml_dags.py
[2023-04-25T23:15:14.602+0100] {processor.py:743} INFO - Processing file /home/cavemhan/Documents/python/test_scripts/cyder-test/dags/ml_dags.py for tasks to queue
[2023-04-25T23:15:14.603+0100] {logging_mixin.py:137} INFO - [2023-04-25T23:15:14.603+0100] {dagbag.py:532} INFO - Filling up the DagBag from /home/cavemhan/Documents/python/test_scripts/cyder-test/dags/ml_dags.py
[2023-04-25T23:15:15.870+0100] {logging_mixin.py:137} INFO - [2023-04-25T23:15:15.869+0100] {dagbag.py:341} ERROR - Failed to import: /home/cavemhan/Documents/python/test_scripts/cyder-test/dags/ml_dags.py
Traceback (most recent call last):
  File "/home/cavemhan/.local/share/virtualenvs/cyder-test-QPBcvLjc/lib/python3.10/site-packages/airflow/models/dagbag.py", line 337, in parse
    loader.exec_module(new_module)
  File "<frozen importlib._bootstrap_external>", line 883, in exec_module
  File "<frozen importlib._bootstrap>", line 241, in _call_with_frames_removed
  File "/home/cavemhan/Documents/python/test_scripts/cyder-test/dags/ml_dags.py", line 32, in <module>
    data_processor_for_ml = DataProcessorForML(data=feature_extractor.df)
AttributeError: 'FeatureExtractor' object has no attribute 'df'
[2023-04-25T23:15:15.870+0100] {processor.py:755} WARNING - No viable dags retrieved from /home/cavemhan/Documents/python/test_scripts/cyder-test/dags/ml_dags.py
[2023-04-25T23:15:15.886+0100] {processor.py:175} INFO - Processing /home/cavemhan/Documents/python/test_scripts/cyder-test/dags/ml_dags.py took 1.288 seconds
[2023-04-25T23:15:43.320+0100] {processor.py:153} INFO - Started process (PID=12228) to work on /home/cavemhan/Documents/python/test_scripts/cyder-test/dags/ml_dags.py
[2023-04-25T23:15:43.323+0100] {processor.py:743} INFO - Processing file /home/cavemhan/Documents/python/test_scripts/cyder-test/dags/ml_dags.py for tasks to queue
[2023-04-25T23:15:43.324+0100] {logging_mixin.py:137} INFO - [2023-04-25T23:15:43.324+0100] {dagbag.py:532} INFO - Filling up the DagBag from /home/cavemhan/Documents/python/test_scripts/cyder-test/dags/ml_dags.py
[2023-04-25T23:15:44.551+0100] {logging_mixin.py:137} INFO - [2023-04-25T23:15:44.550+0100] {dagbag.py:341} ERROR - Failed to import: /home/cavemhan/Documents/python/test_scripts/cyder-test/dags/ml_dags.py
Traceback (most recent call last):
  File "/home/cavemhan/.local/share/virtualenvs/cyder-test-QPBcvLjc/lib/python3.10/site-packages/airflow/models/dagbag.py", line 337, in parse
    loader.exec_module(new_module)
  File "<frozen importlib._bootstrap_external>", line 883, in exec_module
  File "<frozen importlib._bootstrap>", line 241, in _call_with_frames_removed
  File "/home/cavemhan/Documents/python/test_scripts/cyder-test/dags/ml_dags.py", line 32, in <module>
    data_processor_for_ml = DataProcessorForML(data=feature_extractor.df)
AttributeError: 'FeatureExtractor' object has no attribute 'df'
[2023-04-25T23:15:44.551+0100] {processor.py:755} WARNING - No viable dags retrieved from /home/cavemhan/Documents/python/test_scripts/cyder-test/dags/ml_dags.py
[2023-04-25T23:15:44.572+0100] {processor.py:175} INFO - Processing /home/cavemhan/Documents/python/test_scripts/cyder-test/dags/ml_dags.py took 1.257 seconds
[2023-04-25T23:16:15.397+0100] {processor.py:153} INFO - Started process (PID=12404) to work on /home/cavemhan/Documents/python/test_scripts/cyder-test/dags/ml_dags.py
[2023-04-25T23:16:15.398+0100] {processor.py:743} INFO - Processing file /home/cavemhan/Documents/python/test_scripts/cyder-test/dags/ml_dags.py for tasks to queue
[2023-04-25T23:16:15.398+0100] {logging_mixin.py:137} INFO - [2023-04-25T23:16:15.398+0100] {dagbag.py:532} INFO - Filling up the DagBag from /home/cavemhan/Documents/python/test_scripts/cyder-test/dags/ml_dags.py
[2023-04-25T23:16:16.659+0100] {logging_mixin.py:137} INFO - [2023-04-25T23:16:16.658+0100] {dagbag.py:341} ERROR - Failed to import: /home/cavemhan/Documents/python/test_scripts/cyder-test/dags/ml_dags.py
Traceback (most recent call last):
  File "/home/cavemhan/.local/share/virtualenvs/cyder-test-QPBcvLjc/lib/python3.10/site-packages/airflow/models/dagbag.py", line 337, in parse
    loader.exec_module(new_module)
  File "<frozen importlib._bootstrap_external>", line 883, in exec_module
  File "<frozen importlib._bootstrap>", line 241, in _call_with_frames_removed
  File "/home/cavemhan/Documents/python/test_scripts/cyder-test/dags/ml_dags.py", line 32, in <module>
    data_processor_for_ml = DataProcessorForML(data=feature_extractor.df)
AttributeError: 'FeatureExtractor' object has no attribute 'df'
[2023-04-25T23:16:16.660+0100] {processor.py:755} WARNING - No viable dags retrieved from /home/cavemhan/Documents/python/test_scripts/cyder-test/dags/ml_dags.py
[2023-04-25T23:16:16.677+0100] {processor.py:175} INFO - Processing /home/cavemhan/Documents/python/test_scripts/cyder-test/dags/ml_dags.py took 1.283 seconds
[2023-04-25T23:16:47.308+0100] {processor.py:153} INFO - Started process (PID=12582) to work on /home/cavemhan/Documents/python/test_scripts/cyder-test/dags/ml_dags.py
[2023-04-25T23:16:47.311+0100] {processor.py:743} INFO - Processing file /home/cavemhan/Documents/python/test_scripts/cyder-test/dags/ml_dags.py for tasks to queue
[2023-04-25T23:16:47.312+0100] {logging_mixin.py:137} INFO - [2023-04-25T23:16:47.312+0100] {dagbag.py:532} INFO - Filling up the DagBag from /home/cavemhan/Documents/python/test_scripts/cyder-test/dags/ml_dags.py
[2023-04-25T23:16:48.559+0100] {logging_mixin.py:137} INFO - [2023-04-25T23:16:48.558+0100] {dagbag.py:341} ERROR - Failed to import: /home/cavemhan/Documents/python/test_scripts/cyder-test/dags/ml_dags.py
Traceback (most recent call last):
  File "/home/cavemhan/.local/share/virtualenvs/cyder-test-QPBcvLjc/lib/python3.10/site-packages/airflow/models/dagbag.py", line 337, in parse
    loader.exec_module(new_module)
  File "<frozen importlib._bootstrap_external>", line 883, in exec_module
  File "<frozen importlib._bootstrap>", line 241, in _call_with_frames_removed
  File "/home/cavemhan/Documents/python/test_scripts/cyder-test/dags/ml_dags.py", line 32, in <module>
    data_processor_for_ml = DataProcessorForML(data=feature_extractor.df)
AttributeError: 'FeatureExtractor' object has no attribute 'df'
[2023-04-25T23:16:48.560+0100] {processor.py:755} WARNING - No viable dags retrieved from /home/cavemhan/Documents/python/test_scripts/cyder-test/dags/ml_dags.py
[2023-04-25T23:16:48.578+0100] {processor.py:175} INFO - Processing /home/cavemhan/Documents/python/test_scripts/cyder-test/dags/ml_dags.py took 1.274 seconds
[2023-04-25T23:17:19.235+0100] {processor.py:153} INFO - Started process (PID=12767) to work on /home/cavemhan/Documents/python/test_scripts/cyder-test/dags/ml_dags.py
[2023-04-25T23:17:19.239+0100] {processor.py:743} INFO - Processing file /home/cavemhan/Documents/python/test_scripts/cyder-test/dags/ml_dags.py for tasks to queue
[2023-04-25T23:17:19.240+0100] {logging_mixin.py:137} INFO - [2023-04-25T23:17:19.239+0100] {dagbag.py:532} INFO - Filling up the DagBag from /home/cavemhan/Documents/python/test_scripts/cyder-test/dags/ml_dags.py
[2023-04-25T23:17:20.525+0100] {logging_mixin.py:137} INFO - [2023-04-25T23:17:20.524+0100] {dagbag.py:341} ERROR - Failed to import: /home/cavemhan/Documents/python/test_scripts/cyder-test/dags/ml_dags.py
Traceback (most recent call last):
  File "/home/cavemhan/.local/share/virtualenvs/cyder-test-QPBcvLjc/lib/python3.10/site-packages/airflow/models/dagbag.py", line 337, in parse
    loader.exec_module(new_module)
  File "<frozen importlib._bootstrap_external>", line 883, in exec_module
  File "<frozen importlib._bootstrap>", line 241, in _call_with_frames_removed
  File "/home/cavemhan/Documents/python/test_scripts/cyder-test/dags/ml_dags.py", line 32, in <module>
    data_processor_for_ml = DataProcessorForML(data=feature_extractor.df)
AttributeError: 'FeatureExtractor' object has no attribute 'df'
[2023-04-25T23:17:20.525+0100] {processor.py:755} WARNING - No viable dags retrieved from /home/cavemhan/Documents/python/test_scripts/cyder-test/dags/ml_dags.py
[2023-04-25T23:17:20.546+0100] {processor.py:175} INFO - Processing /home/cavemhan/Documents/python/test_scripts/cyder-test/dags/ml_dags.py took 1.315 seconds
[2023-04-25T23:17:52.575+0100] {processor.py:153} INFO - Started process (PID=12960) to work on /home/cavemhan/Documents/python/test_scripts/cyder-test/dags/ml_dags.py
[2023-04-25T23:17:52.578+0100] {processor.py:743} INFO - Processing file /home/cavemhan/Documents/python/test_scripts/cyder-test/dags/ml_dags.py for tasks to queue
[2023-04-25T23:17:52.579+0100] {logging_mixin.py:137} INFO - [2023-04-25T23:17:52.579+0100] {dagbag.py:532} INFO - Filling up the DagBag from /home/cavemhan/Documents/python/test_scripts/cyder-test/dags/ml_dags.py
[2023-04-25T23:17:53.826+0100] {logging_mixin.py:137} INFO - [2023-04-25T23:17:53.825+0100] {dagbag.py:341} ERROR - Failed to import: /home/cavemhan/Documents/python/test_scripts/cyder-test/dags/ml_dags.py
Traceback (most recent call last):
  File "/home/cavemhan/.local/share/virtualenvs/cyder-test-QPBcvLjc/lib/python3.10/site-packages/airflow/models/dagbag.py", line 337, in parse
    loader.exec_module(new_module)
  File "<frozen importlib._bootstrap_external>", line 883, in exec_module
  File "<frozen importlib._bootstrap>", line 241, in _call_with_frames_removed
  File "/home/cavemhan/Documents/python/test_scripts/cyder-test/dags/ml_dags.py", line 32, in <module>
    data_processor_for_ml = DataProcessorForML(data=feature_extractor.df)
AttributeError: 'FeatureExtractor' object has no attribute 'df'
[2023-04-25T23:17:53.826+0100] {processor.py:755} WARNING - No viable dags retrieved from /home/cavemhan/Documents/python/test_scripts/cyder-test/dags/ml_dags.py
[2023-04-25T23:17:53.847+0100] {processor.py:175} INFO - Processing /home/cavemhan/Documents/python/test_scripts/cyder-test/dags/ml_dags.py took 1.276 seconds
[2023-04-25T23:58:49.066+0100] {processor.py:153} INFO - Started process (PID=13457) to work on /home/cavemhan/Documents/python/test_scripts/cyder-test/dags/ml_dags.py
[2023-04-25T23:58:49.070+0100] {processor.py:743} INFO - Processing file /home/cavemhan/Documents/python/test_scripts/cyder-test/dags/ml_dags.py for tasks to queue
[2023-04-25T23:58:49.071+0100] {logging_mixin.py:137} INFO - [2023-04-25T23:58:49.071+0100] {dagbag.py:532} INFO - Filling up the DagBag from /home/cavemhan/Documents/python/test_scripts/cyder-test/dags/ml_dags.py
[2023-04-25T23:58:50.353+0100] {logging_mixin.py:137} INFO - [2023-04-25T23:58:50.352+0100] {dagbag.py:341} ERROR - Failed to import: /home/cavemhan/Documents/python/test_scripts/cyder-test/dags/ml_dags.py
Traceback (most recent call last):
  File "/home/cavemhan/.local/share/virtualenvs/cyder-test-QPBcvLjc/lib/python3.10/site-packages/airflow/models/dagbag.py", line 337, in parse
    loader.exec_module(new_module)
  File "<frozen importlib._bootstrap_external>", line 883, in exec_module
  File "<frozen importlib._bootstrap>", line 241, in _call_with_frames_removed
  File "/home/cavemhan/Documents/python/test_scripts/cyder-test/dags/ml_dags.py", line 32, in <module>
    data_processor_for_ml = DataProcessorForML(data=feature_extractor.df)
AttributeError: 'FeatureExtractor' object has no attribute 'df'
[2023-04-25T23:58:50.353+0100] {processor.py:755} WARNING - No viable dags retrieved from /home/cavemhan/Documents/python/test_scripts/cyder-test/dags/ml_dags.py
[2023-04-25T23:58:50.372+0100] {processor.py:175} INFO - Processing /home/cavemhan/Documents/python/test_scripts/cyder-test/dags/ml_dags.py took 1.309 seconds
[2023-04-25T23:59:30.278+0100] {processor.py:153} INFO - Started process (PID=13647) to work on /home/cavemhan/Documents/python/test_scripts/cyder-test/dags/ml_dags.py
[2023-04-25T23:59:30.281+0100] {processor.py:743} INFO - Processing file /home/cavemhan/Documents/python/test_scripts/cyder-test/dags/ml_dags.py for tasks to queue
[2023-04-25T23:59:30.282+0100] {logging_mixin.py:137} INFO - [2023-04-25T23:59:30.282+0100] {dagbag.py:532} INFO - Filling up the DagBag from /home/cavemhan/Documents/python/test_scripts/cyder-test/dags/ml_dags.py
[2023-04-25T23:59:31.546+0100] {logging_mixin.py:137} INFO - [2023-04-25T23:59:31.545+0100] {dagbag.py:341} ERROR - Failed to import: /home/cavemhan/Documents/python/test_scripts/cyder-test/dags/ml_dags.py
Traceback (most recent call last):
  File "/home/cavemhan/.local/share/virtualenvs/cyder-test-QPBcvLjc/lib/python3.10/site-packages/airflow/models/dagbag.py", line 337, in parse
    loader.exec_module(new_module)
  File "<frozen importlib._bootstrap_external>", line 883, in exec_module
  File "<frozen importlib._bootstrap>", line 241, in _call_with_frames_removed
  File "/home/cavemhan/Documents/python/test_scripts/cyder-test/dags/ml_dags.py", line 32, in <module>
    data_processor_for_ml = DataProcessorForML(data=feature_extractor.df)
AttributeError: 'FeatureExtractor' object has no attribute 'df'
[2023-04-25T23:59:31.546+0100] {processor.py:755} WARNING - No viable dags retrieved from /home/cavemhan/Documents/python/test_scripts/cyder-test/dags/ml_dags.py
[2023-04-25T23:59:31.570+0100] {processor.py:175} INFO - Processing /home/cavemhan/Documents/python/test_scripts/cyder-test/dags/ml_dags.py took 1.296 seconds
[2023-04-26T00:00:20.769+0100] {processor.py:153} INFO - Started process (PID=13895) to work on /home/cavemhan/Documents/python/test_scripts/cyder-test/dags/ml_dags.py
[2023-04-26T00:00:20.773+0100] {processor.py:743} INFO - Processing file /home/cavemhan/Documents/python/test_scripts/cyder-test/dags/ml_dags.py for tasks to queue
[2023-04-26T00:00:20.774+0100] {logging_mixin.py:137} INFO - [2023-04-26T00:00:20.774+0100] {dagbag.py:532} INFO - Filling up the DagBag from /home/cavemhan/Documents/python/test_scripts/cyder-test/dags/ml_dags.py
[2023-04-26T00:00:22.090+0100] {logging_mixin.py:137} INFO - [2023-04-26T00:00:22.089+0100] {dagbag.py:341} ERROR - Failed to import: /home/cavemhan/Documents/python/test_scripts/cyder-test/dags/ml_dags.py
Traceback (most recent call last):
  File "/home/cavemhan/.local/share/virtualenvs/cyder-test-QPBcvLjc/lib/python3.10/site-packages/airflow/models/dagbag.py", line 337, in parse
    loader.exec_module(new_module)
  File "<frozen importlib._bootstrap_external>", line 883, in exec_module
  File "<frozen importlib._bootstrap>", line 241, in _call_with_frames_removed
  File "/home/cavemhan/Documents/python/test_scripts/cyder-test/dags/ml_dags.py", line 32, in <module>
    data_processor_for_ml = DataProcessorForML(data=feature_extractor.df)
AttributeError: 'FeatureExtractor' object has no attribute 'df'
[2023-04-26T00:00:22.090+0100] {processor.py:755} WARNING - No viable dags retrieved from /home/cavemhan/Documents/python/test_scripts/cyder-test/dags/ml_dags.py
[2023-04-26T00:00:22.108+0100] {processor.py:175} INFO - Processing /home/cavemhan/Documents/python/test_scripts/cyder-test/dags/ml_dags.py took 1.343 seconds
[2023-04-26T00:01:16.002+0100] {processor.py:153} INFO - Started process (PID=14347) to work on /home/cavemhan/Documents/python/test_scripts/cyder-test/dags/ml_dags.py
[2023-04-26T00:01:16.005+0100] {processor.py:743} INFO - Processing file /home/cavemhan/Documents/python/test_scripts/cyder-test/dags/ml_dags.py for tasks to queue
[2023-04-26T00:01:16.005+0100] {logging_mixin.py:137} INFO - [2023-04-26T00:01:16.005+0100] {dagbag.py:532} INFO - Filling up the DagBag from /home/cavemhan/Documents/python/test_scripts/cyder-test/dags/ml_dags.py
[2023-04-26T00:01:17.197+0100] {logging_mixin.py:137} INFO - [2023-04-26T00:01:17.196+0100] {dagbag.py:341} ERROR - Failed to import: /home/cavemhan/Documents/python/test_scripts/cyder-test/dags/ml_dags.py
Traceback (most recent call last):
  File "/home/cavemhan/.local/share/virtualenvs/cyder-test-QPBcvLjc/lib/python3.10/site-packages/airflow/models/dagbag.py", line 337, in parse
    loader.exec_module(new_module)
  File "<frozen importlib._bootstrap_external>", line 883, in exec_module
  File "<frozen importlib._bootstrap>", line 241, in _call_with_frames_removed
  File "/home/cavemhan/Documents/python/test_scripts/cyder-test/dags/ml_dags.py", line 32, in <module>
    data_processor_for_ml = DataProcessorForML(data=feature_extractor.df)
AttributeError: 'FeatureExtractor' object has no attribute 'df'
[2023-04-26T00:01:17.197+0100] {processor.py:755} WARNING - No viable dags retrieved from /home/cavemhan/Documents/python/test_scripts/cyder-test/dags/ml_dags.py
[2023-04-26T00:01:17.215+0100] {processor.py:175} INFO - Processing /home/cavemhan/Documents/python/test_scripts/cyder-test/dags/ml_dags.py took 1.314 seconds
[2023-04-26T00:02:11.708+0100] {processor.py:153} INFO - Started process (PID=17781) to work on /home/cavemhan/Documents/python/test_scripts/cyder-test/dags/ml_dags.py
[2023-04-26T00:02:11.709+0100] {processor.py:743} INFO - Processing file /home/cavemhan/Documents/python/test_scripts/cyder-test/dags/ml_dags.py for tasks to queue
[2023-04-26T00:02:11.710+0100] {logging_mixin.py:137} INFO - [2023-04-26T00:02:11.710+0100] {dagbag.py:532} INFO - Filling up the DagBag from /home/cavemhan/Documents/python/test_scripts/cyder-test/dags/ml_dags.py
[2023-04-26T00:02:15.040+0100] {logging_mixin.py:137} INFO - [2023-04-26T00:02:15.036+0100] {dagbag.py:341} ERROR - Failed to import: /home/cavemhan/Documents/python/test_scripts/cyder-test/dags/ml_dags.py
Traceback (most recent call last):
  File "/home/cavemhan/.local/share/virtualenvs/cyder-test-QPBcvLjc/lib/python3.10/site-packages/airflow/models/dagbag.py", line 337, in parse
    loader.exec_module(new_module)
  File "<frozen importlib._bootstrap_external>", line 883, in exec_module
  File "<frozen importlib._bootstrap>", line 241, in _call_with_frames_removed
  File "/home/cavemhan/Documents/python/test_scripts/cyder-test/dags/ml_dags.py", line 32, in <module>
    data_processor_for_ml = DataProcessorForML(data=feature_extractor.df)
AttributeError: 'FeatureExtractor' object has no attribute 'df'
[2023-04-26T00:02:15.041+0100] {processor.py:755} WARNING - No viable dags retrieved from /home/cavemhan/Documents/python/test_scripts/cyder-test/dags/ml_dags.py
[2023-04-26T00:02:15.148+0100] {processor.py:175} INFO - Processing /home/cavemhan/Documents/python/test_scripts/cyder-test/dags/ml_dags.py took 3.443 seconds
[2023-04-26T00:02:47.763+0100] {processor.py:153} INFO - Started process (PID=19325) to work on /home/cavemhan/Documents/python/test_scripts/cyder-test/dags/ml_dags.py
[2023-04-26T00:02:47.764+0100] {processor.py:743} INFO - Processing file /home/cavemhan/Documents/python/test_scripts/cyder-test/dags/ml_dags.py for tasks to queue
[2023-04-26T00:02:47.765+0100] {logging_mixin.py:137} INFO - [2023-04-26T00:02:47.764+0100] {dagbag.py:532} INFO - Filling up the DagBag from /home/cavemhan/Documents/python/test_scripts/cyder-test/dags/ml_dags.py
[2023-04-26T00:02:49.099+0100] {logging_mixin.py:137} INFO - [2023-04-26T00:02:49.098+0100] {dagbag.py:341} ERROR - Failed to import: /home/cavemhan/Documents/python/test_scripts/cyder-test/dags/ml_dags.py
Traceback (most recent call last):
  File "/home/cavemhan/.local/share/virtualenvs/cyder-test-QPBcvLjc/lib/python3.10/site-packages/airflow/models/dagbag.py", line 337, in parse
    loader.exec_module(new_module)
  File "<frozen importlib._bootstrap_external>", line 883, in exec_module
  File "<frozen importlib._bootstrap>", line 241, in _call_with_frames_removed
  File "/home/cavemhan/Documents/python/test_scripts/cyder-test/dags/ml_dags.py", line 32, in <module>
    data_processor_for_ml = DataProcessorForML(data=feature_extractor.df)
AttributeError: 'FeatureExtractor' object has no attribute 'df'
[2023-04-26T00:02:49.099+0100] {processor.py:755} WARNING - No viable dags retrieved from /home/cavemhan/Documents/python/test_scripts/cyder-test/dags/ml_dags.py
[2023-04-26T00:02:49.132+0100] {processor.py:175} INFO - Processing /home/cavemhan/Documents/python/test_scripts/cyder-test/dags/ml_dags.py took 1.373 seconds
[2023-04-26T00:03:42.234+0100] {processor.py:153} INFO - Started process (PID=20576) to work on /home/cavemhan/Documents/python/test_scripts/cyder-test/dags/ml_dags.py
[2023-04-26T00:03:42.235+0100] {processor.py:743} INFO - Processing file /home/cavemhan/Documents/python/test_scripts/cyder-test/dags/ml_dags.py for tasks to queue
[2023-04-26T00:03:42.236+0100] {logging_mixin.py:137} INFO - [2023-04-26T00:03:42.236+0100] {dagbag.py:532} INFO - Filling up the DagBag from /home/cavemhan/Documents/python/test_scripts/cyder-test/dags/ml_dags.py
[2023-04-26T00:03:43.972+0100] {logging_mixin.py:137} INFO - [2023-04-26T00:03:43.971+0100] {dagbag.py:341} ERROR - Failed to import: /home/cavemhan/Documents/python/test_scripts/cyder-test/dags/ml_dags.py
Traceback (most recent call last):
  File "/home/cavemhan/.local/share/virtualenvs/cyder-test-QPBcvLjc/lib/python3.10/site-packages/airflow/models/dagbag.py", line 337, in parse
    loader.exec_module(new_module)
  File "<frozen importlib._bootstrap_external>", line 883, in exec_module
  File "<frozen importlib._bootstrap>", line 241, in _call_with_frames_removed
  File "/home/cavemhan/Documents/python/test_scripts/cyder-test/dags/ml_dags.py", line 32, in <module>
    data_processor_for_ml = DataProcessorForML(data=feature_extractor.df)
AttributeError: 'FeatureExtractor' object has no attribute 'df'
[2023-04-26T00:03:43.972+0100] {processor.py:755} WARNING - No viable dags retrieved from /home/cavemhan/Documents/python/test_scripts/cyder-test/dags/ml_dags.py
[2023-04-26T00:03:43.991+0100] {processor.py:175} INFO - Processing /home/cavemhan/Documents/python/test_scripts/cyder-test/dags/ml_dags.py took 1.760 seconds
[2023-04-26T00:04:34.238+0100] {processor.py:153} INFO - Started process (PID=21801) to work on /home/cavemhan/Documents/python/test_scripts/cyder-test/dags/ml_dags.py
[2023-04-26T00:04:34.240+0100] {processor.py:743} INFO - Processing file /home/cavemhan/Documents/python/test_scripts/cyder-test/dags/ml_dags.py for tasks to queue
[2023-04-26T00:04:34.240+0100] {logging_mixin.py:137} INFO - [2023-04-26T00:04:34.240+0100] {dagbag.py:532} INFO - Filling up the DagBag from /home/cavemhan/Documents/python/test_scripts/cyder-test/dags/ml_dags.py
[2023-04-26T00:04:36.742+0100] {logging_mixin.py:137} INFO - [2023-04-26T00:04:36.741+0100] {dagbag.py:341} ERROR - Failed to import: /home/cavemhan/Documents/python/test_scripts/cyder-test/dags/ml_dags.py
Traceback (most recent call last):
  File "/home/cavemhan/.local/share/virtualenvs/cyder-test-QPBcvLjc/lib/python3.10/site-packages/airflow/models/dagbag.py", line 337, in parse
    loader.exec_module(new_module)
  File "<frozen importlib._bootstrap_external>", line 883, in exec_module
  File "<frozen importlib._bootstrap>", line 241, in _call_with_frames_removed
  File "/home/cavemhan/Documents/python/test_scripts/cyder-test/dags/ml_dags.py", line 40, in <module>
    data_processor_for_ml = DataProcessorForML(data=feature_extractor.df)
AttributeError: 'FeatureExtractor' object has no attribute 'df'
[2023-04-26T00:04:36.742+0100] {processor.py:755} WARNING - No viable dags retrieved from /home/cavemhan/Documents/python/test_scripts/cyder-test/dags/ml_dags.py
[2023-04-26T00:04:36.765+0100] {processor.py:175} INFO - Processing /home/cavemhan/Documents/python/test_scripts/cyder-test/dags/ml_dags.py took 2.530 seconds
[2023-04-26T00:05:03.026+0100] {processor.py:153} INFO - Started process (PID=22469) to work on /home/cavemhan/Documents/python/test_scripts/cyder-test/dags/ml_dags.py
[2023-04-26T00:05:03.030+0100] {processor.py:743} INFO - Processing file /home/cavemhan/Documents/python/test_scripts/cyder-test/dags/ml_dags.py for tasks to queue
[2023-04-26T00:05:03.031+0100] {logging_mixin.py:137} INFO - [2023-04-26T00:05:03.030+0100] {dagbag.py:532} INFO - Filling up the DagBag from /home/cavemhan/Documents/python/test_scripts/cyder-test/dags/ml_dags.py
[2023-04-26T00:05:05.074+0100] {logging_mixin.py:137} INFO - [2023-04-26T00:05:05.073+0100] {dagbag.py:341} ERROR - Failed to import: /home/cavemhan/Documents/python/test_scripts/cyder-test/dags/ml_dags.py
Traceback (most recent call last):
  File "/home/cavemhan/.local/share/virtualenvs/cyder-test-QPBcvLjc/lib/python3.10/site-packages/airflow/models/dagbag.py", line 337, in parse
    loader.exec_module(new_module)
  File "<frozen importlib._bootstrap_external>", line 883, in exec_module
  File "<frozen importlib._bootstrap>", line 241, in _call_with_frames_removed
  File "/home/cavemhan/Documents/python/test_scripts/cyder-test/dags/ml_dags.py", line 40, in <module>
    data_processor_for_ml = DataProcessorForML(data=feature_extractor.df)
AttributeError: 'FeatureExtractor' object has no attribute 'df'
[2023-04-26T00:05:05.075+0100] {processor.py:755} WARNING - No viable dags retrieved from /home/cavemhan/Documents/python/test_scripts/cyder-test/dags/ml_dags.py
[2023-04-26T00:05:05.097+0100] {processor.py:175} INFO - Processing /home/cavemhan/Documents/python/test_scripts/cyder-test/dags/ml_dags.py took 2.074 seconds
[2023-04-26T00:05:32.995+0100] {processor.py:153} INFO - Started process (PID=23168) to work on /home/cavemhan/Documents/python/test_scripts/cyder-test/dags/ml_dags.py
[2023-04-26T00:05:32.996+0100] {processor.py:743} INFO - Processing file /home/cavemhan/Documents/python/test_scripts/cyder-test/dags/ml_dags.py for tasks to queue
[2023-04-26T00:05:32.996+0100] {logging_mixin.py:137} INFO - [2023-04-26T00:05:32.996+0100] {dagbag.py:532} INFO - Filling up the DagBag from /home/cavemhan/Documents/python/test_scripts/cyder-test/dags/ml_dags.py
[2023-04-26T00:05:34.853+0100] {logging_mixin.py:137} INFO - [2023-04-26T00:05:34.852+0100] {dagbag.py:341} ERROR - Failed to import: /home/cavemhan/Documents/python/test_scripts/cyder-test/dags/ml_dags.py
Traceback (most recent call last):
  File "/home/cavemhan/.local/share/virtualenvs/cyder-test-QPBcvLjc/lib/python3.10/site-packages/airflow/models/dagbag.py", line 337, in parse
    loader.exec_module(new_module)
  File "<frozen importlib._bootstrap_external>", line 883, in exec_module
  File "<frozen importlib._bootstrap>", line 241, in _call_with_frames_removed
  File "/home/cavemhan/Documents/python/test_scripts/cyder-test/dags/ml_dags.py", line 40, in <module>
    data_processor_for_ml = DataProcessorForML(data=feature_extractor.df)
AttributeError: 'FeatureExtractor' object has no attribute 'df'
[2023-04-26T00:05:34.853+0100] {processor.py:755} WARNING - No viable dags retrieved from /home/cavemhan/Documents/python/test_scripts/cyder-test/dags/ml_dags.py
[2023-04-26T00:05:34.873+0100] {processor.py:175} INFO - Processing /home/cavemhan/Documents/python/test_scripts/cyder-test/dags/ml_dags.py took 1.881 seconds
[2023-04-26T00:06:00.526+0100] {processor.py:153} INFO - Started process (PID=23845) to work on /home/cavemhan/Documents/python/test_scripts/cyder-test/dags/ml_dags.py
[2023-04-26T00:06:00.527+0100] {processor.py:743} INFO - Processing file /home/cavemhan/Documents/python/test_scripts/cyder-test/dags/ml_dags.py for tasks to queue
[2023-04-26T00:06:00.527+0100] {logging_mixin.py:137} INFO - [2023-04-26T00:06:00.527+0100] {dagbag.py:532} INFO - Filling up the DagBag from /home/cavemhan/Documents/python/test_scripts/cyder-test/dags/ml_dags.py
[2023-04-26T00:06:02.001+0100] {logging_mixin.py:137} INFO - [2023-04-26T00:06:02.000+0100] {dagbag.py:341} ERROR - Failed to import: /home/cavemhan/Documents/python/test_scripts/cyder-test/dags/ml_dags.py
Traceback (most recent call last):
  File "/home/cavemhan/.local/share/virtualenvs/cyder-test-QPBcvLjc/lib/python3.10/site-packages/airflow/models/dagbag.py", line 337, in parse
    loader.exec_module(new_module)
  File "<frozen importlib._bootstrap_external>", line 883, in exec_module
  File "<frozen importlib._bootstrap>", line 241, in _call_with_frames_removed
  File "/home/cavemhan/Documents/python/test_scripts/cyder-test/dags/ml_dags.py", line 40, in <module>
    data_processor_for_ml = DataProcessorForML(data=feature_extractor.df)
AttributeError: 'FeatureExtractor' object has no attribute 'df'
[2023-04-26T00:06:02.002+0100] {processor.py:755} WARNING - No viable dags retrieved from /home/cavemhan/Documents/python/test_scripts/cyder-test/dags/ml_dags.py
[2023-04-26T00:06:02.025+0100] {processor.py:175} INFO - Processing /home/cavemhan/Documents/python/test_scripts/cyder-test/dags/ml_dags.py took 1.504 seconds
[2023-04-26T00:06:28.193+0100] {processor.py:153} INFO - Started process (PID=24478) to work on /home/cavemhan/Documents/python/test_scripts/cyder-test/dags/ml_dags.py
[2023-04-26T00:06:28.194+0100] {processor.py:743} INFO - Processing file /home/cavemhan/Documents/python/test_scripts/cyder-test/dags/ml_dags.py for tasks to queue
[2023-04-26T00:06:28.195+0100] {logging_mixin.py:137} INFO - [2023-04-26T00:06:28.195+0100] {dagbag.py:532} INFO - Filling up the DagBag from /home/cavemhan/Documents/python/test_scripts/cyder-test/dags/ml_dags.py
[2023-04-26T00:06:30.195+0100] {logging_mixin.py:137} INFO - [2023-04-26T00:06:30.194+0100] {dagbag.py:341} ERROR - Failed to import: /home/cavemhan/Documents/python/test_scripts/cyder-test/dags/ml_dags.py
Traceback (most recent call last):
  File "/home/cavemhan/.local/share/virtualenvs/cyder-test-QPBcvLjc/lib/python3.10/site-packages/airflow/models/dagbag.py", line 337, in parse
    loader.exec_module(new_module)
  File "<frozen importlib._bootstrap_external>", line 883, in exec_module
  File "<frozen importlib._bootstrap>", line 241, in _call_with_frames_removed
  File "/home/cavemhan/Documents/python/test_scripts/cyder-test/dags/ml_dags.py", line 40, in <module>
    data_processor_for_ml = DataProcessorForML(data=feature_extractor.df)
AttributeError: 'FeatureExtractor' object has no attribute 'df'
[2023-04-26T00:06:30.196+0100] {processor.py:755} WARNING - No viable dags retrieved from /home/cavemhan/Documents/python/test_scripts/cyder-test/dags/ml_dags.py
[2023-04-26T00:06:30.222+0100] {processor.py:175} INFO - Processing /home/cavemhan/Documents/python/test_scripts/cyder-test/dags/ml_dags.py took 2.035 seconds
[2023-04-26T00:06:56.285+0100] {processor.py:153} INFO - Started process (PID=25107) to work on /home/cavemhan/Documents/python/test_scripts/cyder-test/dags/ml_dags.py
[2023-04-26T00:06:56.288+0100] {processor.py:743} INFO - Processing file /home/cavemhan/Documents/python/test_scripts/cyder-test/dags/ml_dags.py for tasks to queue
[2023-04-26T00:06:56.289+0100] {logging_mixin.py:137} INFO - [2023-04-26T00:06:56.289+0100] {dagbag.py:532} INFO - Filling up the DagBag from /home/cavemhan/Documents/python/test_scripts/cyder-test/dags/ml_dags.py
[2023-04-26T00:06:57.670+0100] {logging_mixin.py:137} INFO - [2023-04-26T00:06:57.669+0100] {dagbag.py:341} ERROR - Failed to import: /home/cavemhan/Documents/python/test_scripts/cyder-test/dags/ml_dags.py
Traceback (most recent call last):
  File "/home/cavemhan/.local/share/virtualenvs/cyder-test-QPBcvLjc/lib/python3.10/site-packages/airflow/models/dagbag.py", line 337, in parse
    loader.exec_module(new_module)
  File "<frozen importlib._bootstrap_external>", line 883, in exec_module
  File "<frozen importlib._bootstrap>", line 241, in _call_with_frames_removed
  File "/home/cavemhan/Documents/python/test_scripts/cyder-test/dags/ml_dags.py", line 40, in <module>
    data_processor_for_ml = DataProcessorForML(data=feature_extractor.df)
AttributeError: 'FeatureExtractor' object has no attribute 'df'
[2023-04-26T00:06:57.670+0100] {processor.py:755} WARNING - No viable dags retrieved from /home/cavemhan/Documents/python/test_scripts/cyder-test/dags/ml_dags.py
[2023-04-26T00:06:57.694+0100] {processor.py:175} INFO - Processing /home/cavemhan/Documents/python/test_scripts/cyder-test/dags/ml_dags.py took 1.412 seconds
[2023-04-26T00:07:24.948+0100] {processor.py:153} INFO - Started process (PID=25792) to work on /home/cavemhan/Documents/python/test_scripts/cyder-test/dags/ml_dags.py
[2023-04-26T00:07:24.949+0100] {processor.py:743} INFO - Processing file /home/cavemhan/Documents/python/test_scripts/cyder-test/dags/ml_dags.py for tasks to queue
[2023-04-26T00:07:24.950+0100] {logging_mixin.py:137} INFO - [2023-04-26T00:07:24.950+0100] {dagbag.py:532} INFO - Filling up the DagBag from /home/cavemhan/Documents/python/test_scripts/cyder-test/dags/ml_dags.py
[2023-04-26T00:07:26.394+0100] {logging_mixin.py:137} INFO - [2023-04-26T00:07:26.393+0100] {dagbag.py:341} ERROR - Failed to import: /home/cavemhan/Documents/python/test_scripts/cyder-test/dags/ml_dags.py
Traceback (most recent call last):
  File "/home/cavemhan/.local/share/virtualenvs/cyder-test-QPBcvLjc/lib/python3.10/site-packages/airflow/models/dagbag.py", line 337, in parse
    loader.exec_module(new_module)
  File "<frozen importlib._bootstrap_external>", line 883, in exec_module
  File "<frozen importlib._bootstrap>", line 241, in _call_with_frames_removed
  File "/home/cavemhan/Documents/python/test_scripts/cyder-test/dags/ml_dags.py", line 40, in <module>
    data_processor_for_ml = DataProcessorForML(data=feature_extractor.df)
AttributeError: 'FeatureExtractor' object has no attribute 'df'
[2023-04-26T00:07:26.395+0100] {processor.py:755} WARNING - No viable dags retrieved from /home/cavemhan/Documents/python/test_scripts/cyder-test/dags/ml_dags.py
[2023-04-26T00:07:26.413+0100] {processor.py:175} INFO - Processing /home/cavemhan/Documents/python/test_scripts/cyder-test/dags/ml_dags.py took 1.468 seconds
[2023-04-26T00:07:52.040+0100] {processor.py:153} INFO - Started process (PID=26423) to work on /home/cavemhan/Documents/python/test_scripts/cyder-test/dags/ml_dags.py
[2023-04-26T00:07:52.043+0100] {processor.py:743} INFO - Processing file /home/cavemhan/Documents/python/test_scripts/cyder-test/dags/ml_dags.py for tasks to queue
[2023-04-26T00:07:52.044+0100] {logging_mixin.py:137} INFO - [2023-04-26T00:07:52.044+0100] {dagbag.py:532} INFO - Filling up the DagBag from /home/cavemhan/Documents/python/test_scripts/cyder-test/dags/ml_dags.py
[2023-04-26T00:07:54.237+0100] {logging_mixin.py:137} INFO - [2023-04-26T00:07:54.236+0100] {dagbag.py:341} ERROR - Failed to import: /home/cavemhan/Documents/python/test_scripts/cyder-test/dags/ml_dags.py
Traceback (most recent call last):
  File "/home/cavemhan/.local/share/virtualenvs/cyder-test-QPBcvLjc/lib/python3.10/site-packages/airflow/models/dagbag.py", line 337, in parse
    loader.exec_module(new_module)
  File "<frozen importlib._bootstrap_external>", line 883, in exec_module
  File "<frozen importlib._bootstrap>", line 241, in _call_with_frames_removed
  File "/home/cavemhan/Documents/python/test_scripts/cyder-test/dags/ml_dags.py", line 40, in <module>
    data_processor_for_ml = DataProcessorForML(data= "{{ ti.xcom_pull(task_ids='run_example_dag_1', key='attribute_1') }}" feature_extractor.df)
AttributeError: 'FeatureExtractor' object has no attribute 'df'
[2023-04-26T00:07:54.238+0100] {processor.py:755} WARNING - No viable dags retrieved from /home/cavemhan/Documents/python/test_scripts/cyder-test/dags/ml_dags.py
[2023-04-26T00:07:54.262+0100] {processor.py:175} INFO - Processing /home/cavemhan/Documents/python/test_scripts/cyder-test/dags/ml_dags.py took 2.225 seconds
[2023-04-26T00:08:20.376+0100] {processor.py:153} INFO - Started process (PID=27094) to work on /home/cavemhan/Documents/python/test_scripts/cyder-test/dags/ml_dags.py
[2023-04-26T00:08:20.380+0100] {processor.py:743} INFO - Processing file /home/cavemhan/Documents/python/test_scripts/cyder-test/dags/ml_dags.py for tasks to queue
[2023-04-26T00:08:20.382+0100] {logging_mixin.py:137} INFO - [2023-04-26T00:08:20.382+0100] {dagbag.py:532} INFO - Filling up the DagBag from /home/cavemhan/Documents/python/test_scripts/cyder-test/dags/ml_dags.py
[2023-04-26T00:08:20.385+0100] {logging_mixin.py:137} INFO - [2023-04-26T00:08:20.384+0100] {dagbag.py:341} ERROR - Failed to import: /home/cavemhan/Documents/python/test_scripts/cyder-test/dags/ml_dags.py
Traceback (most recent call last):
  File "/home/cavemhan/.local/share/virtualenvs/cyder-test-QPBcvLjc/lib/python3.10/site-packages/airflow/models/dagbag.py", line 337, in parse
    loader.exec_module(new_module)
  File "<frozen importlib._bootstrap_external>", line 879, in exec_module
  File "<frozen importlib._bootstrap_external>", line 1017, in get_code
  File "<frozen importlib._bootstrap_external>", line 947, in source_to_code
  File "<frozen importlib._bootstrap>", line 241, in _call_with_frames_removed
  File "/home/cavemhan/Documents/python/test_scripts/cyder-test/dags/ml_dags.py", line 40
    data_processor_for_ml = DataProcessorForML(data= "{{ ti.xcom_pull(task_ids='run_example_dag_1', key='df') }}" feature_extractor.)
                                                     ^^^^^^^^^^^^^^^^^^^^^^^^^^^^^^^^^^^^^^^^^^^^^^^^^^^^^^^^^^^^^^^^^^^^^^^^^^^^^^
SyntaxError: invalid syntax. Perhaps you forgot a comma?
[2023-04-26T00:08:20.385+0100] {processor.py:755} WARNING - No viable dags retrieved from /home/cavemhan/Documents/python/test_scripts/cyder-test/dags/ml_dags.py
[2023-04-26T00:08:20.408+0100] {processor.py:175} INFO - Processing /home/cavemhan/Documents/python/test_scripts/cyder-test/dags/ml_dags.py took 0.035 seconds
[2023-04-26T00:08:47.928+0100] {processor.py:153} INFO - Started process (PID=27719) to work on /home/cavemhan/Documents/python/test_scripts/cyder-test/dags/ml_dags.py
[2023-04-26T00:08:47.928+0100] {processor.py:743} INFO - Processing file /home/cavemhan/Documents/python/test_scripts/cyder-test/dags/ml_dags.py for tasks to queue
[2023-04-26T00:08:47.929+0100] {logging_mixin.py:137} INFO - [2023-04-26T00:08:47.929+0100] {dagbag.py:532} INFO - Filling up the DagBag from /home/cavemhan/Documents/python/test_scripts/cyder-test/dags/ml_dags.py
[2023-04-26T00:08:47.932+0100] {logging_mixin.py:137} INFO - [2023-04-26T00:08:47.931+0100] {dagbag.py:341} ERROR - Failed to import: /home/cavemhan/Documents/python/test_scripts/cyder-test/dags/ml_dags.py
Traceback (most recent call last):
  File "/home/cavemhan/.local/share/virtualenvs/cyder-test-QPBcvLjc/lib/python3.10/site-packages/airflow/models/dagbag.py", line 337, in parse
    loader.exec_module(new_module)
  File "<frozen importlib._bootstrap_external>", line 879, in exec_module
  File "<frozen importlib._bootstrap_external>", line 1017, in get_code
  File "<frozen importlib._bootstrap_external>", line 947, in source_to_code
  File "<frozen importlib._bootstrap>", line 241, in _call_with_frames_removed
  File "/home/cavemhan/Documents/python/test_scripts/cyder-test/dags/ml_dags.py", line 40
    data_processor_for_ml = DataProcessorForML(data= "{{ ti.xcom_pull(task_ids='run_example_dag_1', key='df') }}" feature_extractor.)
                                                     ^^^^^^^^^^^^^^^^^^^^^^^^^^^^^^^^^^^^^^^^^^^^^^^^^^^^^^^^^^^^^^^^^^^^^^^^^^^^^^
SyntaxError: invalid syntax. Perhaps you forgot a comma?
[2023-04-26T00:08:47.932+0100] {processor.py:755} WARNING - No viable dags retrieved from /home/cavemhan/Documents/python/test_scripts/cyder-test/dags/ml_dags.py
[2023-04-26T00:08:47.954+0100] {processor.py:175} INFO - Processing /home/cavemhan/Documents/python/test_scripts/cyder-test/dags/ml_dags.py took 0.029 seconds
[2023-04-26T00:09:13.911+0100] {processor.py:153} INFO - Started process (PID=28367) to work on /home/cavemhan/Documents/python/test_scripts/cyder-test/dags/ml_dags.py
[2023-04-26T00:09:13.912+0100] {processor.py:743} INFO - Processing file /home/cavemhan/Documents/python/test_scripts/cyder-test/dags/ml_dags.py for tasks to queue
[2023-04-26T00:09:13.913+0100] {logging_mixin.py:137} INFO - [2023-04-26T00:09:13.913+0100] {dagbag.py:532} INFO - Filling up the DagBag from /home/cavemhan/Documents/python/test_scripts/cyder-test/dags/ml_dags.py
[2023-04-26T00:09:13.920+0100] {logging_mixin.py:137} INFO - [2023-04-26T00:09:13.919+0100] {dagbag.py:341} ERROR - Failed to import: /home/cavemhan/Documents/python/test_scripts/cyder-test/dags/ml_dags.py
Traceback (most recent call last):
  File "/home/cavemhan/.local/share/virtualenvs/cyder-test-QPBcvLjc/lib/python3.10/site-packages/airflow/models/dagbag.py", line 337, in parse
    loader.exec_module(new_module)
  File "<frozen importlib._bootstrap_external>", line 879, in exec_module
  File "<frozen importlib._bootstrap_external>", line 1017, in get_code
  File "<frozen importlib._bootstrap_external>", line 947, in source_to_code
  File "<frozen importlib._bootstrap>", line 241, in _call_with_frames_removed
  File "/home/cavemhan/Documents/python/test_scripts/cyder-test/dags/ml_dags.py", line 40
    data_processor_for_ml = DataProcessorForML(data= "{{ ti.xcom_pull(task_ids='run_example_dag_1', key='df') }}" feature_extractor.)
                                                     ^^^^^^^^^^^^^^^^^^^^^^^^^^^^^^^^^^^^^^^^^^^^^^^^^^^^^^^^^^^^^^^^^^^^^^^^^^^^^^
SyntaxError: invalid syntax. Perhaps you forgot a comma?
[2023-04-26T00:09:13.921+0100] {processor.py:755} WARNING - No viable dags retrieved from /home/cavemhan/Documents/python/test_scripts/cyder-test/dags/ml_dags.py
[2023-04-26T00:09:13.952+0100] {processor.py:175} INFO - Processing /home/cavemhan/Documents/python/test_scripts/cyder-test/dags/ml_dags.py took 0.046 seconds
[2023-04-26T00:09:40.034+0100] {processor.py:153} INFO - Started process (PID=29000) to work on /home/cavemhan/Documents/python/test_scripts/cyder-test/dags/ml_dags.py
[2023-04-26T00:09:40.035+0100] {processor.py:743} INFO - Processing file /home/cavemhan/Documents/python/test_scripts/cyder-test/dags/ml_dags.py for tasks to queue
[2023-04-26T00:09:40.035+0100] {logging_mixin.py:137} INFO - [2023-04-26T00:09:40.035+0100] {dagbag.py:532} INFO - Filling up the DagBag from /home/cavemhan/Documents/python/test_scripts/cyder-test/dags/ml_dags.py
[2023-04-26T00:09:42.276+0100] {logging_mixin.py:137} INFO - [2023-04-26T00:09:42.273+0100] {dagbag.py:341} ERROR - Failed to import: /home/cavemhan/Documents/python/test_scripts/cyder-test/dags/ml_dags.py
Traceback (most recent call last):
  File "/home/cavemhan/.local/share/virtualenvs/cyder-test-QPBcvLjc/lib/python3.10/site-packages/airflow/models/dagbag.py", line 337, in parse
    loader.exec_module(new_module)
  File "<frozen importlib._bootstrap_external>", line 883, in exec_module
  File "<frozen importlib._bootstrap>", line 241, in _call_with_frames_removed
  File "/home/cavemhan/Documents/python/test_scripts/cyder-test/dags/ml_dags.py", line 47, in <module>
    split_train_test = DataSplitter(X=data_processor_for_ml.features_df, y=data_processor_for_ml.target_series)
AttributeError: 'DataProcessorForML' object has no attribute 'features_df'
[2023-04-26T00:09:42.278+0100] {processor.py:755} WARNING - No viable dags retrieved from /home/cavemhan/Documents/python/test_scripts/cyder-test/dags/ml_dags.py
[2023-04-26T00:09:42.312+0100] {processor.py:175} INFO - Processing /home/cavemhan/Documents/python/test_scripts/cyder-test/dags/ml_dags.py took 2.281 seconds
[2023-04-26T00:10:09.130+0100] {processor.py:153} INFO - Started process (PID=29674) to work on /home/cavemhan/Documents/python/test_scripts/cyder-test/dags/ml_dags.py
[2023-04-26T00:10:09.131+0100] {processor.py:743} INFO - Processing file /home/cavemhan/Documents/python/test_scripts/cyder-test/dags/ml_dags.py for tasks to queue
[2023-04-26T00:10:09.132+0100] {logging_mixin.py:137} INFO - [2023-04-26T00:10:09.132+0100] {dagbag.py:532} INFO - Filling up the DagBag from /home/cavemhan/Documents/python/test_scripts/cyder-test/dags/ml_dags.py
[2023-04-26T00:10:10.969+0100] {logging_mixin.py:137} INFO - [2023-04-26T00:10:10.967+0100] {dagbag.py:341} ERROR - Failed to import: /home/cavemhan/Documents/python/test_scripts/cyder-test/dags/ml_dags.py
Traceback (most recent call last):
  File "/home/cavemhan/.local/share/virtualenvs/cyder-test-QPBcvLjc/lib/python3.10/site-packages/airflow/models/dagbag.py", line 337, in parse
    loader.exec_module(new_module)
  File "<frozen importlib._bootstrap_external>", line 883, in exec_module
  File "<frozen importlib._bootstrap>", line 241, in _call_with_frames_removed
  File "/home/cavemhan/Documents/python/test_scripts/cyder-test/dags/ml_dags.py", line 55, in <module>
    model_trainer = ModelTrainer(X_train=split_train_test.X_train, y_train=split_train_test.y_train)
AttributeError: 'DataSplitter' object has no attribute 'X_train'
[2023-04-26T00:10:10.970+0100] {processor.py:755} WARNING - No viable dags retrieved from /home/cavemhan/Documents/python/test_scripts/cyder-test/dags/ml_dags.py
[2023-04-26T00:10:10.989+0100] {processor.py:175} INFO - Processing /home/cavemhan/Documents/python/test_scripts/cyder-test/dags/ml_dags.py took 1.864 seconds
[2023-04-26T00:10:38.376+0100] {processor.py:153} INFO - Started process (PID=30303) to work on /home/cavemhan/Documents/python/test_scripts/cyder-test/dags/ml_dags.py
[2023-04-26T00:10:38.377+0100] {processor.py:743} INFO - Processing file /home/cavemhan/Documents/python/test_scripts/cyder-test/dags/ml_dags.py for tasks to queue
[2023-04-26T00:10:38.378+0100] {logging_mixin.py:137} INFO - [2023-04-26T00:10:38.378+0100] {dagbag.py:532} INFO - Filling up the DagBag from /home/cavemhan/Documents/python/test_scripts/cyder-test/dags/ml_dags.py
[2023-04-26T00:10:40.938+0100] {logging_mixin.py:137} INFO - [2023-04-26T00:10:40.936+0100] {dagbag.py:341} ERROR - Failed to import: /home/cavemhan/Documents/python/test_scripts/cyder-test/dags/ml_dags.py
Traceback (most recent call last):
  File "/home/cavemhan/.local/share/virtualenvs/cyder-test-QPBcvLjc/lib/python3.10/site-packages/airflow/models/dagbag.py", line 337, in parse
    loader.exec_module(new_module)
  File "<frozen importlib._bootstrap_external>", line 883, in exec_module
  File "<frozen importlib._bootstrap>", line 241, in _call_with_frames_removed
  File "/home/cavemhan/Documents/python/test_scripts/cyder-test/dags/ml_dags.py", line 55, in <module>
    model_trainer = ModelTrainer(X_train="{{ ti.xcom_pull(task_ids='split_train_test', key='X_train') }}", y_train="{{ ti.xcom_pull(task_ids='split_train_test', key='X_train') }}"split_train_test.y_train)
AttributeError: 'DataSplitter' object has no attribute 'y_train'
[2023-04-26T00:10:40.939+0100] {processor.py:755} WARNING - No viable dags retrieved from /home/cavemhan/Documents/python/test_scripts/cyder-test/dags/ml_dags.py
[2023-04-26T00:10:40.964+0100] {processor.py:175} INFO - Processing /home/cavemhan/Documents/python/test_scripts/cyder-test/dags/ml_dags.py took 2.592 seconds
[2023-04-26T00:11:07.714+0100] {processor.py:153} INFO - Started process (PID=31088) to work on /home/cavemhan/Documents/python/test_scripts/cyder-test/dags/ml_dags.py
[2023-04-26T00:11:07.715+0100] {processor.py:743} INFO - Processing file /home/cavemhan/Documents/python/test_scripts/cyder-test/dags/ml_dags.py for tasks to queue
[2023-04-26T00:11:07.716+0100] {logging_mixin.py:137} INFO - [2023-04-26T00:11:07.716+0100] {dagbag.py:532} INFO - Filling up the DagBag from /home/cavemhan/Documents/python/test_scripts/cyder-test/dags/ml_dags.py
[2023-04-26T00:11:10.348+0100] {logging_mixin.py:137} INFO - [2023-04-26T00:11:10.343+0100] {dagbag.py:341} ERROR - Failed to import: /home/cavemhan/Documents/python/test_scripts/cyder-test/dags/ml_dags.py
Traceback (most recent call last):
  File "/home/cavemhan/.local/share/virtualenvs/cyder-test-QPBcvLjc/lib/python3.10/site-packages/airflow/models/dagbag.py", line 337, in parse
    loader.exec_module(new_module)
  File "<frozen importlib._bootstrap_external>", line 883, in exec_module
  File "<frozen importlib._bootstrap>", line 241, in _call_with_frames_removed
  File "/home/cavemhan/Documents/python/test_scripts/cyder-test/dags/ml_dags.py", line 63, in <module>
    model_tester = ModelTester(model="{{ ti.xcom_pull(task_ids='model_trainer', key='X_train') }}" .model, X_test=split_train_test.X_test, y_test=split_train_test.y_test)
AttributeError: 'str' object has no attribute 'model'
[2023-04-26T00:11:10.350+0100] {processor.py:755} WARNING - No viable dags retrieved from /home/cavemhan/Documents/python/test_scripts/cyder-test/dags/ml_dags.py
[2023-04-26T00:11:10.374+0100] {processor.py:175} INFO - Processing /home/cavemhan/Documents/python/test_scripts/cyder-test/dags/ml_dags.py took 2.665 seconds
[2023-04-26T00:11:38.883+0100] {processor.py:153} INFO - Started process (PID=31902) to work on /home/cavemhan/Documents/python/test_scripts/cyder-test/dags/ml_dags.py
[2023-04-26T00:11:38.884+0100] {processor.py:743} INFO - Processing file /home/cavemhan/Documents/python/test_scripts/cyder-test/dags/ml_dags.py for tasks to queue
[2023-04-26T00:11:38.886+0100] {logging_mixin.py:137} INFO - [2023-04-26T00:11:38.886+0100] {dagbag.py:532} INFO - Filling up the DagBag from /home/cavemhan/Documents/python/test_scripts/cyder-test/dags/ml_dags.py
[2023-04-26T00:11:41.088+0100] {logging_mixin.py:137} INFO - [2023-04-26T00:11:41.085+0100] {dagbag.py:341} ERROR - Failed to import: /home/cavemhan/Documents/python/test_scripts/cyder-test/dags/ml_dags.py
Traceback (most recent call last):
  File "/home/cavemhan/.local/share/virtualenvs/cyder-test-QPBcvLjc/lib/python3.10/site-packages/airflow/models/dagbag.py", line 337, in parse
    loader.exec_module(new_module)
  File "<frozen importlib._bootstrap_external>", line 883, in exec_module
  File "<frozen importlib._bootstrap>", line 241, in _call_with_frames_removed
  File "/home/cavemhan/Documents/python/test_scripts/cyder-test/dags/ml_dags.py", line 63, in <module>
    model_tester = ModelTester(model="{{ ti.xcom_pull(task_ids='model_trainer', key='model') }}", X_test="{{ ti.xcom_pull(task_ids='split_train_test', key='model') }}", y_test=split_train_test.y_test)
AttributeError: 'str' object has no attribute 'X_test'
[2023-04-26T00:11:41.089+0100] {processor.py:755} WARNING - No viable dags retrieved from /home/cavemhan/Documents/python/test_scripts/cyder-test/dags/ml_dags.py
[2023-04-26T00:11:41.107+0100] {processor.py:175} INFO - Processing /home/cavemhan/Documents/python/test_scripts/cyder-test/dags/ml_dags.py took 2.230 seconds
[2023-04-26T00:12:06.989+0100] {processor.py:153} INFO - Started process (PID=32564) to work on /home/cavemhan/Documents/python/test_scripts/cyder-test/dags/ml_dags.py
[2023-04-26T00:12:06.990+0100] {processor.py:743} INFO - Processing file /home/cavemhan/Documents/python/test_scripts/cyder-test/dags/ml_dags.py for tasks to queue
[2023-04-26T00:12:06.991+0100] {logging_mixin.py:137} INFO - [2023-04-26T00:12:06.991+0100] {dagbag.py:532} INFO - Filling up the DagBag from /home/cavemhan/Documents/python/test_scripts/cyder-test/dags/ml_dags.py
[2023-04-26T00:12:08.823+0100] {processor.py:753} INFO - DAG(s) dict_keys(['ml_analysis_pipeline']) retrieved from /home/cavemhan/Documents/python/test_scripts/cyder-test/dags/ml_dags.py
[2023-04-26T00:12:08.944+0100] {logging_mixin.py:137} INFO - [2023-04-26T00:12:08.943+0100] {dag.py:2705} INFO - Sync 1 DAGs
[2023-04-26T00:12:08.973+0100] {logging_mixin.py:137} INFO - [2023-04-26T00:12:08.973+0100] {dag.py:3452} INFO - Setting next_dagrun for ml_analysis_pipeline to 2023-04-25T00:00:00+00:00, run_after=2023-04-26T00:00:00+00:00
[2023-04-26T00:12:09.028+0100] {processor.py:175} INFO - Processing /home/cavemhan/Documents/python/test_scripts/cyder-test/dags/ml_dags.py took 2.042 seconds
[2023-04-26T00:12:35.766+0100] {processor.py:153} INFO - Started process (PID=33204) to work on /home/cavemhan/Documents/python/test_scripts/cyder-test/dags/ml_dags.py
[2023-04-26T00:12:35.767+0100] {processor.py:743} INFO - Processing file /home/cavemhan/Documents/python/test_scripts/cyder-test/dags/ml_dags.py for tasks to queue
[2023-04-26T00:12:35.767+0100] {logging_mixin.py:137} INFO - [2023-04-26T00:12:35.767+0100] {dagbag.py:532} INFO - Filling up the DagBag from /home/cavemhan/Documents/python/test_scripts/cyder-test/dags/ml_dags.py
[2023-04-26T00:12:37.308+0100] {processor.py:753} INFO - DAG(s) dict_keys(['ml_analysis_pipeline']) retrieved from /home/cavemhan/Documents/python/test_scripts/cyder-test/dags/ml_dags.py
[2023-04-26T00:12:37.314+0100] {logging_mixin.py:137} INFO - [2023-04-26T00:12:37.314+0100] {dag.py:2705} INFO - Sync 1 DAGs
[2023-04-26T00:12:37.340+0100] {logging_mixin.py:137} INFO - [2023-04-26T00:12:37.340+0100] {dag.py:3452} INFO - Setting next_dagrun for ml_analysis_pipeline to 2023-04-25T00:00:00+00:00, run_after=2023-04-26T00:00:00+00:00
[2023-04-26T00:12:37.370+0100] {processor.py:175} INFO - Processing /home/cavemhan/Documents/python/test_scripts/cyder-test/dags/ml_dags.py took 1.608 seconds
[2023-04-26T00:13:03.312+0100] {processor.py:153} INFO - Started process (PID=33854) to work on /home/cavemhan/Documents/python/test_scripts/cyder-test/dags/ml_dags.py
[2023-04-26T00:13:03.316+0100] {processor.py:743} INFO - Processing file /home/cavemhan/Documents/python/test_scripts/cyder-test/dags/ml_dags.py for tasks to queue
[2023-04-26T00:13:03.317+0100] {logging_mixin.py:137} INFO - [2023-04-26T00:13:03.317+0100] {dagbag.py:532} INFO - Filling up the DagBag from /home/cavemhan/Documents/python/test_scripts/cyder-test/dags/ml_dags.py
[2023-04-26T00:13:03.320+0100] {logging_mixin.py:137} INFO - [2023-04-26T00:13:03.319+0100] {dagbag.py:341} ERROR - Failed to import: /home/cavemhan/Documents/python/test_scripts/cyder-test/dags/ml_dags.py
Traceback (most recent call last):
  File "/home/cavemhan/.local/share/virtualenvs/cyder-test-QPBcvLjc/lib/python3.10/site-packages/airflow/models/dagbag.py", line 337, in parse
    loader.exec_module(new_module)
  File "<frozen importlib._bootstrap_external>", line 879, in exec_module
  File "<frozen importlib._bootstrap_external>", line 1017, in get_code
  File "<frozen importlib._bootstrap_external>", line 947, in source_to_code
  File "<frozen importlib._bootstrap>", line 241, in _call_with_frames_removed
  File "/home/cavemhan/Documents/python/test_scripts/cyder-test/dags/ml_dags.py", line 44
    ,
    ^
SyntaxError: invalid syntax
[2023-04-26T00:13:03.320+0100] {processor.py:755} WARNING - No viable dags retrieved from /home/cavemhan/Documents/python/test_scripts/cyder-test/dags/ml_dags.py
[2023-04-26T00:13:03.347+0100] {processor.py:175} INFO - Processing /home/cavemhan/Documents/python/test_scripts/cyder-test/dags/ml_dags.py took 0.041 seconds
[2023-04-26T00:13:29.275+0100] {processor.py:153} INFO - Started process (PID=34488) to work on /home/cavemhan/Documents/python/test_scripts/cyder-test/dags/ml_dags.py
[2023-04-26T00:13:29.276+0100] {processor.py:743} INFO - Processing file /home/cavemhan/Documents/python/test_scripts/cyder-test/dags/ml_dags.py for tasks to queue
[2023-04-26T00:13:29.277+0100] {logging_mixin.py:137} INFO - [2023-04-26T00:13:29.277+0100] {dagbag.py:532} INFO - Filling up the DagBag from /home/cavemhan/Documents/python/test_scripts/cyder-test/dags/ml_dags.py
[2023-04-26T00:13:31.563+0100] {processor.py:753} INFO - DAG(s) dict_keys(['ml_analysis_pipeline']) retrieved from /home/cavemhan/Documents/python/test_scripts/cyder-test/dags/ml_dags.py
[2023-04-26T00:13:31.610+0100] {logging_mixin.py:137} INFO - [2023-04-26T00:13:31.609+0100] {dag.py:2705} INFO - Sync 1 DAGs
[2023-04-26T00:13:31.629+0100] {logging_mixin.py:137} INFO - [2023-04-26T00:13:31.628+0100] {dag.py:3452} INFO - Setting next_dagrun for ml_analysis_pipeline to 2023-04-25T00:00:00+00:00, run_after=2023-04-26T00:00:00+00:00
[2023-04-26T00:13:31.675+0100] {processor.py:175} INFO - Processing /home/cavemhan/Documents/python/test_scripts/cyder-test/dags/ml_dags.py took 2.404 seconds
[2023-04-26T00:13:57.540+0100] {processor.py:153} INFO - Started process (PID=35146) to work on /home/cavemhan/Documents/python/test_scripts/cyder-test/dags/ml_dags.py
[2023-04-26T00:13:57.541+0100] {processor.py:743} INFO - Processing file /home/cavemhan/Documents/python/test_scripts/cyder-test/dags/ml_dags.py for tasks to queue
[2023-04-26T00:13:57.543+0100] {logging_mixin.py:137} INFO - [2023-04-26T00:13:57.543+0100] {dagbag.py:532} INFO - Filling up the DagBag from /home/cavemhan/Documents/python/test_scripts/cyder-test/dags/ml_dags.py
[2023-04-26T00:13:59.353+0100] {processor.py:753} INFO - DAG(s) dict_keys(['ml_analysis_pipeline']) retrieved from /home/cavemhan/Documents/python/test_scripts/cyder-test/dags/ml_dags.py
[2023-04-26T00:13:59.375+0100] {logging_mixin.py:137} INFO - [2023-04-26T00:13:59.374+0100] {dag.py:2705} INFO - Sync 1 DAGs
[2023-04-26T00:13:59.430+0100] {logging_mixin.py:137} INFO - [2023-04-26T00:13:59.430+0100] {dag.py:3452} INFO - Setting next_dagrun for ml_analysis_pipeline to 2023-04-25T00:00:00+00:00, run_after=2023-04-26T00:00:00+00:00
[2023-04-26T00:13:59.471+0100] {processor.py:175} INFO - Processing /home/cavemhan/Documents/python/test_scripts/cyder-test/dags/ml_dags.py took 1.934 seconds
[2023-04-26T00:14:26.820+0100] {processor.py:153} INFO - Started process (PID=35872) to work on /home/cavemhan/Documents/python/test_scripts/cyder-test/dags/ml_dags.py
[2023-04-26T00:14:26.824+0100] {processor.py:743} INFO - Processing file /home/cavemhan/Documents/python/test_scripts/cyder-test/dags/ml_dags.py for tasks to queue
[2023-04-26T00:14:26.826+0100] {logging_mixin.py:137} INFO - [2023-04-26T00:14:26.826+0100] {dagbag.py:532} INFO - Filling up the DagBag from /home/cavemhan/Documents/python/test_scripts/cyder-test/dags/ml_dags.py
[2023-04-26T00:14:26.832+0100] {logging_mixin.py:137} INFO - [2023-04-26T00:14:26.831+0100] {dagbag.py:341} ERROR - Failed to import: /home/cavemhan/Documents/python/test_scripts/cyder-test/dags/ml_dags.py
Traceback (most recent call last):
  File "/home/cavemhan/.local/share/virtualenvs/cyder-test-QPBcvLjc/lib/python3.10/site-packages/airflow/models/dagbag.py", line 337, in parse
    loader.exec_module(new_module)
  File "<frozen importlib._bootstrap_external>", line 879, in exec_module
  File "<frozen importlib._bootstrap_external>", line 1017, in get_code
  File "<frozen importlib._bootstrap_external>", line 947, in source_to_code
  File "<frozen importlib._bootstrap>", line 241, in _call_with_frames_removed
  File "/home/cavemhan/Documents/python/test_scripts/cyder-test/dags/ml_dags.py", line 60
    op_kwargs={'data_processor_for_ml_attribute': get_attribute}
              
SyntaxError: invalid syntax. Perhaps you forgot a comma?
[2023-04-26T00:14:26.833+0100] {processor.py:755} WARNING - No viable dags retrieved from /home/cavemhan/Documents/python/test_scripts/cyder-test/dags/ml_dags.py
[2023-04-26T00:14:26.865+0100] {processor.py:175} INFO - Processing /home/cavemhan/Documents/python/test_scripts/cyder-test/dags/ml_dags.py took 0.049 seconds
[2023-04-26T00:14:53.152+0100] {processor.py:153} INFO - Started process (PID=36493) to work on /home/cavemhan/Documents/python/test_scripts/cyder-test/dags/ml_dags.py
[2023-04-26T00:14:53.153+0100] {processor.py:743} INFO - Processing file /home/cavemhan/Documents/python/test_scripts/cyder-test/dags/ml_dags.py for tasks to queue
[2023-04-26T00:14:53.154+0100] {logging_mixin.py:137} INFO - [2023-04-26T00:14:53.154+0100] {dagbag.py:532} INFO - Filling up the DagBag from /home/cavemhan/Documents/python/test_scripts/cyder-test/dags/ml_dags.py
[2023-04-26T00:14:53.160+0100] {logging_mixin.py:137} INFO - [2023-04-26T00:14:53.157+0100] {dagbag.py:341} ERROR - Failed to import: /home/cavemhan/Documents/python/test_scripts/cyder-test/dags/ml_dags.py
Traceback (most recent call last):
  File "/home/cavemhan/.local/share/virtualenvs/cyder-test-QPBcvLjc/lib/python3.10/site-packages/airflow/models/dagbag.py", line 337, in parse
    loader.exec_module(new_module)
  File "<frozen importlib._bootstrap_external>", line 879, in exec_module
  File "<frozen importlib._bootstrap_external>", line 1017, in get_code
  File "<frozen importlib._bootstrap_external>", line 947, in source_to_code
  File "<frozen importlib._bootstrap>", line 241, in _call_with_frames_removed
  File "/home/cavemhan/Documents/python/test_scripts/cyder-test/dags/ml_dags.py", line 60
    op_kwargs={'split_train_test_attribute': get_attribute}
              
SyntaxError: invalid syntax. Perhaps you forgot a comma?
[2023-04-26T00:14:53.161+0100] {processor.py:755} WARNING - No viable dags retrieved from /home/cavemhan/Documents/python/test_scripts/cyder-test/dags/ml_dags.py
[2023-04-26T00:14:53.199+0100] {processor.py:175} INFO - Processing /home/cavemhan/Documents/python/test_scripts/cyder-test/dags/ml_dags.py took 0.050 seconds
[2023-04-26T00:15:18.135+0100] {processor.py:153} INFO - Started process (PID=37084) to work on /home/cavemhan/Documents/python/test_scripts/cyder-test/dags/ml_dags.py
[2023-04-26T00:15:18.138+0100] {processor.py:743} INFO - Processing file /home/cavemhan/Documents/python/test_scripts/cyder-test/dags/ml_dags.py for tasks to queue
[2023-04-26T00:15:18.139+0100] {logging_mixin.py:137} INFO - [2023-04-26T00:15:18.139+0100] {dagbag.py:532} INFO - Filling up the DagBag from /home/cavemhan/Documents/python/test_scripts/cyder-test/dags/ml_dags.py
[2023-04-26T00:15:18.142+0100] {logging_mixin.py:137} INFO - [2023-04-26T00:15:18.141+0100] {dagbag.py:341} ERROR - Failed to import: /home/cavemhan/Documents/python/test_scripts/cyder-test/dags/ml_dags.py
Traceback (most recent call last):
  File "/home/cavemhan/.local/share/virtualenvs/cyder-test-QPBcvLjc/lib/python3.10/site-packages/airflow/models/dagbag.py", line 337, in parse
    loader.exec_module(new_module)
  File "<frozen importlib._bootstrap_external>", line 879, in exec_module
  File "<frozen importlib._bootstrap_external>", line 1017, in get_code
  File "<frozen importlib._bootstrap_external>", line 947, in source_to_code
  File "<frozen importlib._bootstrap>", line 241, in _call_with_frames_removed
  File "/home/cavemhan/Documents/python/test_scripts/cyder-test/dags/ml_dags.py", line 60
    op_kwargs={'split_train_test_attribute': get_attribute}
              
SyntaxError: invalid syntax. Perhaps you forgot a comma?
[2023-04-26T00:15:18.143+0100] {processor.py:755} WARNING - No viable dags retrieved from /home/cavemhan/Documents/python/test_scripts/cyder-test/dags/ml_dags.py
[2023-04-26T00:15:18.166+0100] {processor.py:175} INFO - Processing /home/cavemhan/Documents/python/test_scripts/cyder-test/dags/ml_dags.py took 0.034 seconds
[2023-04-26T00:15:41.451+0100] {processor.py:153} INFO - Started process (PID=37612) to work on /home/cavemhan/Documents/python/test_scripts/cyder-test/dags/ml_dags.py
[2023-04-26T00:15:41.452+0100] {processor.py:743} INFO - Processing file /home/cavemhan/Documents/python/test_scripts/cyder-test/dags/ml_dags.py for tasks to queue
[2023-04-26T00:15:41.453+0100] {logging_mixin.py:137} INFO - [2023-04-26T00:15:41.453+0100] {dagbag.py:532} INFO - Filling up the DagBag from /home/cavemhan/Documents/python/test_scripts/cyder-test/dags/ml_dags.py
[2023-04-26T00:15:41.458+0100] {logging_mixin.py:137} INFO - [2023-04-26T00:15:41.456+0100] {dagbag.py:341} ERROR - Failed to import: /home/cavemhan/Documents/python/test_scripts/cyder-test/dags/ml_dags.py
Traceback (most recent call last):
  File "/home/cavemhan/.local/share/virtualenvs/cyder-test-QPBcvLjc/lib/python3.10/site-packages/airflow/models/dagbag.py", line 337, in parse
    loader.exec_module(new_module)
  File "<frozen importlib._bootstrap_external>", line 879, in exec_module
  File "<frozen importlib._bootstrap_external>", line 1017, in get_code
  File "<frozen importlib._bootstrap_external>", line 947, in source_to_code
  File "<frozen importlib._bootstrap>", line 241, in _call_with_frames_removed
  File "/home/cavemhan/Documents/python/test_scripts/cyder-test/dags/ml_dags.py", line 60
    op_kwargs={'split_train_test_attribute': get_attribute}
              
SyntaxError: invalid syntax. Perhaps you forgot a comma?
[2023-04-26T00:15:41.458+0100] {processor.py:755} WARNING - No viable dags retrieved from /home/cavemhan/Documents/python/test_scripts/cyder-test/dags/ml_dags.py
[2023-04-26T00:15:41.480+0100] {processor.py:175} INFO - Processing /home/cavemhan/Documents/python/test_scripts/cyder-test/dags/ml_dags.py took 0.032 seconds
[2023-04-26T00:16:05.376+0100] {processor.py:153} INFO - Started process (PID=38119) to work on /home/cavemhan/Documents/python/test_scripts/cyder-test/dags/ml_dags.py
[2023-04-26T00:16:05.379+0100] {processor.py:743} INFO - Processing file /home/cavemhan/Documents/python/test_scripts/cyder-test/dags/ml_dags.py for tasks to queue
[2023-04-26T00:16:05.380+0100] {logging_mixin.py:137} INFO - [2023-04-26T00:16:05.380+0100] {dagbag.py:532} INFO - Filling up the DagBag from /home/cavemhan/Documents/python/test_scripts/cyder-test/dags/ml_dags.py
[2023-04-26T00:16:05.384+0100] {logging_mixin.py:137} INFO - [2023-04-26T00:16:05.382+0100] {dagbag.py:341} ERROR - Failed to import: /home/cavemhan/Documents/python/test_scripts/cyder-test/dags/ml_dags.py
Traceback (most recent call last):
  File "/home/cavemhan/.local/share/virtualenvs/cyder-test-QPBcvLjc/lib/python3.10/site-packages/airflow/models/dagbag.py", line 337, in parse
    loader.exec_module(new_module)
  File "<frozen importlib._bootstrap_external>", line 879, in exec_module
  File "<frozen importlib._bootstrap_external>", line 1017, in get_code
  File "<frozen importlib._bootstrap_external>", line 947, in source_to_code
  File "<frozen importlib._bootstrap>", line 241, in _call_with_frames_removed
  File "/home/cavemhan/Documents/python/test_scripts/cyder-test/dags/ml_dags.py", line 60
    op_kwargs={'split_train_test_attribute': get_attribute}
              
SyntaxError: invalid syntax. Perhaps you forgot a comma?
[2023-04-26T00:16:05.384+0100] {processor.py:755} WARNING - No viable dags retrieved from /home/cavemhan/Documents/python/test_scripts/cyder-test/dags/ml_dags.py
[2023-04-26T00:16:05.412+0100] {processor.py:175} INFO - Processing /home/cavemhan/Documents/python/test_scripts/cyder-test/dags/ml_dags.py took 0.039 seconds
[2023-04-26T00:16:35.102+0100] {processor.py:153} INFO - Started process (PID=38805) to work on /home/cavemhan/Documents/python/test_scripts/cyder-test/dags/ml_dags.py
[2023-04-26T00:16:35.105+0100] {processor.py:743} INFO - Processing file /home/cavemhan/Documents/python/test_scripts/cyder-test/dags/ml_dags.py for tasks to queue
[2023-04-26T00:16:35.107+0100] {logging_mixin.py:137} INFO - [2023-04-26T00:16:35.106+0100] {dagbag.py:532} INFO - Filling up the DagBag from /home/cavemhan/Documents/python/test_scripts/cyder-test/dags/ml_dags.py
[2023-04-26T00:16:35.118+0100] {logging_mixin.py:137} INFO - [2023-04-26T00:16:35.116+0100] {dagbag.py:341} ERROR - Failed to import: /home/cavemhan/Documents/python/test_scripts/cyder-test/dags/ml_dags.py
Traceback (most recent call last):
  File "/home/cavemhan/.local/share/virtualenvs/cyder-test-QPBcvLjc/lib/python3.10/site-packages/airflow/models/dagbag.py", line 337, in parse
    loader.exec_module(new_module)
  File "<frozen importlib._bootstrap_external>", line 879, in exec_module
  File "<frozen importlib._bootstrap_external>", line 1017, in get_code
  File "<frozen importlib._bootstrap_external>", line 947, in source_to_code
  File "<frozen importlib._bootstrap>", line 241, in _call_with_frames_removed
  File "/home/cavemhan/Documents/python/test_scripts/cyder-test/dags/ml_dags.py", line 60
    op_kwargs={'split_train_test_attribute': get_attribute}
              
SyntaxError: invalid syntax. Perhaps you forgot a comma?
[2023-04-26T00:16:35.119+0100] {processor.py:755} WARNING - No viable dags retrieved from /home/cavemhan/Documents/python/test_scripts/cyder-test/dags/ml_dags.py
[2023-04-26T00:16:35.167+0100] {processor.py:175} INFO - Processing /home/cavemhan/Documents/python/test_scripts/cyder-test/dags/ml_dags.py took 0.071 seconds
[2023-04-26T00:17:04.106+0100] {processor.py:153} INFO - Started process (PID=39502) to work on /home/cavemhan/Documents/python/test_scripts/cyder-test/dags/ml_dags.py
[2023-04-26T00:17:04.108+0100] {processor.py:743} INFO - Processing file /home/cavemhan/Documents/python/test_scripts/cyder-test/dags/ml_dags.py for tasks to queue
[2023-04-26T00:17:04.109+0100] {logging_mixin.py:137} INFO - [2023-04-26T00:17:04.108+0100] {dagbag.py:532} INFO - Filling up the DagBag from /home/cavemhan/Documents/python/test_scripts/cyder-test/dags/ml_dags.py
[2023-04-26T00:17:06.724+0100] {processor.py:753} INFO - DAG(s) dict_keys(['ml_analysis_pipeline']) retrieved from /home/cavemhan/Documents/python/test_scripts/cyder-test/dags/ml_dags.py
[2023-04-26T00:17:06.780+0100] {logging_mixin.py:137} INFO - [2023-04-26T00:17:06.779+0100] {dag.py:2705} INFO - Sync 1 DAGs
[2023-04-26T00:17:06.801+0100] {logging_mixin.py:137} INFO - [2023-04-26T00:17:06.801+0100] {dag.py:3452} INFO - Setting next_dagrun for ml_analysis_pipeline to 2023-04-25T00:00:00+00:00, run_after=2023-04-26T00:00:00+00:00
[2023-04-26T00:17:06.841+0100] {processor.py:175} INFO - Processing /home/cavemhan/Documents/python/test_scripts/cyder-test/dags/ml_dags.py took 2.740 seconds
[2023-04-26T00:17:37.058+0100] {processor.py:153} INFO - Started process (PID=40209) to work on /home/cavemhan/Documents/python/test_scripts/cyder-test/dags/ml_dags.py
[2023-04-26T00:17:37.063+0100] {processor.py:743} INFO - Processing file /home/cavemhan/Documents/python/test_scripts/cyder-test/dags/ml_dags.py for tasks to queue
[2023-04-26T00:17:37.064+0100] {logging_mixin.py:137} INFO - [2023-04-26T00:17:37.064+0100] {dagbag.py:532} INFO - Filling up the DagBag from /home/cavemhan/Documents/python/test_scripts/cyder-test/dags/ml_dags.py
[2023-04-26T00:17:38.726+0100] {processor.py:753} INFO - DAG(s) dict_keys(['ml_analysis_pipeline']) retrieved from /home/cavemhan/Documents/python/test_scripts/cyder-test/dags/ml_dags.py
[2023-04-26T00:17:38.804+0100] {logging_mixin.py:137} INFO - [2023-04-26T00:17:38.804+0100] {dag.py:2705} INFO - Sync 1 DAGs
[2023-04-26T00:17:38.838+0100] {logging_mixin.py:137} INFO - [2023-04-26T00:17:38.837+0100] {dag.py:3452} INFO - Setting next_dagrun for ml_analysis_pipeline to 2023-04-25T00:00:00+00:00, run_after=2023-04-26T00:00:00+00:00
[2023-04-26T00:17:38.924+0100] {processor.py:175} INFO - Processing /home/cavemhan/Documents/python/test_scripts/cyder-test/dags/ml_dags.py took 1.870 seconds
[2023-04-26T00:18:06.037+0100] {processor.py:153} INFO - Started process (PID=40846) to work on /home/cavemhan/Documents/python/test_scripts/cyder-test/dags/ml_dags.py
[2023-04-26T00:18:06.038+0100] {processor.py:743} INFO - Processing file /home/cavemhan/Documents/python/test_scripts/cyder-test/dags/ml_dags.py for tasks to queue
[2023-04-26T00:18:06.038+0100] {logging_mixin.py:137} INFO - [2023-04-26T00:18:06.038+0100] {dagbag.py:532} INFO - Filling up the DagBag from /home/cavemhan/Documents/python/test_scripts/cyder-test/dags/ml_dags.py
[2023-04-26T00:18:07.244+0100] {processor.py:753} INFO - DAG(s) dict_keys(['ml_analysis_pipeline']) retrieved from /home/cavemhan/Documents/python/test_scripts/cyder-test/dags/ml_dags.py
[2023-04-26T00:18:07.253+0100] {logging_mixin.py:137} INFO - [2023-04-26T00:18:07.253+0100] {dag.py:2705} INFO - Sync 1 DAGs
[2023-04-26T00:18:07.285+0100] {logging_mixin.py:137} INFO - [2023-04-26T00:18:07.285+0100] {dag.py:3452} INFO - Setting next_dagrun for ml_analysis_pipeline to 2023-04-25T00:00:00+00:00, run_after=2023-04-26T00:00:00+00:00
[2023-04-26T00:18:07.316+0100] {processor.py:175} INFO - Processing /home/cavemhan/Documents/python/test_scripts/cyder-test/dags/ml_dags.py took 1.284 seconds
[2023-04-26T00:18:38.117+0100] {processor.py:153} INFO - Started process (PID=41541) to work on /home/cavemhan/Documents/python/test_scripts/cyder-test/dags/ml_dags.py
[2023-04-26T00:18:38.119+0100] {processor.py:743} INFO - Processing file /home/cavemhan/Documents/python/test_scripts/cyder-test/dags/ml_dags.py for tasks to queue
[2023-04-26T00:18:38.119+0100] {logging_mixin.py:137} INFO - [2023-04-26T00:18:38.119+0100] {dagbag.py:532} INFO - Filling up the DagBag from /home/cavemhan/Documents/python/test_scripts/cyder-test/dags/ml_dags.py
[2023-04-26T00:18:40.925+0100] {processor.py:753} INFO - DAG(s) dict_keys(['ml_analysis_pipeline']) retrieved from /home/cavemhan/Documents/python/test_scripts/cyder-test/dags/ml_dags.py
[2023-04-26T00:18:40.932+0100] {logging_mixin.py:137} INFO - [2023-04-26T00:18:40.931+0100] {dag.py:2705} INFO - Sync 1 DAGs
[2023-04-26T00:18:40.952+0100] {logging_mixin.py:137} INFO - [2023-04-26T00:18:40.952+0100] {dag.py:3452} INFO - Setting next_dagrun for ml_analysis_pipeline to 2023-04-25T00:00:00+00:00, run_after=2023-04-26T00:00:00+00:00
[2023-04-26T00:18:40.978+0100] {processor.py:175} INFO - Processing /home/cavemhan/Documents/python/test_scripts/cyder-test/dags/ml_dags.py took 2.864 seconds
