[2023-04-25T18:36:56.052+0100] {taskinstance.py:1090} INFO - Dependencies all met for dep_context=non-requeueable deps ti=<TaskInstance: ml_analysis_pipeline.analyze_data manual__2023-04-25T17:36:39.857877+00:00 [queued]>
[2023-04-25T18:36:56.060+0100] {taskinstance.py:1090} INFO - Dependencies all met for dep_context=requeueable deps ti=<TaskInstance: ml_analysis_pipeline.analyze_data manual__2023-04-25T17:36:39.857877+00:00 [queued]>
[2023-04-25T18:36:56.060+0100] {taskinstance.py:1288} INFO - 
--------------------------------------------------------------------------------
[2023-04-25T18:36:56.061+0100] {taskinstance.py:1289} INFO - Starting attempt 1 of 1
[2023-04-25T18:36:56.061+0100] {taskinstance.py:1290} INFO - 
--------------------------------------------------------------------------------
[2023-04-25T18:36:56.077+0100] {taskinstance.py:1309} INFO - Executing <Task(PythonOperator): analyze_data> on 2023-04-25 17:36:39.857877+00:00
[2023-04-25T18:36:56.084+0100] {standard_task_runner.py:55} INFO - Started process 184521 to run task
[2023-04-25T18:36:56.088+0100] {standard_task_runner.py:82} INFO - Running: ['airflow', 'tasks', 'run', 'ml_analysis_pipeline', 'analyze_data', 'manual__2023-04-25T17:36:39.857877+00:00', '--job-id', '28', '--raw', '--subdir', 'DAGS_FOLDER/data_ml_pipeline.py', '--cfg-path', '/tmp/tmp311kajaw']
[2023-04-25T18:36:56.089+0100] {standard_task_runner.py:83} INFO - Job 28: Subtask analyze_data
[2023-04-25T18:36:56.146+0100] {task_command.py:389} INFO - Running <TaskInstance: ml_analysis_pipeline.analyze_data manual__2023-04-25T17:36:39.857877+00:00 [running]> on host cavemanPC
[2023-04-25T18:36:56.193+0100] {taskinstance.py:1516} INFO - Exporting the following env vars:
AIRFLOW_CTX_DAG_OWNER=airflow
AIRFLOW_CTX_DAG_ID=ml_analysis_pipeline
AIRFLOW_CTX_TASK_ID=analyze_data
AIRFLOW_CTX_EXECUTION_DATE=2023-04-25T17:36:39.857877+00:00
AIRFLOW_CTX_TRY_NUMBER=1
AIRFLOW_CTX_DAG_RUN_ID=manual__2023-04-25T17:36:39.857877+00:00
[2023-04-25T18:39:43.224+0100] {logging_mixin.py:137} INFO - save file with : outputs/data/output_analysis_inputs/UserWillChristodoulou_DataScience_TestData.csv
[2023-04-25T18:39:43.230+0100] {taskinstance.py:1776} ERROR - Task failed with exception
Traceback (most recent call last):
  File "/home/cavemhan/.local/share/virtualenvs/cyder-test-QPBcvLjc/lib/python3.10/site-packages/airflow/operators/python.py", line 175, in execute
    return_value = self.execute_callable()
  File "/home/cavemhan/.local/share/virtualenvs/cyder-test-QPBcvLjc/lib/python3.10/site-packages/airflow/operators/python.py", line 192, in execute_callable
    return self.python_callable(*self.op_args, **self.op_kwargs)
  File "/home/cavemhan/Documents/python/test_scripts/cyder-test/dags/common_files/operators/data_operators.py", line 260, in analyze_data
    self.save_data()
  File "/home/cavemhan/Documents/python/test_scripts/cyder-test/dags/common_files/operators/data_operators.py", line 251, in save_data
    self.data.to_csv(output_file, index=False)
  File "/home/cavemhan/.local/share/virtualenvs/cyder-test-QPBcvLjc/lib/python3.10/site-packages/pandas/core/generic.py", line 3772, in to_csv
    return DataFrameRenderer(formatter).to_csv(
  File "/home/cavemhan/.local/share/virtualenvs/cyder-test-QPBcvLjc/lib/python3.10/site-packages/pandas/io/formats/format.py", line 1186, in to_csv
    csv_formatter.save()
  File "/home/cavemhan/.local/share/virtualenvs/cyder-test-QPBcvLjc/lib/python3.10/site-packages/pandas/io/formats/csvs.py", line 240, in save
    with get_handle(
  File "/home/cavemhan/.local/share/virtualenvs/cyder-test-QPBcvLjc/lib/python3.10/site-packages/pandas/io/common.py", line 737, in get_handle
    check_parent_directory(str(handle))
  File "/home/cavemhan/.local/share/virtualenvs/cyder-test-QPBcvLjc/lib/python3.10/site-packages/pandas/io/common.py", line 600, in check_parent_directory
    raise OSError(rf"Cannot save file into a non-existent directory: '{parent}'")
OSError: Cannot save file into a non-existent directory: 'outputs/data/output_analysis_inputs'
[2023-04-25T18:39:43.243+0100] {taskinstance.py:1327} INFO - Marking task as FAILED. dag_id=ml_analysis_pipeline, task_id=analyze_data, execution_date=20230425T173639, start_date=20230425T173656, end_date=20230425T173943
[2023-04-25T18:39:43.260+0100] {standard_task_runner.py:100} ERROR - Failed to execute job 28 for task analyze_data (Cannot save file into a non-existent directory: 'outputs/data/output_analysis_inputs'; 184521)
[2023-04-25T18:39:43.292+0100] {local_task_job.py:212} INFO - Task exited with return code 1
[2023-04-25T18:39:43.306+0100] {taskinstance.py:2596} INFO - 0 downstream tasks scheduled from follow-on schedule check
